Workbook
Name addlogo: INDEX(#REF!,MATCH(#REF!,#REF!,0))

Sheet TONGQUAN
A1: Kỳ báo cáo: | C1: Tại ngày 31 tháng 07 năm 2022 / As at 31 Jul 2022
C2: Tháng 07 năm 2022 / Jul 2022
A4: Thông tin chung:
C5: Tên Công ty quản lý quỹ: | D5: Công ty Cổ phần Quản lý Quỹ Đầu tư Dragon Capital Việt Nam
C6: Fund Management Company: | D6: Dragon Capital Vietfund Management Joint Stock Company
C7: Tên ngân hàng giám sát: | D7: Ngân hàng TNHH Một thành viên Standard Chartered (Việt Nam)
C8: Supervising bank: | D8: Standard Chartered Bank (Vietnam) Limited
C9: Tên Quỹ: | D9: Quỹ Đầu tư Chứng khoán Năng động DC
C10: Fund name: | D10: DC Dynamic Securities Fund(VFMVF1)
C11: Ngày lập báo cáo: | D11: Ngày 01 tháng 08 năm 2022
C12: Reporting Date: | D12: 01 Aug 2022
A14: Người ký báo cáo:
C16: Đại diện có thẩm quyền của Ngân hàng giám sát | F16: Đại diện có thẩm quyền của Công ty quản lý Quỹ
C17: Authorised Representative of Supervisory Bank | F17: Authorised Representative of Fund Management Company
C19: Ngân hàng TNHH MTV Standard Chartered (Việt Nam) | F19: =D5 -> Công ty Cổ phần Quản lý Quỹ Đầu tư Dragon Capital Việt Nam
C20: Trịnh Hoài Nam | F20: Nguyễn Minh Đăng Khánh
C21: Phó phòng Dịch vụ Quản trị và Giám sát Quỹ | F21: Giám đốc điều hành Nghiệp vụ hỗ trợ đầu tư
B34: STT | C34: Nội dung | D34: Tên sheet
B35: 1 | C35: Báo cáo về tài sản của quỹ | D35: 06027
B36: 2 | C36: Báo cáo kết quả hoạt động | D36: 06028
B37: 3 | C37: Báo cáo danh mục đầu tư của quỹ | D37: 06029
B38: 4 | C38: Một số chỉ tiêu khác | D38: 06030
B39: 5 | C39: Báo cáo thay đổi giá trị tài sản ròng, giao dịch chứng chỉ quỹ | D39: 06129
B40: 6 | C40: Báo cáo thu nhập giữa niên độ | D40: 06203
B41: 7 | C41: Báo cáo tình hình tài chính giữa niên độ | D41: 06105
B42: 8 | C42: Báo cáo thay đổi giá trị tài sản ròng, giao dịch chứng chỉ quỹ giữa niên độ | D42: 06107
B43: 9 | C43: Báo cáo danh mục đầu tư | D43: 06108
B44: 10 | C44: Báo cáo lưu chuyển tiền tệ | D44: 06262
B45: 11 | C45: Báo cáo thu nhập | D45: 06104
B46: 12 | C46: Báo cáo về tài sản của quỹ | D46: 06126

Sheet BCthunhap
A1: Mẫu số B01g - QM. Báo cáo thu nhập Template B01g - QM. Statement of Comprehensive Income
A2: (Ban hành kèm theo Thông tư 198/2012/TT-BTC ngày 15 tháng 11 năm 2012 về chế độ kế toán áp dụng đối với quỹ mở) (Issued in association with Circular 198/2012/TT-BTC dated 15 Nov 2012 on the Accounting Policies for Open-Ended Fund)
A3: BÁO CÁO THU NHẬP STATEMENT OF COMPREHENSIVE INCOME
A5: =TONGQUAN!C2 -> Tháng 07 năm 2022 / Jul 2022
A7: Tên Công ty quản lý quỹ: | D7: =TONGQUAN!D5 -> Công ty Cổ phần Quản lý Quỹ Đầu tư Dragon Capital Việt Nam
A8: Fund Management Company: | D8: =TONGQUAN!D6 -> Dragon Capital Vietfund Management Joint Stock Company
A9: Tên ngân hàng giám sát: | D9: =TONGQUAN!D7 -> Ngân hàng TNHH Một thành viên Standard Chartered (Việt Nam)
A10: Supervising bank: | D10: =TONGQUAN!D8 -> Standard Chartered Bank (Vietnam) Limited
A11: Tên Quỹ: | D11: =TONGQUAN!D9 -> Quỹ Đầu tư Chứng khoán Năng động DC
A12: Fund name: | D12: =TONGQUAN!D10 -> DC Dynamic Securities Fund(VFMVF1)
A13: Ngày lập báo cáo: | D13: =TONGQUAN!D11 -> Ngày 01 tháng 08 năm 2022
A14: Reporting Date: | D14: =TONGQUAN!D12 -> 01 Aug 2022
A16: Chỉ tiêu Indicator | B16: Mã số Code | C16: Thuyết minh Note | D16: Năm 2022 Year 2022 | F16: Năm 2021 Year 2021
D17: =BCKetQuaHoatDong_06028!D18 -> Tháng 07 năm 2022 Jul 2022 | E17: Số lũy kế Year-to-date | F17: Tháng 07 năm 2021 Jul 2021 | G17: Số lũy kế Year-to-date
A18: I. THU NHẬP, DOANH THU HOẠT ĐỘNG ĐẦU TƯ Investment income | B18: 01 | D18: -14939385873 | E18: -429717885070 | F18: -13099594865 | G18: 200773185202
A19: 1.1. Cổ tức được chia Dividend income | B19: 02 | D19: 2937160000 | E19: 9928292500 | F19: 735280000 | G19: 4241863418
A20: 1.2. Tiền lãi được nhận Interest income | B20: 03 | D20: 1590327272 | E20: 10206130379 | F20: 660869085 | G20: 3572725912
A21: Lãi tiền gửi ngân hàng Interest income from bank deposits | B21: 03.1 | D21: 22224578 | E21: 1028198843 | F21: 12204701 | G21: 52890297
A22: Lãi chứng chỉ tiền gửi Interest income from Certificates of Deposit | B22: 03.2 | D22: 66458904 | E22: 706698630 | F22: 139075343 | G22: 2158739724
A23: Lãi trái phiếu Interest income from bonds | B23: 03.3 | D23: 1501643790 | E23: 8471232906 | F23: 509589041 | G23: 1361095891
A24: Tiền lãi hợp đồng mua lại đảo ngược được nhận Reverse repo contract interest received | B24: 03.4 | D24: 0 | E24: 0 | F24: 0 | G24: 0
A25: 1.3. Lãi (lỗ) bán các khoản đầu tư Realized gain (losses) from disposal investments | B25: 04 | D25: -56005984946 | E25: -223721190383 | F25: 39446220636 | G25: 119193067591
A26: 1.4. Chênh lệch tăng, giảm đánh giá lại các khoản đầu tư chưa thực hiện Unrealized gain (losses) from investment revaluation | B26: 05 | D26: 36539111801 | E26: -226131117566 | F26: -53941964586 | G26: 73765528281
A27: 1.5. Doanh thu khác Other income | B27: 06 | D27: 0 | E27: 0 | F27: 0 | G27: 0
A28: 1.6. Chênh lệch lãi, lỗ tỷ giá hối đoái đã và chưa thực hiện Realized and unrealized gain (losses) from foreign exchange | B28: 07 | D28: 0 | E28: 0 | F28: 0 | G28: 0
A29: 1.7. Doanh thu khác về đầu tư Other investment income | B29: 08 | D29: 0 | E29: 0 | F29: 0 | G29: 0
... A77: VIII. LỢI NHUẬN KẾ TOÁN SAU THUẾ TNDN PROFIT AFTER TAX (41=30-40) | B77: 41 | D77: -19608724457 | E77: -458051190817 | F77: -14978575973 | G77: 190674815145
A80: Người lập: | B80: Người duyệt:
A93: _______________________________________________ | B93: ___________________________________________ | F93: _____________________________
A94: Nguyễn Thu Ngọc | B94: Phạm Thanh Dũng | F94: Nguyễn Minh Đăng Khánh
A95: Kế toán Quỹ | B95: Kế toán Trưởng | F95: Giám đốc điều hành Nghiệp vụ hỗ trợ đầu tư

Sheet BCtinhhinhtaichinh
A1: Mẫu số B02g - QM. Báo cáo tình hình tài chính Template B02g - QM. Statement of Financial Position
A2: (Ban hành kèm theo Thông tư 198/2012/TT-BTC ngày 15 tháng 11 năm 2012 về chế độ kế toán áp dụng đối với quỹ mở) (Issued in association with Circular 198/2012/TT-BTC dated 15 Nov 2012 on the Accounting Policies for Open-Ended Fund)
A3: BÁO CÁO TÌNH HÌNH TÀI CHÍNH STATEMENT OF FINANCIAL POSITION
A5: =TONGQUAN!C1 -> Tại ngày 31 tháng 07 năm 2022 / As at 31 Jul 2022
A7: Tên Công ty quản lý quỹ: | C7: =TONGQUAN!D5 -> Công ty Cổ phần Quản lý Quỹ Đầu tư Dragon Capital Việt Nam
A8: Fund Management Company: | C8: =TONGQUAN!D6 -> Dragon Capital Vietfund Management Joint Stock Company
A9: Tên ngân hàng giám sát: | C9: =TONGQUAN!D7 -> Ngân hàng TNHH Một thành viên Standard Chartered (Việt Nam)
A10: Supervising bank: | C10: =TONGQUAN!D8 -> Standard Chartered Bank (Vietnam) Limited
A11: Tên Quỹ: | C11: =TONGQUAN!D9 -> Quỹ Đầu tư Chứng khoán Năng động DC
A12: Fund name: | C12: =TONGQUAN!D10 -> DC Dynamic Securities Fund(VFMVF1)
A13: Ngày lập báo cáo: | C13: =TONGQUAN!D11 -> Ngày 01 tháng 08 năm 2022
A14: Reporting Date: | C14: =TONGQUAN!D12 -> 01 Aug 2022
A16: STT No. | B16: Chỉ tiêu Indicator | C16: Mã số Code | D16: Thuyết minh Note | E16: =BCTaiSan_06027!D18 -> Ngày 31 tháng 07 năm 2022 As at 31 Jul 2022 | F16: =BCTaiSan_06027!E18 -> Ngày 30 tháng 06 năm 2022 As at 30 Jun 2022
A17: I | B17: I. TÀI SẢN ASSETS | C17: I
A18: 1 | B18: 1.Tiền gửi ngân hàng và tương đương tiền Cash at bank and cash equivalent | C18: 110 | E18: 189101074987 | F18: 118659866954
A19: 1.1 | B19: 1.1. Tiền gửi ngân hàng Cash at bank | C19: 111 | E19: 189101074987 | F19: 118659866954
B20: Tiền gửi của nhà đầu tư cho hoạt động mua chứng chỉ quỹ Cash at bank for Fund's subscription | C20: 111.1 | E20: 0 | F20: 0
B21: Tiền phải trả cho Nhà đầu tư về mua lại Chứng chỉ quỹ Cash at bank for Fund's redemption | C21: 111.2 | E21: 719033789 | F21: 1118154682
B22: Tiền gửi ngân hàng cho hoạt động của Quỹ Cash at bank for Fund's operation | C22: 111.3 | E22: 188382041198 | F22: 117541712272
B23: Tiền gửi ký quỹ cho hoạt động đầu tư chứng khoán phái sinh Margin account for trading derivatives | C23: 111.4 | E23: 0 | F23: 0
A24: 1.2 | B24: 1.2. Tiền gửi có kỳ hạn dưới ba (03) tháng Deposit with term less than three (03) months | C24: 112 | E24: 0 | F24: 0
A25: 2 | B25: 2. Các khoản đầu tư thuần Net Investments | C25: 120 | E25: 1401393395550 | F25: 1470911463400
A26: 2.1 | B26: 2.1. Các khoản đầu tư Investments | C26: 121 | E26: 1401393395550 | F26: 1470911463400
B27: Cổ phiếu niêm yết Listed Shares | C27: 121.1 | E27: 1271337570950 | F27: 1291055638800
B28: Cổ phiếu chưa niêm yết Unlisted Shares | C28: 121.2 | E28: 0 | F28: 0
B29: Trái phiếu niêm yết Listed Bonds | C29: 121.3 | E29: 30062400000 | F29: 79862400000
B30: Trái phiếu chưa niêm yết Unlisted Bonds | C30: 121.4 | E30: 89993424600 | F30: 89993424600
B31: Chứng chỉ tiền gửi Certificates of Deposit | C31: 121.5 | E31: 10000000000 | F31: 10000000000
B32: Hợp đồng tiền gửi có kỳ hạn trên ba (03) tháng Deposits with term over three (03) months | C32: 121.6 | E32: 0 | F32: 0
B33: Quyền mua chứng khoán Investment - Rights | C33: 121.7 | E33: 0 | F33: 0
B34: Hợp đồng tương lai chỉ số Index future contracts | C34: 121.8 | E34: 0 | F34: 0
B35: Đầu tư khác Other Investments | C35: 121.9 | E35: 0 | F35: 0
B36: Hợp đồng mua lại đảo ngược Reverse repo contracts | C36: 121.10 | E36: 0 | F36: 0
A37: 2.2 | B37: 2.2. Dự phòng giảm giá tài sản nhận thế chấp Impairment of devaluation of pledged assets | C37: 122 | E37: 0 | F37: 0
A38: 3 | B38: 3. Các khoản phải thu Receivables | C38: 130 | E38: 88255697740 | F38: 47664359841
A39: 3.1 | B39: 3.1 Phải thu về bán các khoản đầu tư Receivables from investments sold but not yet settled | C39: 131 | E39: 83396335000 | F39: 41850102600
B40: Trong đó: Phải thu khó đòi về bán các khoản đầu tư In which: Overdue receivables from selling investments | C40: 132 | E40: 0 | F40: 0
A41: 3.2 | B41: 3.2. Phải thu và dự thu cổ tức, tiền lãi các khoản đầu tư Dividend and interest receivables | C41: 133 | E41: 5725762740 | F41: 6680657241
A42: 3.2.1 | B42: 3.2.1. Phải thu cổ tức, tiền lãi đến ngày nhận Dividend and interest receivables on or after payment date | C42: 134 | E42: 866400000 | F42: 866400000
B43: Phải thu cổ tức Dividend receivables | C43: 134.1 | E43: 866400000 | F43: 866400000
...

Sheet BCTaiSan_06027
A1: Phụ lục XXVI. Mẫu báo cáo về hoạt động của Quỹ Appendix XXVI. Report on Fund's Operation
A2: (Ban hành kèm theo Thông tư số 98/2020/TT-BTC ngày 16 tháng 11 năm 2020 của Bộ trưởng Bộ Tài Chính về hướng dẫn hoạt động và quản lý quỹ đầu tư chứng khoán) (Issued in association with Circular 98/2020/TT-BTC dated 16 November 2020 of the Minister of Finance on guiding the operation and management of the securities investment funds)
A3: BÁO CÁO VỀ HOẠT ĐỘNG ĐẦU TƯ REPORT ON INVESTMENT ACTIVITIES
A5: Tại ngày 31 tháng 07 năm 2022 / As at 31 Jul 2022
A7: Tên Công ty quản lý quỹ: | C7: Công ty Cổ phần Quản lý Quỹ Đầu tư Dragon Capital Việt Nam
A8: Fund Management Company: | C8: Dragon Capital Vietfund Management Joint Stock Company
A9: Tên ngân hàng giám sát: | C9: Ngân hàng TNHH Một thành viên Standard Chartered (Việt Nam)
A10: Supervising bank: | C10: Standard Chartered Bank (Vietnam) Limited
A11: Tên Quỹ: | C11: Quỹ Đầu tư Chứng khoán Năng động DC
A12: Fund name: | C12: DC Dynamic Securities Fund(VFMVF1)
A13: Ngày lập báo cáo: | C13: Ngày 01 tháng 08 năm 2022
A14: Reporting Date: | C14: 01 Aug 2022
A16: A. | B16: BÁO CÁO CHUNG VỀ HOẠT ĐỘNG ĐẦU TƯ CỦA QUỸ/GENERAL INFORMATION ON FUND'S INVESTMENT ACTIVITIES
A17: I | B17: BÁO CÁO VỀ TÀI SẢN / ASSET REPORT
A18: STT No | B18: Nội dung Indicator | C18: Mã chỉ tiêu Code | D18: Ngày 31 tháng 07 năm 2022 As at 31 Jul 2022 | E18: Ngày 30 tháng 06 năm 2022 As at 30 Jun 2022 | F18: %/cùng kỳ năm trước %/against last year
A19: I | B19: TÀI SẢN ASSETS
A20: I.1 | B20: Tiền và các khoản tương đương tiền Cash and Cash Equivalents | D20: 189101074987 | E20: 118659866954 | F20: 3.0340988
B21: Tiền gửi ngân hàng Cash at bank | D21: 189101074987 | E21: 118659866954 | F21: 3.0340988
B22: Tiền gửi của nhà đầu tư cho hoạt động mua chứng chỉ quỹ Cash at bank for Fund's subscription | D22: 0 | E22: 0
B23: Tiền phải trả cho Nhà đầu tư về mua lại chứng chỉ quỹ Cash at bank for Fund's redemption | D23: 719033789 | E23: 1118154682 | F23: 4.5588939
B24: Tiền gửi ngân hàng cho hoạt động của Quỹ Cash at bank for Fund's operation | D24: 188382041198 | E24: 117541712272 | F24: 3.0302303
B25: Tiền gửi ký quỹ cho hoạt động đầu tư chứng khoán phái sinh Margin account for trading derivatives | D25: 0 | E25: 0
B26: Tiền, tương đương tiền Cash, cash equivalents | D26: 0 | E26: 0
A27: I.2 | B27: Các khoản đầu tư (kê chi tiết) Investments | D27: 1401393395550 | E27: 1470911463400 | F27: 1.7481488
B28: Cổ phiếu niêm yết Listed shares | D28: 1271337570950 | E28: 1291055638800 | F28: 1.7376289
B29: Cổ phiếu chưa niêm yết Unlisted shares | D29: 0 | E29: 0
B30: Trái phiếu Bonds | D30: 120055824600 | E30: 169855824600 | F30: 2.4014323
B31: Chứng chỉ tiền gửi Certificates of Deposit | D31: 10000000000 | E31: 10000000000 | F31: 0.5
B32: Hợp đồng tiền gửi có kỳ hạn trên ba (03) tháng Deposits with term over three (03) months | D32: 0 | E32: 0
B33: Quyền mua chứng khoán Investment - Rights | D33: 0 | E33: 0
B34: Hợp đồng tương lai chỉ số Index future contracts | D34: 0 | E34: 0
B35: Đầu tư khác Other investments | D35: 0 | E35: 0
B36: Hợp đồng mua lại đảo ngược Reverse repo contracts | D36: 0 | E36: 0
A37: I.3 | B37: Thu từ cho thuê bất động sản đầu tư (không áp dụng) Receivables from rental of investment property (not applicable)
A38: I.4 | B38: Cổ tức, trái tức được nhận Dividend, Coupon receivables | D38: 5459927124 | E38: 6481280529 | F38: 2.2065338
B39: Phải thu cổ tức Dividend receivables | D39: 3341160000 | E39: 3201554500 | F39: 3.0188522
B40: Phải thu trái tức Coupon receivables | D40: 2118767124 | E40: 3279726029 | F40: 1.5491787
A41: I.5 | B41: Lãi được nhận Interest receivables | D41: 265835616 | E41: 199376712 | F41: 0.53774108
B42: Phải thu lãi tiền gửi Interest receivable from bank deposits | D42: 0 | E42: 0
B43: Phải thu lãi chứng chỉ tiền gửi Interest receivable from Certificates of Deposit | D43: 265835616 | E43: 199376712 | F43: 0.53774108
...

Sheet BCKetQuaHoatDong_06028
A1: Phụ lục XXVI. Mẫu báo cáo về hoạt động của Quỹ Appendix XXVI. Report on Fund's Operation
A2: (Ban hành kèm theo Thông tư số 98/2020/TT-BTC ngày 16 tháng 11 năm 2020 của Bộ trưởng Bộ Tài Chính về hướng dẫn hoạt động và quản lý quỹ đầu tư chứng khoán) (Issued in association with Circular 98/2020/TT-BTC dated 16 November 2020 of the Minister of Finance on guiding the operation and management of the securities investment funds)
A3: BÁO CÁO VỀ HOẠT ĐỘNG ĐẦU TƯ REPORT ON INVESTMENT ACTIVITIES
A5: Tháng 07 năm 2022 / Jul 2022
A7: Tên Công ty quản lý quỹ: | C7: Công ty Cổ phần Quản lý Quỹ Đầu tư Dragon Capital Việt Nam
A8: Fund Management Company: | C8: Dragon Capital Vietfund Management Joint Stock Company
A9: Tên ngân hàng giám sát: | C9: Ngân hàng TNHH Một thành viên Standard Chartered (Việt Nam)
A10: Supervising bank: | C10: Standard Chartered Bank (Vietnam) Limited
A11: Tên Quỹ: | C11: Quỹ Đầu tư Chứng khoán Năng động DC
A12: Fund name: | C12: DC Dynamic Securities Fund(VFMVF1)
A13: Ngày lập báo cáo: | C13: Ngày 01 tháng 08 năm 2022
A14: Reporting Date: | C14: 01 Aug 2022
A16: A. | B16: BÁO CÁO CHUNG VỀ HOẠT ĐỘNG ĐẦU TƯ CỦA QUỸ/GENERAL INFORMATION ON FUND'S INVESTMENT ACTIVITIES
A17: II | B17: BÁO CÁO KẾT QUẢ HOẠT ĐỘNG / PROFIT AND LOSS REPORT
A18: STT No | B18: Nội dung Indicator | C18: Mã chỉ tiêu Code | D18: Tháng 07 năm 2022 Jul 2022 | E18: Tháng 06 năm 2022 Jun 2022 | F18: Lũy kế từ đầu năm Accumulated from beginning of year
A19: I | B19: Thu nhập từ hoạt động đầu tư Income from Investment Activities | D19: 4527487272 | E19: 5778917619 | F19: 20134422879
A20: 1 | B20: Thu từ bất động sản cho thuê (không áp dụng) Income from rental property (not applicable)
A21: 2 | B21: Cổ tức, trái tức được nhận Dividend income, interest income from bonds | D21: 4438803790 | E21: 5691951625 | F21: 18399525406
B22: Cổ tức được nhận Dividends income | D22: 2937160000 | E22: 4163184500 | F22: 9928292500
B23: Trái tức được nhận Interest income from bonds | D23: 1501643790 | E23: 1528767125 | F23: 8471232906
A24: 3 | B24: Lãi được nhận Interest income | D24: 88683482 | E24: 86965994 | F24: 1734897473
B25: Lãi tiền gửi ngân hàng Interest income from bank deposits | D25: 22224578 | E25: 22650926 | F25: 1028198843
B26: Lãi chứng chỉ tiền gửi Interest income from Certificates of Deposit | D26: 66458904 | E26: 64315068 | F26: 706698630
B27: Lãi hợp đồng mua lại đảo ngược Interest income from reverse repo contracts | D27: 0 | E27: 0 | F27: 0
A28: 4 | B28: Các khoản thu nhập khác Other incomes | D28: 0 | E28: 0 | F28: 0
B29: Thu nhập khác về đầu tư Other investment incomes | D29: 0 | E29: 0 | F29: 0
B30: Thu nhập khác Other incomes | D30: 0 | E30: 0 | F30: 0
B31: Chi phí dự phòng nợ phải thu khó đòi về cổ tức, tiền lãi và xử lý tổn thất nợ phải thu khó đòi về cổ tức, tiền lãi Provision expense for bad debts from dividends, interest income and written off bad debts from dividends, interest income | D31: 0 | E31: 0 | F31: 0
A32: II | B32: Chi phí Expenses | D32: 4669338584 | E32: 5216351986 | F32: 28333305747
A33: 1 | B33: Chi phí quản lý trả cho Công ty quản lý quỹ Management Fee paid to Fund Management Company | D33: 2510663947 | E33: 2562833656 | F33: 18994474631
A34: 2 | B34: Chi phí lưu ký, giám sát trả cho Ngân hàng Giám sát/VSD Custody fee, Supervising fee paid to Supervising Bank/VSD | D34: 151138053 | E34: 153352081 | F34: 978239083
B35: Chi phí dịch vụ lưu ký - bảo quản tài sản Custodian service - Safe Custody Fee | D35: 51500798 | E35: 52570948 | F35: 389630247
B36: Chi phí dịch vụ lưu ký - giao dịch chứng khoán Custodian service - Transaction fee | D36: 33200000 | E36: 33700000 | F36: 104600000
B37: Chi phí dịch vụ lưu ký cho chứng khoán cơ sở, phí quản lý vị thế và tài sản phái sinh trả cho VSD Custodian service - Depository fee, Position and Margin management fee paid to VSD | D37: 9786377 | E37: 9253091 | F37: 55415562
B38: Chi phí giám sát Supervisory fee | D38: 56650878 | E38: 57828042 | F38: 428593274
A39: 3 | B39: Chi phí quản trị quỹ và các chi phí khác mà công ty quản lý quỹ trả cho tổ chức cung cấp dịch vụ có liên quan Fund Administration Fee, and other fees paid to relevant Fund's service providers | D39: 48606798 | E39: 47142524 | F39: 347070794
B40: Chi phí quản trị Quỹ Fund Administration Fee | D40: 35406798 | E40: 36142524 | F40: 267870794
B41: Chi phí dịch vụ Đại lý Chuyển nhượng Transfer Agency Fee | D41: 13200000 | E41: 11000000 | F41: 79200000
A42: 4 | B42: Chi phí dịch vụ quản lý bất động sản (không áp dụng) Real Estate Management Service fee (not applicable)
A43: 5 | B43: Chi phí dịch vụ định giá bất động sản (không áp dụng) Real estate valuation service fees (not applicable)
...

Sheet BCDanhMucDauTu_06029
A1: Phụ lục XXVI. Mẫu báo cáo về hoạt động của Quỹ Appendix XXVI. Report on Fund's Operation
A2: (Ban hành kèm theo Thông tư số 98/2020/TT-BTC ngày 16 tháng 11 năm 2020 của Bộ trưởng Bộ Tài chính về hướng dẫn hoạt động và quản lý quỹ đầu tư chứng khoán) (Issued in association with Circular 98/2020/TT-BTC dated 16 November 2020 of the Minister of Finance on guiding the operation and management of the securities investment funds)
A3: BÁO CÁO VỀ HOẠT ĐỘNG ĐẦU TƯ REPORT ON INVESTMENT ACTIVITIES
A5: Tại ngày 31 tháng 07 năm 2022 / As at 31 Jul 2022
A7: Tên Công ty quản lý quỹ: | C7: Công ty Cổ phần Quản lý Quỹ Đầu tư Dragon Capital Việt Nam
A8: Fund Management Company: | C8: Dragon Capital Vietfund Management Joint Stock Company
A9: Tên ngân hàng giám sát: | C9: Ngân hàng TNHH Một thành viên Standard Chartered (Việt Nam)
A10: Supervising bank: | C10: Standard Chartered Bank (Vietnam) Limited
A11: Tên Quỹ: | C11: Quỹ Đầu tư Chứng khoán Năng động DC
A12: Fund name: | C12: DC Dynamic Securities Fund(VFMVF1)
A13: Ngày lập báo cáo: | C13: Ngày 01 tháng 08 năm 2022
A14: Reporting Date: | C14: 01 Aug 2022
A16: A. | B16: BÁO CÁO CHUNG VỀ HOẠT ĐỘNG ĐẦU TƯ CỦA QUỸ/GENERAL INFORMATION ON FUND'S INVESTMENT ACTIVITIES
A17: III | B17: BÁO CÁO DANH MỤC ĐẦU TƯ / INVESTMENT PORTFOLIO REPORT
A18: STT No. | B18: Loại Category | C18: Mã chỉ tiêu Code | D18: Số Lượng Quantity | E18: Giá thị trường hoặc giá trị hợp lý tại ngày báo cáo Market price | F18: Tổng giá trị (Đồng) Value (VND) | G18: Tỷ lệ % Tổng giá trị tài sản của Quỹ % of total asset
A19: I | B19: BẤT ĐỘNG SẢN ĐẦU TƯ (KHÔNG ÁP DỤNG) REAL ESTATE INVESTMENT (NOT APPLICABLE)
A20: II | B20: CỔ PHIẾU NIÊM YẾT, ĐĂNG KÝ GIAO DỊCH, CHỨNG CHỈ QUỸ NIÊM YẾT SHARES LISTED, SHARES REGISTERED FOR TRADING, LISTED FUND CERTIFICATES
A21: 1 | B21: ACB | D21: 662677 | E21: 24600 | F21: 16301854200 | G21: 0.0097107089
A22: 2 | B22: BID | D22: 526800 | E22: 37300 | F22: 19649640000 | G22: 0.011704922
A23: 3 | B23: BWE | D23: 150000 | E23: 47700 | F23: 7155000000 | G23: 0.0042620993
A24: 4 | B24: CTD | D24: 196800 | E24: 60300 | F24: 11867040000 | G24: 0.0070689732
A25: 5 | B25: CTG | D25: 396800 | E25: 27200 | F25: 10792960000 | G25: 0.0064291639
A26: 6 | B26: DGC | D26: 212900 | E26: 89300 | F26: 19011970000 | G26: 0.011325074
A27: 7 | B27: DGW | D27: 257200 | E27: 58600 | F27: 15071920000 | G27: 0.0089780602
A28: 8 | B28: DPG | D28: 400000 | E28: 44250 | F28: 17700000000 | G28: 0.010543558
A29: 9 | B29: DXG | D29: 1101500 | E29: 24800 | F29: 27317200000 | G29: 0.016272344
A30: 10 | B30: FPT | D30: 615700 | E30: 83500 | F30: 51410950000 | G30: 0.030624539
A31: 11 | B31: FRT | D31: 226000 | E31: 72000 | F31: 16272000000 | G31: 0.0096929253
A32: 12 | B32: GAS | D32: 566800 | E32: 107500 | F32: 60931000000 | G32: 0.036295454
... A67: 47 | B67: VSH | D67: 399900 | E67: 39300 | F67: 15716070000 | G67: 0.0093617682
B68: TỔNG TOTAL | F68: 1271337570950 | G68: 0.75731195
A69: III | B69: CỔ PHIẾU CHƯA NIÊM YẾT, ĐĂNG KÝ GIAO DỊCH, CHỨNG CHỈ QUỸ KHÔNG NIÊM YẾT SHARES UNLISTED, UNREGISTERED FOR TRADING, UNLISTED FUND CERTIFICATES
B70: TỔNG TOTAL | D70: 0 | F70: 0 | G70: 0
B71: TỔNG CÁC LOẠI CỔ PHIẾU TOTAL SHARES | F71: 1271337570950 | G71: 0.75731195
A72: IV | B72: TRÁI PHIẾU BONDS
A73: 1 | B73: Trái phiếu niêm yết Listed bonds | F73: 30062400000 | G73: 0.017907608
A74: 1.1 | B74: CII121029 | D74: 300000 | E74: 100208 | F74: 30062400000 | G74: 0.017907608
A75: 2 | B75: Trái phiếu chưa niêm yết Unlisted Bonds | F75: 89993424600 | G75: 0.053607396
A76: 2.1 | B76: DAT XANH GROUP JSC 12% 18 Mar 2023 | D76: 200 | E76: 99967123 | F76: 19993424600 | G76: 0.011909708
A77: 2.2 | B77: KDH TRADING & INV JSC 12% 14/06/2025 | D77: 30 | E77: 1000000000 | F77: 30000000000 | G77: 0.017870438
...

Sheet BCHoatDongVay_06026
A1: Phụ lục XXVI. Mẫu báo cáo về hoạt động của Quỹ Appendix XXVI. Report on Fund's Operation
A2: (Ban hành kèm theo Thông tư số 98/2020/TT-BTC ngày 16 tháng 11 năm 2020 của Bộ trưởng Bộ Tài Chính về hướng dẫn hoạt động và quản lý quỹ đầu tư chứng khoán) (Issued in association with Circular 98/2020/TT-BTC dated 16 November 2020 of the Minister of Finance on guiding the operation and management of the securities investment funds)
A3: BÁO CÁO VỀ HOẠT ĐỘNG ĐẦU TƯ REPORT ON INVESTMENT ACTIVITIES
A5: =TONGQUAN!C2 -> Tháng 07 năm 2022 / Jul 2022
A7: Tên Công ty quản lý quỹ: | G7: =TONGQUAN!D5 -> Công ty Cổ phần Quản lý Quỹ Đầu tư Dragon Capital Việt Nam
A8: Fund Management Company: | G8: =TONGQUAN!D6 -> Dragon Capital Vietfund Management Joint Stock Company
A9: Tên ngân hàng giám sát: | G9: =TONGQUAN!D7 -> Ngân hàng TNHH Một thành viên Standard Chartered (Việt Nam)
A10: Supervising bank: | G10: =TONGQUAN!D8 -> Standard Chartered Bank (Vietnam) Limited
A11: Tên Quỹ: | G11: =TONGQUAN!D9 -> Quỹ Đầu tư Chứng khoán Năng động DC
A12: Fund name: | G12: =TONGQUAN!D10 -> DC Dynamic Securities Fund(VFMVF1)
A13: Ngày lập báo cáo: | G13: =TONGQUAN!D11 -> Ngày 01 tháng 08 năm 2022
A14: Reporting Date: | G14: =TONGQUAN!D12 -> 01 Aug 2022
A15: A. | B15: BÁO CÁO CHUNG VỀ HOẠT ĐỘNG ĐẦU TƯ CỦA QUỸ/GENERAL INFORMATION ON FUND'S INVESTMENT ACTIVITIES
A16: IV | B16: BÁO CÁO HOẠT ĐỘNG VAY, GIAO DỊCH MUA BÁN LẠI / REPORT ON BORROWING OPERATION, REPO/REVERSE REPO TRANSACTIONS
A17: STT No. | B17: Nội dung hoạt động (nêu chi tiết theo mục tiêu và đối tác) Description | C17: Mã chỉ tiêu Code | D17: Đối tác Counterparty | E17: Mục tiêu/Tài sản đảm bảo Collateral | F17: Kỳ hạn Term | G17: Giá trị khoản vay hoặc khoản cho vay Amount | H17: Thời điểm giao dịch As at transaction date | J17: Thời điểm báo cáo As at reporting date
H18: Ngày tháng năm Date | I18: Tỷ lệ giá trị hợp đồng/giá trị tài sản ròng của quỹ Balance/NAV | J18: Ngày tháng năm Date | K18: Tỷ lệ giá trị hợp đồng/giá trị tài sản ròng của quỹ Balance/NAV
A19: 1 | B19: Các khoản vay tiền (nêu chi tiết từng hợp đồng) Borrowings (detail by each contract)
A20: I | B20: Tổng giá trị các khoản vay tiền/giá trị tài sản ròng Borrowings/NAV
A21: 2 | B21: Hợp đồng Repo (nêu chi tiết từng hợp đồng) Repo contract (detail by each contract)
A22: II | B22: Tổng giá trị các hợp đồng Repo/giá trị tài sản ròng Total value of Repo contracts/NAV
A23: A | B23: Tổng giá trị các khoản vay/giá trị tài sản ròng (=I+II) Total Borrowings, Repo/NAV (=I+II)
A24: 3 | B24: Cho vay chứng khoán (nêu chi tiết từng hợp đồng) Securities lending (detail by each contract)
A25: III | B25: Tổng giá trị các hợp đồng/giá trị tài sản ròng Total contract value/NAV
A26: 4 | B26: Hợp đồng Reverse Repo (nêu chi tiết từng hợp đồng) Reverse Repo contract (Detail by each contract)
A27: IV | B27: Tổng giá trị các hợp đồng/giá trị tài sản ròng Total contract value/NAV
A28: B | B28: Tổng giá trị các khoản cho vay/giá trị tài sản ròng (=III + IV) Total Loans/NAV (=III + IV)
A33: Đại diện có thẩm quyền của Ngân hàng giám sát | I33: Đại diện có thẩm quyền của Công ty quản lý Quỹ
A34: Authorised Representative of Supervisory Bank | I34: Authorised Representative of Fund Management Company
A44: Ngân hàng TNHH MTV Standard Chartered (Việt Nam) | I44: =TONGQUAN!F19 -> Công ty Cổ phần Quản lý Quỹ Đầu tư Dragon Capital Việt Nam
A45: =TONGQUAN!C20 -> Trịnh Hoài Nam | I45: =TONGQUAN!F20 -> Nguyễn Minh Đăng Khánh
A46: =TONGQUAN!C21 -> Phó phòng Dịch vụ Quản trị và Giám sát Quỹ | I46: =TONGQUAN!F21 -> Giám đốc điều hành Nghiệp vụ hỗ trợ đầu tư

Sheet Khac_06030
A1: Phụ lục XXVI. Mẫu báo cáo về hoạt động của Quỹ Appendix XXVI. Report on Fund's Operation
A2: (Ban hành kèm theo Thông tư số 98/2020/TT-BTC ngày 16 tháng 11 năm 2020 của Bộ trưởng Bộ Tài chính về hướng dẫn hoạt động và quản lý quỹ đầu tư chứng khoán) (Issued in association with Circular 98/2020/TT-BTC dated 16 November 2020 of the Minister of Finance on guiding the operation and management of the securities investment funds)
A3: BÁO CÁO VỀ HOẠT ĐỘNG ĐẦU TƯ REPORT ON INVESTMENT ACTIVITIES
A5: Tháng 07 năm 2022 / Jul 2022
A7: Tên Công ty quản lý quỹ: | C7: Công ty Cổ phần Quản lý Quỹ Đầu tư Dragon Capital Việt Nam
A8: Fund Management Company: | C8: Dragon Capital Vietfund Management Joint Stock Company
A9: Tên ngân hàng giám sát: | C9: Ngân hàng TNHH Một thành viên Standard Chartered (Việt Nam)
A10: Supervising bank: | C10: Standard Chartered Bank (Vietnam) Limited
A11: Tên Quỹ: | C11: Quỹ Đầu tư Chứng khoán Năng động DC
A12: Fund name: | C12: DC Dynamic Securities Fund(VFMVF1)
A13: Ngày lập báo cáo: | C13: Ngày 01 tháng 08 năm 2022
A14: Reporting Date: | C14: 01 Aug 2022
A16: A. | B16: BÁO CÁO CHUNG VỀ HOẠT ĐỘNG ĐẦU TƯ CỦA QUỸ/GENERAL INFORMATION ON FUND'S INVESTMENT ACTIVITIES
A17: V | B17: MỘT SỐ CHỈ TIÊU KHÁC / OTHER INDICATORS
A18: STT No | B18: Chỉ tiêu Indicators | C18: Mã chỉ tiêu Code | D18: Tháng 07 năm 2022 Jul 2022 | E18: Tháng 06 năm 2022 Jun 2022
A19: I | B19: CÁC CHỈ TIÊU VỀ HIỆU QUẢ HOẠT ĐỘNG INVESTMENT PERFORMANCE INDICATORS
A20: 1 | B20: Tỷ lệ giá dịch vụ quản lý quỹ trả cho công ty quản lý quỹ/Giá trị tài sản ròng trung bình trong kỳ (%) Management fee paid to the fund management company/Average NAV (%) | D20: 0.019876187 | E20: 0.019234837
A21: 2 | B21: Tỷ lệ giá dịch vụ lưu ký, giám sát trả cho Ngân hàng Giám sát/Giá trị tài sản ròng trung bình trong kỳ (%) Custody and supervising fees paid to the Supervisory Bank/Average NAV (%) | D21: 0.0011190396 | E21: 0.0010815062
A22: 3 | B22: Tỷ lệ chi phí dịch vụ quản trị quỹ, và các chi phí khác mà công ty quản lý quỹ trả cho tổ chức cung cấp dịch vụ có liên quan/Giá trị tài sản ròng của quỹ trung bình trong kỳ (%) Fund admin fee, and other fees paid to relating services providers by the fund management company/Average NAV (%) | D22: 0.00046228157 | E22: 0.00042326604
A23: 4 | B23: Chi phí kiểm toán trả cho tổ chức kiểm toán (nếu phát sinh)/Giá trị tài sản ròng trung bình trong kỳ (%) Auditing fee paid to auditing organizations (if any)/Average NAV (%) | D23: 0.00013063765 | E23: 0.00011985372
A24: 5 | B24: Chi phí trả cho tổ chức quản lý bất động sản/ Giá trị tài sản ròng trung bình trong kỳ (%) (không áp dụng) Fee paid to Real Estate management organisation/ Average NAV (%) (not applicable)
A25: 6 | B25: Chi phí trả cho doanh nghiệp thẩm định giá bất động sản/Giá trị tài sản ròng trung bình trong kỳ (%) (không áp dụng) Fee paid to Real Estate valuation service provider/ Average NAV (%) (not applicable)
A26: 7 | B26: Chi phí dịch vụ tư vấn pháp lý, dịch vụ báo giá và các dịch vụ hợp lý khác, thù lao trả cho ban đại diện quỹ/Giá trị tài sản ròng trung bình trong kỳ (%) Legal consultancy, price quotation and other appropriate service fees; remunerations paid to the Board of Representatives/Average NAV (%) | D26: 0.0004587958 | E26: 9.5289742e-05
A27: 8 | B27: Tỷ lệ chi phí /Giá trị tài sản ròng trung bình trong kỳ (%) Expense/Average NAV (%) | D27: 0.036965779 | E27: 0.039150289
A28: 9 | B28: Tốc độ vòng quay danh mục trong kỳ (%) = (Tổng giá trị mua vào + tổng giá trị bán ra) x 100%/ (2 x Giá trị tài sản ròng trung bình trong kỳ) Portfolio turnover rate (%) = (Total value of purchase transactions + total value of sales transactions) x 100%/ (2 x Average NAV) (**) | D28: 6.0501778 | E28: 6.4666664
A29: 10 | B29: Tỷ lệ thu nhập (tính cả thu nhập từ lãi, cổ tức, trái tức, chênh lệch giá)/ Giá trị tài sản ròng (không áp dụng) Income (including interest income, dividend, coupon income and unrealised gain)/ Average NAV (%) (not applicable)
A30: II | B30: CÁC CHỈ TIÊU KHÁC OTHER INDICATORS
A31: 1 | B31: Quy mô quỹ đầu kỳ (theo mệnh giá) Fund scale at the beginning of the period (based on par value) | D31: 257852775500 | E31: 252649777600
B32: Tổng giá trị chứng chỉ quỹ đang lưu hành đầu kỳ (theo mệnh giá) Total value of outstanding Fund Certificate at the beginning of period (based on par value) | D32: 257852775500 | E32: 252649777600
B33: Tổng số lượng chứng chỉ quỹ đang lưu hành đầu kỳ Total number of outstanding Fund Certificate at the beginning of period | D33: 25785278 | E33: 25264978
A34: 2 | B34: Thay đổi quy mô quỹ trong kỳ (theo mệnh giá) Change of Fund scale during the period (based on par value) | D34: -2226121100 | E34: 5202997900
B35: Thay đổi số lượng chứng chỉ quỹ trong kỳ Change of Number of Fund Certificates during the period | D35: -222612.11 | E35: 520299.79
B36: Thay đổi giá trị vốn trong kỳ (theo mệnh giá) Change in capital amount during the period (based on par value) | D36: -2226121100 | E36: 5202997900
B37: Số lượng chứng chỉ quỹ phát hành thêm trong kỳ Number of Fund Certificates subscribed during the period | D37: 415796.87 | E37: 827815.92
B38: Giá trị vốn huy động thêm trong kỳ (theo mệnh giá) Net subscription amount during the period (based on par value) | D38: 4157968700 | E38: 8278159200
B39: Số lượng chứng chỉ quỹ mua lại trong kỳ Number of Fund Certificates redeemed during the period | D39: -638408.98 | E39: -307516.13
B40: Giá trị vốn phải thanh toán trong kỳ khi đáp ứng lệnh của nhà đầu tư (theo mệnh giá) Net redemption amount during the period (based on par value) | D40: -6384089800 | E40: -3075161300
A41: 3 | B41: Quy mô quỹ cuối kỳ (theo mệnh giá) Fund scale at the end of the period (based on par value) | D41: 255626654400 | E41: 257852775500
B42: Tổng giá trị thị trường của quỹ đang lưu hành cuối kỳ (theo mệnh giá) Total value of outstanding Fund Certificate at the end of the period (based on par value) | D42: 255626654400 | E42: 257852775500
B43: Tổng số lượng chứng chỉ quỹ đang lưu hành cuối kỳ Total number of outstanding Fund Certificate at the end of the period | D43: 25562665 | E43: 25785278
...
