Workbook
Name addlogo: INDEX(LogoFMS!$C$3:$C$76,MATCH(LogoFMS!$D$1,LogoFMS!$A$3:$A$76,0))

Sheet TONGQUAN
A1: Kỳ báo cáo: | C1: Tại ngày 31 tháng 12 năm 2024 / As at 31 Dec 2024
C2: Quý IV năm 2024 / Quarter IV 2024
A4: Thông tin chung:
C5: Tên Công ty quản lý quỹ: | D5: Công ty Cổ phần Quản lý Quỹ Đầu tư Dragon Capital Việt Nam
C6: Fund Management Company: | D6: Dragon Capital Vietfund Management Joint Stock Company
C7: Tên ngân hàng giám sát: | D7: Ngân hàng TNHH Một thành viên Standard Chartered (Việt Nam)
C8: Supervising bank: | D8: Standard Chartered Bank (Vietnam) Limited
C9: Tên Quỹ: | D9: Quỹ Đầu tư Trái phiếu DC
C10: Fund name: | D10: DC Bond Fund (DCBF)
C11: Ngày lập báo cáo: | D11: Ngày 07 tháng 01 năm 2025
C12: Reporting Date: | D12: 07 Jan 2025
A14: Người ký báo cáo:
C16: Đại diện có thẩm quyền của Ngân hàng giám sát | F16: Đại diện có thẩm quyền của Công ty quản lý Quỹ
C17: Authorised Representative of Supervisory Bank | F17: Authorised Representative of Fund Management Company
C19: Ngân hàng TNHH MTV Standard Chartered (Việt Nam) | F19: =D5 -> Công ty Cổ phần Quản lý Quỹ Đầu tư Dragon Capital Việt Nam
C20: Vũ Quang Phan | F20: Lê Hoàng Anh
C21: Phó phòng Dịch vụ nghiệp vụ giám sát Quỹ | F21: Quyền Giám đốc nghiệp vụ hỗ trợ đầu tư

Sheet BCTaiSan_06027
A1: Phụ lục XXVI. Mẫu báo cáo về hoạt động của Quỹ Appendix XXVI. Report on Fund's Operation
A2: (Ban hành kèm theo Thông tư số 98/2020/TT-BTC ngày 16 tháng 11 năm 2020 của Bộ trưởng Bộ Tài Chính về hướng dẫn hoạt động và quản lý quỹ đầu tư chứng khoán) (Issued in association with Circular 98/2020/TT-BTC dated 16 November 2020 of the Minister of Finance on guiding the operation and management of the securities investment funds)
A3: BÁO CÁO HOẠT ĐỘNG ĐẦU TƯ CỦA QUỸ MỞ REPORT ON OPEN ENDED FUND'S INVESTMENT ACTIVITIES
A5: Tại ngày 31 tháng 12 năm 2024 / As at 31 Dec 2024
A7: Tên Công ty quản lý quỹ: | C7: Công ty Cổ phần Quản lý Quỹ Đầu tư Dragon Capital Việt Nam
A8: Fund Management Company: | C8: Dragon Capital Vietfund Management Joint Stock Company
A9: Tên ngân hàng giám sát: | C9: Ngân hàng TNHH Một thành viên Standard Chartered (Việt Nam)
A10: Supervising bank: | C10: Standard Chartered Bank (Vietnam) Limited
A11: Tên Quỹ: | C11: Quỹ Đầu tư Trái phiếu DC
A12: Fund name: | C12: DC Bond Fund (DCBF)
A13: Ngày lập báo cáo: | C13: Ngày 07 tháng 01 năm 2025
A14: Reporting Date: | C14: 07 Jan 2025
A16: A. | B16: BÁO CÁO CHUNG VỀ HOẠT ĐỘNG ĐẦU TƯ CỦA QUỸ/GENERAL INFORMATION ON FUND'S INVESTMENT ACTIVITIES
A17: I | B17: BÁO CÁO VỀ TÀI SẢN / ASSET REPORT
A18: STT No | B18: Nội dung Indicator | C18: Mã chỉ tiêu Code | D18: Ngày 31 tháng 12 năm 2024 As at 31 Dec 2024 | E18: Ngày 30 tháng 09 năm 2024 As at 30 Sep 2024 | F18: %/cùng kỳ năm trước %/against last year
A19: I | B19: TÀI SẢN ASSETS | C19: 2200
A20: I.1 | B20: Tiền và các khoản tương đương tiền Cash and Cash Equivalents | C20: 2201 | D20: 260940922040 | E20: 156172164816 | F20: 3.7632083
B21: Tiền Cash | C21: 2202
A22: ... | B22: ... | C22: ... | D22: ... | E22: ... | F22: ...
B23: Tiền gửi ngân hàng Cash at bank | C23: 2203 | D23: 260940922040 | E23: 156172164816 | F23: 3.7632083
A24: ... | B24: ... | C24: ... | D24: ... | E24: ... | F24: ...
B25: Tiền gửi của nhà đầu tư cho hoạt động mua chứng chỉ quỹ Cash at bank for Fund's subscription | C25: 2203.1 | D25: 9923142711 | E25: 9525444010 | F25: 62.736741
B26: Tiền phải trả cho Nhà đầu tư về cổ tức và mua lại chứng chỉ quỹ Cash at bank for Fund's dividend payment and redemption | C26: 2203.2 | D26: 4391073 | E26: 4391073 | F26: 0.41283769
B27: Tiền gửi ngân hàng cho hoạt động của Quỹ Cash at bank for Fund's operation | C27: 2203.3 | D27: 2213388256 | E27: 842329733 | F27: 0.049849731
B28: Tiền gửi ký quỹ cho hoạt động đầu tư chứng khoán phái sinh Margin account for trading derivatives | C28: 2203.4 | D28: 0 | E28: 0
B29: Tiền, tương đương tiền Cash, cash equivalents | C29: 2203.5 | D29: 248800000000 | E29: 145800000000 | F29: 10.044409
A30: I.2 | B30: Các khoản đầu tư (kê chi tiết) Investments | C30: 2205 | D30: 1383107257612 | E30: 1360106253896 | F30: 3.3522179
A31: ... | B31: ... | C31: ... | D31: ... | E31: ... | F31: ...
B32: Cổ phiếu, chứng chỉ quỹ niêm yết Listed Shares, fund certificates | C32: 2205.1 | D32: 0 | E32: 0
B33: Cổ phiếu, chứng chỉ quỹ chưa niêm yết Unlisted Shares, fund certifictes | C33: 2205.2 | D33: 0 | E33: 0
B34: Trái phiếu Bonds | C34: 2205.3 | D34: 956884352009 | E34: 939006253896 | F34: 2.5341574
B35: Công cụ thị trường tiền tệ Money market instruments | C35: 2205.4 | D35: 265122905603 | E35: 265000000000 | F35: 7.5749402
B36: Hợp đồng tiền gửi có kỳ hạn trên ba (03) tháng Deposits with term over three (03) months | C36: 2205.5 | D36: 161100000000 | E36: 156100000000
B37: Quyền mua chứng khoán Investment - Rights | C37: 2205.6 | D37: 0 | E37: 0
B38: Hợp đồng tương lai chỉ số Index future contracts | C38: 2205.7 | D38: 0 | E38: 0
B39: Đầu tư khác Other investments | C39: 2205.8 | D39: 0 | E39: 0
B40: Hợp đồng mua lại đảo ngược Reverse repo contracts | C40: 2205.9 | D40: 0 | E40: 0
A41: I.3 | B41: Thu từ cho thuê bất động sản đầu tư (không áp dụng) Receivables from rental of investment property (not applicable) | C41: 2220 | D41: 0 | E41: 0
A42: ... | B42: ... | C42: ... | D42: ... | E42: ... | F42: ...
A43: I.4 | B43: Cổ tức, trái tức được nhận Dividend, Coupon receivables | C43: 2206 | D43: 30288039815 | E43: 15619405291 | F43: 2.2453645
...

Sheet BCKetQuaHoatDong_06028
A1: Phụ lục XXVI. Mẫu báo cáo về hoạt động của Quỹ Appendix XXVI. Report on Fund's Operation
A2: (Ban hành kèm theo Thông tư số 98/2020/TT-BTC ngày 16 tháng 11 năm 2020 của Bộ trưởng Bộ Tài Chính về hướng dẫn hoạt động và quản lý quỹ đầu tư chứng khoán) (Issued in association with Circular 98/2020/TT-BTC dated 16 November 2020 of the Minister of Finance on guiding the operation and management of the securities investment funds)
A3: BÁO CÁO HOẠT ĐỘNG ĐẦU TƯ CỦA QUỸ MỞ REPORT ON OPEN ENDED FUND'S INVESTMENT ACTIVITIES
A5: Quý IV năm 2024 / Quarter IV 2024
A7: Tên Công ty quản lý quỹ: | C7: Công ty Cổ phần Quản lý Quỹ Đầu tư Dragon Capital Việt Nam
A8: Fund Management Company: | C8: Dragon Capital Vietfund Management Joint Stock Company
A9: Tên ngân hàng giám sát: | C9: Ngân hàng TNHH Một thành viên Standard Chartered (Việt Nam)
A10: Supervising bank: | C10: Standard Chartered Bank (Vietnam) Limited
A11: Tên Quỹ: | C11: Quỹ Đầu tư Trái phiếu DC
A12: Fund name: | C12: DC Bond Fund (DCBF)
A13: Ngày lập báo cáo: | C13: Ngày 07 tháng 01 năm 2025
A14: Reporting Date: | C14: 07 Jan 2025
A16: A. | B16: BÁO CÁO CHUNG VỀ HOẠT ĐỘNG ĐẦU TƯ CỦA QUỸ/GENERAL INFORMATION ON FUND'S INVESTMENT ACTIVITIES
A17: II | B17: BÁO CÁO KẾT QUẢ HOẠT ĐỘNG / PROFIT AND LOSS REPORT
A18: STT No | B18: Nội dung Indicator | C18: Mã chỉ tiêu Code | D18: Quý IV năm 2024 Quarter IV 2024 | E18: Quý III năm 2024 Quarter III 2024 | F18: Lũy kế từ đầu năm Accumulated from beginning of year
A19: I | B19: Thu nhập từ hoạt động đầu tư Income from Investment Activities | C19: 2220 | D19: 31084786669 | E19: 26893035688 | F19: 94422054315
A20: 1 | B20: Thu từ bất động sản cho thuê (không áp dụng) Income from rental property (not applicable) | C20: 2223 | D20: 0 | E20: 0 | F20: 0
A21: ... | B21: ... | C21: ... | D21: ... | E21: … | F21: …
A22: 2 | B22: Cổ tức, trái tức được nhận Dividend income, interest income from bonds | C22: 2221 | D22: 21436650554 | E22: 18333400700 | F22: 64672633442
A23: ... | B23: ... | C23: ... | D23: ... | E23: … | F23: …
B24: Cổ tức được nhận Dividends income | C24: 2221.1 | D24: 0 | E24: 0 | F24: 0
B25: Trái tức được nhận Interest income from bonds | C25: 2221.2 | D25: 21436650554 | E25: 18333400700 | F25: 64672633442
A26: 3 | B26: Lãi được nhận Interest income | C26: 2222 | D26: 9648136115 | E26: 8559634988 | F26: 29749420873
A27: ... | B27: ... | C27: ... | D27: ... | E27: ... | F27: ...
B28: Lãi tiền gửi ngân hàng Interest income from bank deposits | C28: 2222.1 | D28: 4691725157 | E28: 3231087044 | F28: 13238023615
B29: Lãi công cụ thị trường tiền tệ Interest income from Money market instruments | C29: 2222.2 | D29: 4956410958 | E29: 5328547944 | F29: 16511397258
B30: Lãi hợp đồng mua lại đảo ngược Interest income from reverse repo contracts | C30: 2222.3 | D30: 0 | E30: 0 | F30: 0
A31: 4 | B31: Các khoản thu nhập khác Other incomes | C31: 2223 | D31: 0 | E31: 0 | F31: 0
A32: ... | B32: ... | C32: ... | D32: ... | E32: ... | F32: ...
B33: Thu nhập khác về đầu tư Other investment incomes | C33: 2223.1 | D33: 0 | E33: 0 | F33: 0
B34: Thu nhập khác Other incomes | C34: 2223.2 | D34: 0 | E34: 0 | F34: 0
B35: Chi phí dự phòng nợ phải thu khó đòi về cổ tức, tiền lãi và xử lý tổn thất nợ phải thu khó đòi về cổ tức, tiền lãi Provision expense for bad debts from dividends, interest income and written off bad debts from dividends, interest income | C35: 2223.3 | D35: 0 | E35: 0 | F35: 0
A36: II | B36: Chi phí Expenses | C36: 2224 | D36: 5704744487 | E36: 5247439042 | F36: 17785928645
A37: 1 | B37: Chi phí quản lý trả cho Công ty quản lý quỹ Management Fee paid to Fund Management Company | C37: 2225 | D37: 4801176409 | E37: 4315110065 | F37: 14826392925
A38: ... | B38: ... | C38: ... | D38: ... | E38: ... | F38: ...
A39: 2 | B39: Chi phí lưu ký, giám sát trả cho Ngân hàng Giám sát/VSDC Custody fee, Supervising fee paid to Supervising Bank/VSDC | C39: 2226 | D39: 326579992 | E39: 313273976 | F39: 1048321067
A40: ... | B40: ... | C40: ... | D40: ... | E40: ... | F40: ...
B41: Chi phí dịch vụ lưu ký - bảo quản tài sản Custodian service - Safe Custody Fee | C41: 2226.1 | D41: 140237335 | E41: 143837005 | F41: 474411221
B42: Chi phí dịch vụ lưu ký - giao dịch chứng khoán Custodian service - Transaction fee | C42: 2226.2 | D42: 6200000 | E42: 8500000 | F42: 19500000
B43: Chi phí dịch vụ lưu ký cho chứng khoán cơ sở, phí quản lý vị thế và tài sản phái sinh trả cho VSDC Custodian service - Depository fee, Position and Margin management fee paid to VSDC | C43: 2226.3 | D43: 4099523 | E43: 2716268 | F43: 10775439
...

Sheet BCDanhMucDauTu_06029
A1: Phụ lục XXVI. Mẫu báo cáo về hoạt động của Quỹ Appendix XXVI. Report on Fund's Operation
A2: (Ban hành kèm theo Thông tư số 98/2020/TT-BTC ngày 16 tháng 11 năm 2020 của Bộ trưởng Bộ Tài Chính về hướng dẫn hoạt động và quản lý quỹ đầu tư chứng khoán) (Issued in association with Circular 98/2020/TT-BTC dated 16 November 2020 of the Minister of Finance on guiding the operation and management of the securities investment funds)
A3: BÁO CÁO HOẠT ĐỘNG ĐẦU TƯ CỦA QUỸ MỞ REPORT ON OPEN ENDED FUND'S INVESTMENT ACTIVITIES
A5: =TONGQUAN!C1 -> Tại ngày 31 tháng 12 năm 2024 / As at 31 Dec 2024
A7: Tên Công ty quản lý quỹ: | C7: =TONGQUAN!D5 -> Công ty Cổ phần Quản lý Quỹ Đầu tư Dragon Capital Việt Nam
A8: Fund Management Company: | C8: =TONGQUAN!D6 -> Dragon Capital Vietfund Management Joint Stock Company
A9: Tên ngân hàng giám sát: | C9: =TONGQUAN!D7 -> Ngân hàng TNHH Một thành viên Standard Chartered (Việt Nam)
A10: Supervising bank: | C10: =TONGQUAN!D8 -> Standard Chartered Bank (Vietnam) Limited
A11: Tên Quỹ: | C11: =TONGQUAN!D9 -> Quỹ Đầu tư Trái phiếu DC
A12: Fund name: | C12: =TONGQUAN!D10 -> DC Bond Fund (DCBF)
A13: Ngày lập báo cáo: | C13: =TONGQUAN!D11 -> Ngày 07 tháng 01 năm 2025
A14: Reporting Date: | C14: =TONGQUAN!D12 -> 07 Jan 2025
A16: A. | B16: BÁO CÁO CHUNG VỀ HOẠT ĐỘNG ĐẦU TƯ CỦA QUỸ/GENERAL INFORMATION ON FUND'S INVESTMENT ACTIVITIES
A17: III | B17: BÁO CÁO DANH MỤC ĐẦU TƯ / INVESTMENT PORTFOLIO REPORT
A18: STT No. | B18: Loại Category | C18: Mã chỉ tiêu Code | D18: Số Lượng Quantity | E18: Giá thị trường hoặc giá trị hợp lý tại ngày báo cáo Market price | F18: Tổng giá trị (Đồng) Value (VND) | G18: Tỷ lệ % Tổng giá trị tài sản của Quỹ % of total asset
A19: I | B19: BẤT ĐỘNG SẢN ĐẦU TƯ (KHÔNG ÁP DỤNG) REAL ESTATE INVESTMENT (NOT APPLICABLE)
B21: TỔNG TOTAL | C21: 2264
A22: II | B22: CỔ PHIẾU NIÊM YẾT, ĐĂNG KÝ GIAO DỊCH, CHỨNG CHỈ QUỸ NIÊM YẾT SHARES LISTED, SHARES REGISTERED FOR TRADING, LISTED FUND CERTIFICATES | C22: 2246
B24: TỔNG TOTAL | C24: 2247
A25: III | B25: CỔ PHIẾU CHƯA NIÊM YẾT, ĐĂNG KÝ GIAO DỊCH, CHỨNG CHỈ QUỸ KHÔNG NIÊM YẾT SHARES UNLISTED, UNREGISTERED FOR TRADING, UNLISTED FUND CERTIFICATES | C25: 2248
B27: TỔNG TOTAL | C27: 2249 | F27: 0 | G27: 0
A28: IV | B28: TRÁI PHIẾU BONDS | C28: 2251
A30: 1 | B30: Trái phiếu niêm yết Listed bonds | C30: 2251.1 | F30: 803804814079 | G30: 0.47624957
A31: 1.1 | B31: BAF122029 | C31: 2251.1.1 | D31: 390000 | E31: 100539.32 | F31: 39210336750 | G31: 0.023231891
A32: 1.2 | B32: BAF123020 | C32: 2251.1.2 | D32: 452357 | E32: 100750.69 | F32: 45575278067 | G32: 0.027003081
A33: 1.3 | B33: CII124021 | C33: 2251.1.3 | D33: 993 | E33: 100055449 | F33: 99355060857 | G33: 0.058867283
A34: 1.4 | B34: HDB124006 | C34: 2251.1.4 | D34: 100000 | E34: 100571.29 | F34: 10057128800 | G34: 0.005958789
A35: 1.5 | B35: HDB124018 | C35: 2251.1.5 | D35: 1000000 | E35: 99787.479 | F35: 99787479000 | G35: 0.059123488
A36: 1.6 | B36: MML121021 | C36: 2251.1.6 | D36: 400230 | E36: 99943.096 | F36: 40000225312 | G36: 0.023699896
A37: 1.7 | B37: MSN123008 | C37: 2251.1.7 | D37: 500000 | E37: 99645.297 | F37: 49822648500 | G37: 0.029519623
A38: 1.8 | B38: MSN123009 | C38: 2251.1.8 | D38: 250000 | E38: 99644.332 | F38: 24911083000 | G38: 0.014759669
A39: 1.9 | B39: TNG122017 | C39: 2251.1.9 | D39: 1100000 | E39: 101016.37 | F39: 111118009200 | G39: 0.06583676
A40: 1.10 | B40: VBA122001 | C40: 2251.1.10 | D40: 220480 | E40: 98098.34 | F40: 21628722003 | G40: 0.012814889
A41: 1.11 | B41: VIC123028 | C41: 2251.1.11 | D41: 380000 | E41: 99662.45 | F41: 37871731000 | G41: 0.022438775
A42: 1.12 | B42: VND122014 | C42: 2251.1.12 | D42: 654430 | E42: 100317.73 | F42: 65650929426 | G42: 0.038897785
... A44: 1.14 | B44: VRE12007 | C44: 2251.1.14 | D44: 200000 | E44: 100190.6 | F44: 20038120800 | G44: 0.011872467
A45: 2 | B45: Trái phiếu chưa niêm yết Unlisted Bonds | C45: 2251.2 | F45: 153079537930 | G45: 0.090698716
A46: 2.1 | B46: CII12403 | C46: 2251.2.1 | D46: 360 | E46: 99965873 | F46: 35987714280 | G46: 0.021322507
A47: 2.2 | B47: KBC12401 | C47: 2251.2.2 | D47: 75 | E47: 999709240 | F47: 74978193000 | G47: 0.044424133
A48: 2.3 | B48: KDH12101 | C48: 2251.2.3 | D48: 35 | E48: 1003246590 | F48: 35113630650 | G48: 0.020804617
...

Sheet BCHoatDongVay_06026
A1: Phụ lục XXVI. Mẫu báo cáo về hoạt động của Quỹ Appendix XXVI. Report on Fund's Operation
A2: (Ban hành kèm theo Thông tư số 98/2020/TT-BTC ngày 16 tháng 11 năm 2020 của Bộ trưởng Bộ Tài Chính về hướng dẫn hoạt động và quản lý quỹ đầu tư chứng khoán) (Issued in association with Circular 98/2020/TT-BTC dated 16 November 2020 of the Minister of Finance on guiding the operation and management of the securities investment funds)
A3: BÁO CÁO HOẠT ĐỘNG ĐẦU TƯ CỦA QUỸ MỞ REPORT ON OPEN ENDED FUND'S INVESTMENT ACTIVITIES
A5: =TONGQUAN!C2 -> Quý IV năm 2024 / Quarter IV 2024
A7: Tên Công ty quản lý quỹ: | G7: =TONGQUAN!D5 -> Công ty Cổ phần Quản lý Quỹ Đầu tư Dragon Capital Việt Nam
A8: Fund Management Company: | G8: =TONGQUAN!D6 -> Dragon Capital Vietfund Management Joint Stock Company
A9: Tên ngân hàng giám sát: | G9: =TONGQUAN!D7 -> Ngân hàng TNHH Một thành viên Standard Chartered (Việt Nam)
A10: Supervising bank: | G10: =TONGQUAN!D8 -> Standard Chartered Bank (Vietnam) Limited
A11: Tên Quỹ: | G11: =TONGQUAN!D9 -> Quỹ Đầu tư Trái phiếu DC
A12: Fund name: | G12: =TONGQUAN!D10 -> DC Bond Fund (DCBF)
A13: Ngày lập báo cáo: | G13: =TONGQUAN!D11 -> Ngày 07 tháng 01 năm 2025
A14: Reporting Date: | G14: =TONGQUAN!D12 -> 07 Jan 2025
A15: A. | B15: BÁO CÁO CHUNG VỀ HOẠT ĐỘNG ĐẦU TƯ CỦA QUỸ/GENERAL INFORMATION ON FUND'S INVESTMENT ACTIVITIES
A16: IV | B16: BÁO CÁO HOẠT ĐỘNG VAY, GIAO DỊCH MUA BÁN LẠI / REPORT ON BORROWING OPERATION, REPO/REVERSE REPO TRANSACTIONS
A17: STT No. | B17: Nội dung hoạt động (nên chi tiết theo mục tiêu và đối tác) Description | C17: Đối tác Counterparty | D17: Mục tiêu/ Tài sản đảm bảo Collateral | E17: Kỳ hạn Term | F17: Giá trị khoản vay hoặc khoản cho vay Amount | G17: Thời điểm giao dịch As at transaction date | I17: Thời điểm báo cáo As at reporting date
G18: Ngày tháng năm Date | H18: Tỷ lệ giá trị hợp đồng/giá trị tài sản ròng của quỹ/công ty (%) Balance/NAV (%) | I18: Ngày tháng năm Date | J18: Tỷ lệ giá trị hợp đồng/ giá trị tài sản ròng của quỹ/ công ty (%) Balance/NAV (%)
A19: 1 | B19: Các khoản vay tiền (nêu chi tiết từng hợp đồng)
A20: ... | B20: ... | C20: ... | D20: ... | E20: ... | F20: ... | G20: ... | H20: ... | I20: ... | J20: ...
A21: I | B21: Tổng giá trị các khoản vay tiền/giá trị tài sản ròng | F21: 0 | H21: 0 | J21: 0
A22: 2 | B22: Hợp đồng Repo (nêu chi tiết từng hợp đồng)
A23: ... | B23: ... | C23: ... | D23: ... | E23: ... | F23: ... | G23: ... | H23: ... | I23: ... | J23: ...
A24: II | B24: Tổng giá trị các hợp đồng Repo/giá trị tài sản ròng | F24: 0 | H24: 0 | J24: 0
A25: A | B25: Tổng giá trị các khoản vay/giá trị tài sản ròng (=I+II) | F25: 0 | H25: 0 | J25: 0
A26: 3 | B26: Cho vay chứng khoán (nêu chi tiết từng hợp đồng)
A27: ... | B27: ... | C27: ... | D27: ... | E27: ... | F27: ... | G27: ... | H27: ... | I27: ... | J27: ...
A28: III | B28: Tổng giá trị các hợp đồng/giá trị tài sản ròng | F28: 0 | H28: 0 | J28: 0
A29: 4 | B29: Hợp đồng Reverse Repo (nêu chi tiết từng hợp đồng)
A30: ... | B30: ... | C30: ... | D30: ... | E30: ... | F30: ... | G30: ... | H30: ... | I30: ... | J30: ...
A31: IV | B31: Tổng giá trị các hợp đồng/ giá trị tài sản ròng | F31: 0 | H31: 0 | J31: 0
A32: B | B32: Tổng giá trị các khoản cho vay/giá trị tài sản ròng (=III + IV) | F32: 0 | H32: 0 | J32: 0
A33: Đại diện có thẩm quyền của Ngân hàng giám sát | I33: Đại diện có thẩm quyền của Công ty quản lý Quỹ
A34: Authorised Representative of Supervisory Bank | I34: Authorised Representative of Fund Management Company
A40: Ngân hàng TNHH MTV Standard Chartered (Việt Nam) | I40: Công ty Cổ phần Quản lý Quỹ Đầu tư Dragon Capital Việt Nam
A41: Vũ Quang Phan | I41: Lê Hoàng Anh
A42: Phó phòng Dịch vụ nghiệp vụ giám sát Quỹ | I42: Quyền Giám đốc nghiệp vụ hỗ trợ đầu tư

Sheet Khac_06030
A1: Phụ lục XXVI. Mẫu báo cáo về hoạt động của Quỹ Appendix XXVI. Report on Fund's Operation
A2: (Ban hành kèm theo Thông tư số 98/2020/TT-BTC ngày 16 tháng 11 năm 2020 của Bộ trưởng Bộ Tài Chính về hướng dẫn hoạt động và quản lý quỹ đầu tư chứng khoán) (Issued in association with Circular 98/2020/TT-BTC dated 16 November 2020 of the Minister of Finance on guiding the operation and management of the securities investment funds)
A3: BÁO CÁO HOẠT ĐỘNG ĐẦU TƯ CỦA QUỸ MỞ REPORT ON OPEN ENDED FUND'S INVESTMENT ACTIVITIES
A5: Quý IV năm 2024 / Quarter IV 2024
A7: Tên Công ty quản lý quỹ: | C7: Công ty Cổ phần Quản lý Quỹ Đầu tư Dragon Capital Việt Nam
A8: Fund Management Company: | C8: Dragon Capital Vietfund Management Joint Stock Company
A9: Tên ngân hàng giám sát: | C9: Ngân hàng TNHH Một thành viên Standard Chartered (Việt Nam)
A10: Supervising bank: | C10: Standard Chartered Bank (Vietnam) Limited
A11: Tên Quỹ: | C11: Quỹ Đầu tư Trái phiếu DC
A12: Fund name: | C12: DC Bond Fund (DCBF)
A13: Ngày lập báo cáo: | C13: Ngày 07 tháng 01 năm 2025
A14: Reporting Date: | C14: 07 Jan 2025
A16: A. | B16: BÁO CÁO CHUNG VỀ HOẠT ĐỘNG ĐẦU TƯ CỦA QUỸ/GENERAL INFORMATION ON FUND'S INVESTMENT ACTIVITIES
A17: V | B17: MỘT SỐ CHỈ TIÊU KHÁC / OTHER INDICATORS
A18: STT No | B18: Chỉ tiêu Indicators | C18: Mã chỉ tiêu Code | D18: Quý IV năm 2024 Quarter IV 2024 | E18: Quý III năm 2024 Quarter III 2024
A19: I | B19: CÁC CHỈ TIÊU VỀ HIỆU QUẢ HOẠT ĐỘNG INVESTMENT PERFORMANCE INDICATORS | C19: 2264
A20: 1 | B20: Tỷ lệ giá dịch vụ quản lý quỹ trả cho công ty quản lý quỹ/Giá trị tài sản ròng trung bình trong kỳ (%) Management fee paid to the fund management company/Average NAV (%) | C20: 2265 | D20: 0.012067296 | E20: 0.012067621
A21: 2 | B21: Tỷ lệ giá dịch vụ lưu ký, giám sát trả cho Ngân hàng Giám sát/Giá trị tài sản ròng trung bình trong kỳ (%) Custody and supervising fees paid to the Supervisory Bank/Average NAV (%) | C21: 2266 | D21: 0.00081052371 | E21: 0.00086850456
A22: 3 | B22: Tỷ lệ chi phí dịch vụ quản trị quỹ, và các chi phí khác mà công ty quản lý quỹ trả cho tổ chức cung cấp dịch vụ có liên quan/Giá trị tài sản ròng của quỹ trung bình trong kỳ (%) Fund admin fee, and other fees paid to relating services providers by the fund management company/Average NAV (%) | C22: 22661 | D22: 0.00042509673 | E22: 0.00043174356
A23: 4 | B23: Chi phí kiểm toán trả cho tổ chức kiểm toán (nếu phát sinh)/Giá trị tài sản ròng trung bình trong kỳ (%) Auditing fee paid to auditing organizations (if any)/Average NAV (%) | C23: 2267 | D23: 8.8117019e-05 | E23: 9.8045414e-05
A24: 5 | B24: Chi phí trả cho tổ chức quản lý bất động sản/ Giá trị tài sản ròng trung bình trong kỳ (%) (không áp dụng) Fee paid to Real Estate management organisation/ Average NAV (%) (not applicable) | C24: 2286
A25: 6 | B25: Chi phí trả cho doanh nghiệp thẩm định giá bất động sản/Giá trị tài sản ròng trung bình trong kỳ (%) (không áp dụng) Fee paid to Real Estate valuation service provider/ Average NAV (%) (not applicable)
A26: 7 | B26: Chi phí dịch vụ tư vấn pháp lý, dịch vụ báo giá và các dịch vụ hợp lý khác, thù lao trả cho ban đại diện quỹ/Giá trị tài sản ròng trung bình trong kỳ (%) Legal consultancy, price quotation and other appropriate service fees; remunerations paid to the Board of Representatives/Average NAV (%) | C26: 2268 | D26: 0.00019464242 | E26: 0.00015085332
A27: 8 | B27: Tỷ lệ chi phí /Giá trị tài sản ròng trung bình trong kỳ (%) Expense/Average NAV (%) | C27: 2269 | D27: 0.013651615 | E27: 0.013723292
A28: 9 | B28: Tốc độ vòng quay danh mục trong kỳ (%)/Portfolio turnover rate (%) | C28: 2270 | D28: 1.7853931 | E28: 1.7217115
A29: 10 | B29: Tỷ lệ thu nhập (tính cả thu nhập từ lãi, cổ tức, trái tức, chênh lệch giá)/ Giá trị tài sản ròng (không áp dụng) Income (including interest income, dividend, coupon income and unrealised gain)/ Average NAV (%) (not applicable) | C29: 2287
A30: II | B30: CÁC CHỈ TIÊU KHÁC OTHER INDICATORS | C30: 2272
A31: 1 | B31: Quy mô quỹ đầu kỳ (tính theo mệnh giá chứng chỉ quỹ) Fund scale at the beginning of the period (based on par value of fund certificate) | C31: 2273 | D31: 557399216300 | E31: 512141120400
B32: Tổng giá trị chứng chỉ quỹ đang lưu hành đầu kỳ Total value of outstanding Fund Certificate at the beginning of period | C32: 2274 | D32: 557399216300 | E32: 512141120400
B33: Tổng số lượng chứng chỉ quỹ đang lưu hành đầu kỳ Total number of outstanding Fund Certificate at the beginning of period | C33: 2275 | D33: 55739922 | E33: 51214112
A34: 2 | B34: Thay đổi quy mô quỹ trong kỳ (tính theo mệnh giá chứng chỉ quỹ) Change of Fund scale during the period (based on par value of fund certificate) | C34: 2276 | D34: 50479299800 | E34: 45258095900
B35: Thay đổi số lượng chứng chỉ quỹ trong kỳ Change of Number of Fund Certificates during the period | C35: 22761 | D35: 5047930 | E35: 4525809.6
B36: Thay đổi giá trị vốn trong kỳ (theo mệnh giá) Change in capital amount during the period (based on par value) | C36: 22762 | D36: 50479299800 | E36: 45258095900
B37: Số lượng chứng chỉ quỹ phát hành thêm trong kỳ Number of Fund Certificates subscribed during the period | C37: 2277 | D37: 19074809 | E37: 16096108
B38: Giá trị vốn huy động thêm trong kỳ (theo mệnh giá) Net subscription amount during the period (based on par value) | C38: 2278 | D38: 190748086600 | E38: 160961080900
B39: Số lượng chứng chỉ quỹ mua lại trong kỳ Number of Fund Certificates redeemed during the period | C39: 22781 | D39: -14026879 | E39: -11570298
B40: Giá trị vốn phải thanh toán trong kỳ khi đáp ứng lệnh của nhà đầu tư (theo mệnh giá) Net redemption amount during the period (based on par value) | C40: 22782 | D40: -140268786800 | E40: -115702985000
A41: 3 | B41: Quy mô quỹ cuối kỳ (tính theo mệnh giá chứng chỉ quỹ) Fund scale at the end of the period (based on par value) | C41: 2279 | D41: 607878516100 | E41: 557399216300
B42: Tổng giá trị thị trường của quỹ đang lưu hành cuối kỳ (theo mệnh giá) Total value of outstanding Fund Certificate at the end of the period (based on par value) | C42: 2280 | D42: 607878516100 | E42: 557399216300
B43: Tổng số lượng chứng chỉ quỹ đang lưu hành cuối kỳ Total number of outstanding Fund Certificate at the end of the period | C43: 2281 | D43: 60787852 | E43: 55739922
...

Sheet BCThuNhap_06203
A1: Mẫu số B01 - QM Báo cáo thu nhập Template B01 - QM Statement of Comprehensive Income
A2: (Ban hành kèm theo Thông tư 198/2012/TT-BTC ngày 15 tháng 11 năm 2012 về chế độ kế toán áp dụng đối với quỹ mở) (Issued in association with Circular 198/2012/TT-BTC dated 15 Nov 2012 on the Accounting Policies for Open-Ended Fund)
A3: BÁO CÁO THU NHẬP STATEMENT OF COMPREHENSIVE INCOME
A5: =TONGQUAN!C2 -> Quý IV năm 2024 / Quarter IV 2024
A7: Tên Công ty quản lý quỹ: | D7: =TONGQUAN!D5 -> Công ty Cổ phần Quản lý Quỹ Đầu tư Dragon Capital Việt Nam
A8: Fund Management Company: | D8: =TONGQUAN!D6 -> Dragon Capital Vietfund Management Joint Stock Company
A9: Tên ngân hàng giám sát: | D9: =TONGQUAN!D7 -> Ngân hàng TNHH Một thành viên Standard Chartered (Việt Nam)
A10: Supervising bank: | D10: =TONGQUAN!D8 -> Standard Chartered Bank (Vietnam) Limited
A11: Tên Quỹ: | D11: =TONGQUAN!D9 -> Quỹ Đầu tư Trái phiếu DC
A12: Fund name: | D12: =TONGQUAN!D10 -> DC Bond Fund (DCBF)
A13: Ngày lập báo cáo: | D13: =TONGQUAN!D11 -> Ngày 07 tháng 01 năm 2025
A14: Reporting Date: | D14: =TONGQUAN!D12 -> 07 Jan 2025
A16: Chỉ tiêu Indicator | B16: Mã số Code | C16: Thuyết minh Note | D16: Năm 2024 Year 2024 | F16: Năm 2023 Year 2023
D17: =BCKetQuaHoatDong_06028!D18 -> Quý IV năm 2024 Quarter IV 2024 | E17: Số lũy kế Year-to-date | F17: Quý IV năm 2023 Quarter IV 2023 | G17: Số lũy kế Year-to-date
A18: I. THU NHẬP, DOANH THU HOẠT ĐỘNG ĐẦU TƯ Investment income | B18: 01 | D18: 33379845676 | E18: 99509616251 | F18: 12330419193 | G18: 41092208650
A19: 1.1. Cổ tức được chia Dividend income | B19: 02 | D19: 0 | E19: 0 | F19: 0 | G19: 0
A20: 1.2. Tiền lãi được nhận Interest income | B20: 03 | D20: 31084786669 | E20: 94422054315 | F20: 10074642133 | G20: 37966620921
A21: Lãi tiền gửi ngân hàng Interest income from bank deposits | B21: 03.1 | D21: 4691725157 | E21: 13238023615 | F21: 128065761 | G21: 3206997455
A22: Lãi công cụ thị trường tiền tệ Interest income from Money market instruments | B22: 03.2 | D22: 4956410958 | E22: 16511397258 | F22: 970410958 | G22: 1909726027
A23: Lãi trái phiếu Interest income from bonds | B23: 03.3 | D23: 21436650554 | E23: 64672633442 | F23: 8976165414 | G23: 32849897439
A24: Tiền lãi hợp đồng mua lại đảo ngược được nhận Reverse repo contract interest received | B24: 03.4 | D24: 0 | E24: 0 | F24: 0 | G24: 0
A25: 1.3. Lãi (lỗ) bán các khoản đầu tư Realized gain (losses) from disposal investments | B25: 04 | D25: 2605392376 | E25: 6377328833 | F25: 1242797289 | G25: 2062879766
A26: 1.4. Chênh lệch tăng, giảm đánh giá lại các khoản đầu tư chưa thực hiện Unrealized gain (losses) from investment revaluation | B26: 05 | D26: -310333369 | E26: -1289766897 | F26: 1012979771 | G26: 1062707963
A27: 1.5. Doanh thu khác Other income | B27: 06 | D27: 0 | E27: 0 | F27: 0 | G27: 0
A28: 1.6. Chênh lệch lãi, lỗ tỷ giá hối đoái đã và chưa thực hiện Realized and unrealized gain (losses) from foreign exchange | B28: 07 | D28: 0 | E28: 0 | F28: 0 | G28: 0
A29: 1.7. Doanh thu khác về đầu tư Other investment income | B29: 08 | D29: 0 | E29: 0 | F29: 0 | G29: 0
... A77: VIII. LỢI NHUẬN KẾ TOÁN SAU THUẾ TNDN PROFIT AFTER TAX (41=30-40) | B77: 41 | D77: 27675101189 | E77: 81723687606 | F77: 10755690676 | G77: 34890488461
A80: Người lập: | B80: Người duyệt:
A93: _______________________________________________ | B93: ___________________________________________ | F93: _____________________________
A94: Vương Thị Trâm Anh | B94: Ninh Thị Tuệ Minh | F94: Lê Hoàng Anh
A95: Kế toán Quỹ | B95: Trưởng phòng Kế toán Quỹ | F95: Quyền Giám đốc nghiệp vụ hỗ trợ đầu tư

Sheet BCTinhHinhTaiChinh_06105
A1: Mẫu số B02 - QM. Báo cáo tình hình tài chính Template B02 - QM. Statement of Financial Position
A2: (Ban hành kèm theo Thông tư 198/2012/TT-BTC ngày 15 tháng 11 năm 2012 về chế độ kế toán áp dụng đối với quỹ mở) (Issued in association with Circular 198/2012/TT-BTC dated 15 Nov 2012 on the Accounting Policies for Open-Ended Fund)
A3: BÁO CÁO TÌNH HÌNH TÀI CHÍNH STATEMENT OF FINANCIAL POSITION
A5: =TONGQUAN!C1 -> Tại ngày 31 tháng 12 năm 2024 / As at 31 Dec 2024
A7: Tên Công ty quản lý quỹ: | C7: =TONGQUAN!D5 -> Công ty Cổ phần Quản lý Quỹ Đầu tư Dragon Capital Việt Nam
A8: Fund Management Company: | C8: =TONGQUAN!D6 -> Dragon Capital Vietfund Management Joint Stock Company
A9: Tên ngân hàng giám sát: | C9: =TONGQUAN!D7 -> Ngân hàng TNHH Một thành viên Standard Chartered (Việt Nam)
A10: Supervising bank: | C10: =TONGQUAN!D8 -> Standard Chartered Bank (Vietnam) Limited
A11: Tên Quỹ: | C11: =TONGQUAN!D9 -> Quỹ Đầu tư Trái phiếu DC
A12: Fund name: | C12: =TONGQUAN!D10 -> DC Bond Fund (DCBF)
A13: Ngày lập báo cáo: | C13: =TONGQUAN!D11 -> Ngày 07 tháng 01 năm 2025
A14: Reporting Date: | C14: =TONGQUAN!D12 -> 07 Jan 2025
A16: STT No. | B16: Chỉ tiêu Indicator | C16: Mã số Code | D16: Thuyết minh Note | E16: =BCTaiSan_06027!D18 -> Ngày 31 tháng 12 năm 2024 As at 31 Dec 2024 | F16: =BCTaiSan_06027!E18 -> Ngày 30 tháng 09 năm 2024 As at 30 Sep 2024
A17: I | B17: I. TÀI SẢN ASSETS | C17: I
A18: 1 | B18: 1.Tiền gửi ngân hàng và tương đương tiền Cash at bank and cash equivalent | C18: 110 | E18: 260940922040 | F18: 156172164816
A19: 1.1 | B19: 1.1. Tiền gửi ngân hàng Cash at bank | C19: 111 | E19: 12140922040 | F19: 10372164816
B20: Tiền gửi của nhà đầu tư cho hoạt động mua chứng chỉ quỹ Cash at bank for Fund's subscription | C20: 111.1 | E20: 9923142711 | F20: 9525444010
B21: Tiền phải trả cho Nhà đầu tư về cổ tức và mua lại chứng chỉ quỹ Cash at bank for Fund's dividend payment and redemption | C21: 111.2 | E21: 4391073 | F21: 4391073
B22: Tiền gửi ngân hàng cho hoạt động của Quỹ Cash at bank for Fund's operation | C22: 111.3 | E22: 2213388256 | F22: 842329733
B23: Tiền gửi ký quỹ cho hoạt động đầu tư chứng khoán phái sinh Margin account for trading derivatives | C23: 111.4 | E23: 0 | F23: 0
A24: 1.2 | B24: 1.2. Tiền gửi có kỳ hạn không quá ba (03) tháng Deposit with term up to three (03) months | C24: 112 | E24: 248800000000 | F24: 145800000000
A25: 2 | B25: 2. Các khoản đầu tư thuần Net Investments | C25: 120 | E25: 1383107257612 | F25: 1360106253896
A26: 2.1 | B26: 2.1. Các khoản đầu tư Investments | C26: 121 | E26: 1383107257612 | F26: 1360106253896
B27: Cổ phiếu, chứng chỉ quỹ niêm yết Listed Shares, fund certificates | C27: 121.1 | E27: 0 | F27: 0
B28: Cổ phiếu, chứng chỉ quỹ chưa niêm yết Unlisted Shares, fund certifictes | C28: 121.2 | E28: 0 | F28: 0
B29: Trái phiếu niêm yết Listed Bonds | C29: 121.3 | E29: 803804814079 | F29: 796657988636
B30: Trái phiếu chưa niêm yết Unlisted Bonds | C30: 121.4 | E30: 153079537930 | F30: 142348265260
B31: Công cụ thị trường tiền tệ Money market instruments | C31: 121.5 | E31: 265122905603 | F31: 265000000000
B32: Hợp đồng tiền gửi có kỳ hạn trên ba (03) tháng Deposits with term over three (03) months | C32: 121.6 | E32: 161100000000 | F32: 156100000000
B33: Quyền mua chứng khoán Investment - Rights | C33: 121.7 | E33: 0 | F33: 0
B34: Hợp đồng tương lai chỉ số Index future contracts | C34: 121.8 | E34: 0 | F34: 0
B35: Đầu tư khác Other Investments | C35: 121.9 | E35: 0 | F35: 0
B36: Hợp đồng mua lại đảo ngược Reverse repo contracts | C36: 121.10 | E36: 0 | F36: 0
A37: 2.2 | B37: 2.2. Dự phòng giảm giá tài sản nhận thế chấp Impairment of devaluation of pledged assets | C37: 122 | E37: 0 | F37: 0
A38: 3 | B38: 3. Các khoản phải thu Receivables | C38: 130 | E38: 43732476255 | F38: 22327657480
A39: 3.1 | B39: 3.1 Phải thu về bán các khoản đầu tư Receivables from investments sold but not yet settled | C39: 131 | E39: 0 | F39: 0
B40: Trong đó: Phải thu khó đòi về bán các khoản đầu tư In which: Overdue receivables from selling investments | C40: 132 | E40: 0 | F40: 0
A41: 3.2 | B41: 3.2. Phải thu và dự thu cổ tức, tiền lãi các khoản đầu tư Dividend and interest receivables | C41: 133 | E41: 43732476255 | F41: 22291073922
A42: 3.2.1 | B42: 3.2.1. Phải thu cổ tức, tiền lãi đến ngày nhận Dividend and interest receivables on or after payment date | C42: 134 | E42: 0 | F42: 0
B43: Phải thu cổ tức Dividend receivables | C43: 134.1 | E43: 0 | F43: 0
...

Sheet BCLCGT_06262
A1: Mẫu số B05 - QM. Báo cáo lưu chuyển tiền tệ Template B05 - QM. Cash flow statement
A2: (Ban hành kèm theo Thông tư 198/2012/TT-BTC ngày 15 tháng 11 năm 2012 về chế độ kế toán áp dụng đối với quỹ mở) (Issued in association with Circular 198/2012/TT-BTC dated 15 Nov 2012 on the Accounting Policies for Open-Ended Fund)
A3: BÁO CÁO LƯU CHUYỂN TIỀN TỆ CASH FLOW STATEMENT
A4: =TONGQUAN!C2 -> Quý IV năm 2024 / Quarter IV 2024
A7: Tên Công ty quản lý quỹ: | B7: =TONGQUAN!D5 -> Công ty Cổ phần Quản lý Quỹ Đầu tư Dragon Capital Việt Nam
A8: Fund Management Company: | B8: =TONGQUAN!D6 -> Dragon Capital Vietfund Management Joint Stock Company
A9: Tên ngân hàng giám sát: | B9: =TONGQUAN!D7 -> Ngân hàng TNHH Một thành viên Standard Chartered (Việt Nam)
A10: Supervising bank: | B10: =TONGQUAN!D8 -> Standard Chartered Bank (Vietnam) Limited
A11: Tên Quỹ: | B11: =TONGQUAN!D9 -> Quỹ Đầu tư Trái phiếu DC
A12: Fund name: | B12: =TONGQUAN!D10 -> DC Bond Fund (DCBF)
A13: Ngày lập báo cáo: | B13: =TONGQUAN!D11 -> Ngày 07 tháng 01 năm 2025
A14: Reporting Date: | B14: =TONGQUAN!D12 -> 07 Jan 2025
A17: Chỉ tiêu Indicator | B17: Mã số Code | C17: Thuyết minh Note | D17: =BCKetQuaHoatDong_06028!D18 -> Quý IV năm 2024 Quarter IV 2024 | E17: =BCKetQuaHoatDong_06028!E18 -> Quý III năm 2024 Quarter III 2024
A18: I. Lưu chuyển tiền từ hoạt động đầu tư Cash flow from investing activities | B18: I
A19: 1. Lợi nhuận trước Thuế thu nhập doanh nghiệp Profit before income tax | B19: 01 | D19: 27675101189 | E19: 21294940715
A20: 2. Điều chỉnh cho các khoản tăng giá trị tài sản ròng từ các hoạt động đầu tư Adjustment for NAV increase from investing activities | B20: 02 | D20: 361301919 | E20: 2103653951
A21: (- Lãi) hoặc (+ lỗ) chênh lệch tỷ giá hối đoái/ đánh giá lại các khoản đầu tư chưa thực hiện Unreliased (Gain) or Loss from FX valuation/Investment revaluation | B21: 03 | D21: 310333369 | E21: 2121255402
A22: (+) Chi phí trích trước Increase of Accrued Expenses | B22: 04 | D22: 50968550 | E22: -17601451
A23: 3. Lợi nhuận từ hoạt động đầu tư trước thay đổi vốn lưu động Profit from investing activities before changes in working capital | B23: 05 | D23: 28036403108 | E23: 23398594666
A24: (-) Tăng, (+) giảm đầu tư (Increase), Decrease Investments | B24: 20 | D24: -23311337085 | E24: -394164813916
A25: (-) Tăng, (+) giảm phải thu bán chứng khoán đầu tư (Increase), Decrease in Receivables from investments sold but not yet settled | B25: 06 | D25: 0 | E25: 0
A26: (-) Tăng, (+) giảm dự thu phải thu tiền lãi các khoản đầu tư (Increase), Decrease in Dividend and interest receivables | B26: 07 | D26: -21441402333 | E26: 998881763
A27: (-) Tăng, (+) giảm các khoản phải thu khác (Increase), Decrease in other receivables | B27: 08 | D27: 36583558 | E27: 10933561
A28: (+) Tăng, (-) giảm vay ngắn hạn Increase, (Decrease) in Short-term Loans | B28: 09 | D28: 0 | E28: 0
A29: (+) Tăng, (-) giảm phải trả cho người bán (Decrease), Increase in payables for securities purchased but not yet settled | B29: 10 | D29: 0 | E29: 0
A30: (+) Tăng, (-) giảm phải trả các Đại lý phân phối Chứng chỉ quỹ, Công ty Quản lý Quỹ (Decrease)/increase in subscription and redemption fee payable to distributors and Fund Management Company | B30: 11 | D30: 108447066 | E30: 16555281
... A38: Lưu chuyển tiền thuần từ hoạt động đầu tư (1+2+3) Net Cash flow from Investing activities | B38: 19 | D38: -30555011596 | E38: -327012635669
A39: II. Lưu chuyển tiền từ hoạt động tài chính Cash flow from financing activities | B39: II
A40: 1. Tiền thu từ phát hành Chứng chỉ quỹ mở Receipts from subscriptions | B40: 31 | D40: 512421664397 | E40: 426233716431
A41: 2. Tiền chi mua lại Chứng chỉ quỹ mở Payments for redemptions | B41: 32 | D41: -377097895577 | E41: -306711809447
A42: 3. Tiền vay gốc Principal of borrowings | B42: 33 | D42: 0 | E42: 0
A43: 4. Tiền chi trả nợ gốc vay Payment of Principal borrowings | B43: 34 | D43: 0 | E43: 0
A44: 5. Tiền chi trả cổ tức, tiền lãi cho nhà đầu tư Dividend, profit distribution paid to investors | B44: 35 | D44: 0 | E44: 0
A45: Lưu chuyển tiền thuần từ hoạt động tài chính (1-2+3-4-5) Net cash outflows from financing activities | B45: 30 | D45: 135323768820 | E45: 119521906984
A46: III. Tăng/giảm tiền thuần trong kỳ Net Increase/Decrease in cash and cash equivalent for the period | B46: 40 | D46: 104768757224 | E46: -207490728685
A47: IV. Tiền và các khoản tương đương tiền đầu kỳ Cash and cash equivalents at the beginning of period | B47: 50 | D47: 156172164816 | E47: 363662893501
A48: Tiền gửi ngân hàng đầu kỳ: Cash at bank of the beginning of period: | B48: 51 | D48: 156172164816 | E48: 363662893501
A49: -Tiền gửi ngân hàng và tương đương tiền cho hoạt động của Quỹ Cash at bank and cash equivalent for Fund's operation | B49: 52 | D49: 146642329733 | E49: 360560914263
A50: Tiền gửi không kỳ hạn Demand deposit | B50: 52.1 | D50: 842329733 | E50: 460914263
A51: Tiền gửi có kỳ hạn không quá ba (03) tháng Deposit with term up to three (03) months | B51: 52.2 | D51: 145800000000 | E51: 360100000000
...

Sheet LogoFMS
D1: VFMVFB
A2: FUNDCODE | B2: FUNDNAME | C2: LOGO
A3: VFMVSF | B3: Quỹ Đầu Tư Cổ Phiếu Việt Nam Chọn Lọc
A4: VFMVF1 | B4: Quỹ Đầu tư Chứng khoán Năng động DC
A5: VFMVF4 | B5: Quỹ Đầu tư Doanh nghiệp Hàng đầu DC
A6: VFMVFA | B6: Quỹ Đầu tư Năng Động Việt Nam
A7: VFMVFB | B7: Quỹ Đầu tư Trái phiếu DC
A8: VFMVFC | B8: Quỹ Đầu tư Trái phiếu Gia tăng Thu nhập Cố định DC
A9: TCEF1 | B9: Quỹ Đầu tư Cổ phiếu Techcom
A10: TCBF | B10: Quỹ Đầu tư Cổ phiếu Techcom
A11: MBEF1 | B11: Quỹ Đầu tư JAPAN ASIA MB CAPITAL
A12: MBVF | B12: Quỹ Đầu tư Giá trị MB Capital
A13: SSISCA | B13: Quỹ Đầu tư Lợi thế Cạnh tranh Bền vững SSI
A14: VCBBCF | B14: Quỹ Đầu tư Cổ Phiếu Hàng Đầu VCBF
... A52: VCBMGF | B52: Quỹ Đầu Tư Cổ phiếu Tăng trưởng VCBF
A53: AM33
A54: AM34
A55: AM35
A56: AM36 | B56: Tổng công ty cổ phần bảo hiểm Petrolimex - PJICO EQUITY PORTFOLIO 04
A57: AM37
A58: AM38
A59: AM39
A60: AM40
A61: AM41
A62: AM42
A63: AM43
A64: AM44
A65: AM45
A66: AM46
A67: AM47
A68: AM48
... A70: AM50
A71: VMPF | B71: Quỹ Đầu Tư Cổ Phiếu Hiệu Suất Thị Trường Việt Nam VinaCapital (VinaCapital-VMPF)
A72: ENF
A73: EVESG
A74: UVDIF
A75: VDEF
A76: VCBAIF
