Workbook
Name addlogo: INDEX(#REF!,MATCH(#REF!,#REF!,0))

Sheet TONGQUAN
A1: Kỳ báo cáo: | C1: Tại ngày 31 tháng 03 năm 2021 / As at 31 Mar 2021
C2: Quý I năm 2021 / Quarter I 2021
A4: Thông tin chung:
C5: Tên Công ty quản lý quỹ: | D5: Công ty Cổ phần Quản lý Quỹ Đầu tư Dragon Capital Việt Nam
C6: Fund Management Company: | D6: Dragon Capital Vietfund Management Joint Stock Company
C7: Tên ngân hàng giám sát: | D7: Ngân hàng TNHH Một thành viên Standard Chartered (Việt Nam)
C8: Supervising bank: | D8: Standard Chartered Bank (Vietnam) Limited
C9: Tên Quỹ: | D9: Quỹ Đầu tư Chứng khoán Việt Nam
C10: Fund name: | D10: Vietnam Securities Investment Fund(VFMVF1)
C11: Ngày lập báo cáo: | D11: Ngày 06 tháng 04 năm 2021
C12: Reporting Date: | D12: 06 Apr 2021
A14: Người ký báo cáo:
C16: Đại diện có thẩm quyền của Ngân hàng giám sát | F16: Đại diện có thẩm quyền của Công ty quản lý Quỹ
C17: Authorised Representative of Supervisory Bank | F17: Authorised Representative of Fund Management Company
C19: Ngân hàng TNHH MTV Standard Chartered (Việt Nam) | F19: Công ty Cổ phần Quản lý Quỹ Đầu tư Dragon Capital Việt Nam
C20: Vũ Hương Giang | F20: Nguyễn Minh Đăng Khánh
C21: Trưởng phòng Dịch vụ Quản trị và Giám sát Quỹ | F21: Giám đốc điều hành Nghiệp vụ hỗ trợ đầu tư
B34: STT | C34: Nội dung | D34: Tên sheet
B35: A | C35: BÁO CÁO CHUNG VỀ HOẠT ĐỘNG ĐẦU TƯ CỦA QUỸ
B36: A.I | C36: Báo cáo về tài sản | D36: 06027
B37: A.II | C37: Báo cáo kết quả hoạt động | D37: 06028
B38: A.III | C38: Báo cáo danh mục đầu tư | D38: 06029
B39: A.IV | C39: Báo cáo hoạt động vay, giao dịch mua bán lại | D39: 06026
B40: A.V | C40: Một số chỉ tiêu khác | D40: 06030
B41: A.VI | C41: Thống kê phí giao dịch | D41: 06031
B42: 5 | C42: Báo cáo thay đổi giá trị tài sản ròng, giao dịch chứng chỉ quỹ | D42: 06129
B43: 6 | C43: Báo cáo thu nhập giữa niên độ | D43: 06203
B44: 7 | C44: Báo cáo tình hình tài chính giữa niên độ | D44: 06105
B45: 8 | C45: Báo cáo thay đổi giá trị tài sản ròng, giao dịch chứng chỉ quỹ giữa niên độ | D45: 06107
B46: 9 | C46: Báo cáo danh mục đầu tư | D46: 06108
B47: 10 | C47: Báo cáo lưu chuyển tiền tệ | D47: 06262
B48: 11 | C48: Báo cáo thu nhập | D48: 06104
B49: 12 | C49: Báo cáo về tài sản của quỹ | D49: 06126
B50: A.VII | C50: Thống kê giao dịch của Quỹ đầu tư bất động sản với người có liên quan | D50: không có
B51: A.VIII | C51: Thống kê giao dịch bất động sản của Quỹ đầu tư bất động sản | D51: không có
B52: B | C52: BÁO CÁO TÌNH HÌNH TỰ DOANH ĐẦU TƯ GIÁN TIẾP RA NƯỚC NGOÀI CỦA QUỸ | D52: Không có

Sheet BCthunhap
A1: Mẫu số B01g - QM. Báo cáo thu nhập Template B01g - QM. Statement of Comprehensive Income
A2: (Ban hành kèm theo Thông tư 198/2012/TT-BTC ngày 15 tháng 11 năm 2012 về chế độ kế toán áp dụng đối với quỹ mở) (Issued in association with Circular 198/2012/TT-BTC dated 15 Nov 2012 on the Accounting Policies for Open-Ended Fund)
A3: BÁO CÁO THU NHẬP STATEMENT OF COMPREHENSIVE INCOME
A5: Quý I năm 2021 / Quarter I 2021
A7: Tên Công ty quản lý quỹ: | D7: Công ty Cổ phần Quản lý Quỹ Đầu tư Dragon Capital Việt Nam
A8: Fund Management Company: | D8: Dragon Capital Vietfund Management Joint Stock Company
A9: Tên ngân hàng giám sát: | D9: Ngân hàng TNHH Một thành viên Standard Chartered (Việt Nam)
A10: Supervising bank: | D10: Standard Chartered Bank (Vietnam) Limited
A11: Tên Quỹ: | D11: Quỹ Đầu tư Chứng khoán Việt Nam
A12: Fund name: | D12: Vietnam Securities Investment Fund(VFMVF1)
A13: Ngày lập báo cáo: | D13: Ngày 06 tháng 04 năm 2021
A14: Reporting Date: | D14: 06 Apr 2021
A16: Chỉ tiêu Indicator | B16: Mã số Code | C16: Thuyết minh Note | D16: Năm 2021 Year 2021 | F16: Năm 2020 Year 2020
D17: Quý I năm 2021 Quarter I 2021 | E17: Số lũy kế Year-to-date | F17: Quý I năm 2020 Quarter I 2020 | G17: Số lũy kế Year-to-date
A18: I. THU NHẬP, DOANH THU HOẠT ĐỘNG ĐẦU TƯ Investment income | B18: 01 | D18: 54506351329 | E18: 54506351329 | F18: -213949429922 | G18: -213949429922
A19: 1.1. Cổ tức được chia Dividend income | B19: 02 | D19: 537421400 | E19: 537421400 | F19: 224360000 | G19: 224360000
A20: 1.2. Tiền lãi được nhận Interest income | B20: 03 | D20: 1168478112 | E20: 1168478112 | F20: 3179346128 | G20: 3179346128
A21: Lãi tiền gửi ngân hàng Interest income from bank deposits | B21: 03.1 | D21: 15943864 | E21: 15943864 | F21: 122743388 | G21: 122743388
A22: Lãi chứng chỉ tiền gửi Interest income from Certificates of Deposit | B22: 03.2 | D22: 1067054795 | E22: 1067054795 | F22: 1458493151 | G22: 1458493151
A23: Lãi trái phiếu Interest income from bonds | B23: 03.3 | D23: 85479453 | E23: 85479453 | F23: 1598109589 | G23: 1598109589
A24: Tiền lãi hợp đồng mua lại đảo ngược được nhận Reverse repo contract interest received | B24: 03.4 | D24: 0 | E24: 0 | F24: 0 | G24: 0
A25: 1.3. Lãi (lỗ) bán các khoản đầu tư Realized gain (losses) from disposal investments | B25: 04 | D25: 12680230736 | E25: 12680230736 | F25: 7643535882 | G25: 7643535882
A26: 1.4. Chênh lệch tăng, giảm đánh giá lại các khoản đầu tư chưa thực hiện Unrealized gain (losses) from investment revaluation | B26: 05 | D26: 40120221081 | E26: 40120221081 | F26: -224996671932 | G26: -224996671932
A27: 1.5. Doanh thu khác Other income | B27: 06 | D27: 0 | E27: 0 | F27: 0 | G27: 0
A28: 1.6. Chênh lệch lãi, lỗ tỷ giá hối đoái đã và chưa thực hiện Realized and unrealized gain (losses) from foreign exchange | B28: 07 | D28: 0 | E28: 0 | F28: 0 | G28: 0
A29: 1.7. Doanh thu khác về đầu tư Other investment income | B29: 08 | D29: 0 | E29: 0 | F29: 0 | G29: 0
... A77: VIII. LỢI NHUẬN KẾ TOÁN SAU THUẾ TNDN PROFIT AFTER TAX (41=30-40) | B77: 41 | D77: 51099476926 | E77: 51099476926 | F77: -218624918757 | G77: -218624918757
A80: Người lập: | B80: Người duyệt:
A93: _______________________________________________ | B93: ___________________________________________ | F93: _____________________________
A94: Mai Thùy Sâm | B94: Phạm Thanh Dũng | F94: Nguyễn Minh Đăng Khánh
A95: Kế toán Quỹ | B95: Kế toán Trưởng | F95: Giám đốc điều hành Nghiệp vụ hỗ trợ đầu tư

Sheet BCtinhhinhtaichinh
A1: Mẫu số B02g - QM. Báo cáo tình hình tài chính Template B02g - QM. Statement of Financial Position
A2: (Ban hành kèm theo Thông tư 198/2012/TT-BTC ngày 15 tháng 11 năm 2012 về chế độ kế toán áp dụng đối với quỹ mở) (Issued in association with Circular 198/2012/TT-BTC dated 15 Nov 2012 on the Accounting Policies for Open-Ended Fund)
A3: BÁO CÁO TÌNH HÌNH TÀI CHÍNH STATEMENT OF FINANCIAL POSITION
A5: Tại ngày 31 tháng 03 năm 2021 / As at 31 Mar 2021
A7: Tên Công ty quản lý quỹ: | C7: Công ty Cổ phần Quản lý Quỹ Đầu tư Dragon Capital Việt Nam
A8: Fund Management Company: | C8: Dragon Capital Vietfund Management Joint Stock Company
A9: Tên ngân hàng giám sát: | C9: Ngân hàng TNHH Một thành viên Standard Chartered (Việt Nam)
A10: Supervising bank: | C10: Standard Chartered Bank (Vietnam) Limited
A11: Tên Quỹ: | C11: Quỹ Đầu tư Chứng khoán Việt Nam
A12: Fund name: | C12: Vietnam Securities Investment Fund(VFMVF1)
A13: Ngày lập báo cáo: | C13: Ngày 06 tháng 04 năm 2021
A14: Reporting Date: | C14: 06 Apr 2021
A16: STT No. | B16: Chỉ tiêu Indicator | C16: Mã số Code | D16: Thuyết minh Note | E16: Ngày 31 tháng 03 năm 2021 As at 31 Mar 2021 | F16: Ngày 31 tháng 12 năm 2020 As at 31 Dec 2020
A17: I | B17: I. TÀI SẢN ASSETS | C17: I
A18: 1 | B18: 1.Tiền gửi ngân hàng và tương đương tiền Cash at bank and cash equivalent | C18: 110 | E18: 13601078113 | F18: 46497927740
A19: 1.1 | B19: 1.1. Tiền gửi ngân hàng Cash at bank | C19: 111 | E19: 13601078113 | F19: 46497927740
B20: Tiền gửi của nhà đầu tư cho hoạt động mua chứng chỉ quỹ Cash at bank for Fund's subscription | C20: 111.1 | E20: 0 | F20: 0
B21: Tiền phải trả cho Nhà đầu tư về mua lại Chứng chỉ quỹ Cash at bank for Fund's redemption | C21: 111.2 | E21: 125123389 | F21: 226700815
B22: Tiền gửi ngân hàng cho hoạt động của Quỹ Cash at bank for Fund's operation | C22: 111.3 | E22: 13475839515 | F22: 41972659771
B23: Tiền gửi ký quỹ cho hoạt động đầu tư chứng khoán phái sinh Margin account for trading derivatives | C23: 111.4 | E23: 115209 | F23: 4298567154
A24: 1.2 | B24: 1.2. Tiền gửi có kỳ hạn dưới ba (03) tháng Deposit with term less than three (03) months | C24: 112 | E24: 0 | F24: 0
A25: 2 | B25: 2. Các khoản đầu tư thuần Net Investments | C25: 120 | E25: 607539056450 | F25: 493298290900
A26: 2.1 | B26: 2.1. Các khoản đầu tư Investments | C26: 121 | E26: 607539056450 | F26: 493298290900
B27: Cổ phiếu niêm yết Listed Shares | C27: 121.1 | E27: 542545631850 | F27: 448298290900
B28: Cổ phiếu chưa niêm yết Unlisted Shares | C28: 121.2 | E28: 0 | F28: 0
B29: Trái phiếu niêm yết Listed Bonds | C29: 121.3 | E29: 0 | F29: 0
B30: Trái phiếu chưa niêm yết Unlisted Bonds | C30: 121.4 | E30: 19993424600 | F30: 0
B31: Chứng chỉ tiền gửi Certificates of Deposit | C31: 121.5 | E31: 45000000000 | F31: 45000000000
B32: Hợp đồng tiền gửi có kỳ hạn trên ba (03) tháng Deposits with term over three (03) months | C32: 121.6 | E32: 0 | F32: 0
B33: Quyền mua chứng khoán Investment - Rights | C33: 121.7 | E33: 0 | F33: 0
B34: Hợp đồng tương lai chỉ số Index future contracts | C34: 121.8 | E34: 0 | F34: 0
B35: Đầu tư khác Other Investments | C35: 121.9 | E35: 0 | F35: 0
B36: Hợp đồng mua lại đảo ngược Reverse repo contracts | C36: 121.10 | E36: 0 | F36: 0
A37: 2.2 | B37: 2.2. Dự phòng giảm giá tài sản nhận thế chấp Impairment of devaluation of pledged assets | C37: 122 | E37: 0 | F37: 0
A38: 3 | B38: 3. Các khoản phải thu Receivables | C38: 130 | E38: 1360117932 | F38: 2234411093
A39: 3.1 | B39: 3.1 Phải thu về bán các khoản đầu tư Receivables from investments sold but not yet settled | C39: 131 | E39: 5286600 | F39: 154710
B40: Trong đó: Phải thu khó đòi về bán các khoản đầu tư In which: Overdue receivables from selling investments | C40: 132 | E40: 0 | F40: 0
A41: 3.2 | B41: 3.2. Phải thu và dự thu cổ tức, tiền lãi các khoản đầu tư Dividend and interest receivables | C41: 133 | E41: 2221231332 | F41: 3100656383
A42: 3.2.1 | B42: 3.2.1. Phải thu cổ tức, tiền lãi đến ngày nhận Dividend and interest receivables on or after payment date | C42: 134 | E42: 866400000 | F42: 866400000
B43: Phải thu cổ tức Dividend receivables | C43: 134.1 | E43: 866400000 | F43: 866400000
...

Sheet BCLCGT_06262
A1: Mẫu số B05g - QM. Báo cáo lưu chuyển tiền tệ Template B05g - QM. Cash flow statement
A2: (Ban hành kèm theo Thông tư 198/2012/TT-BTC ngày 15 tháng 11 năm 2012 về chế độ kế toán áp dụng đối với quỹ mở) (Issued in association with Circular 198/2012/TT-BTC dated 15 Nov 2012 on the Accounting Policies for Open-Ended Fund)
A3: BÁO CÁO LƯU CHUYỂN TIỀN TỆ CASH FLOW STATEMENT
A4: =TONGQUAN!C2 -> Quý I năm 2021 / Quarter I 2021
A7: Tên Công ty quản lý quỹ: | B7: =TONGQUAN!D5 -> Công ty Cổ phần Quản lý Quỹ Đầu tư Dragon Capital Việt Nam
A8: Fund Management Company: | B8: =TONGQUAN!D6 -> Dragon Capital Vietfund Management Joint Stock Company
A9: Tên ngân hàng giám sát: | B9: =TONGQUAN!D7 -> Ngân hàng TNHH Một thành viên Standard Chartered (Việt Nam)
A10: Supervising bank: | B10: =TONGQUAN!D8 -> Standard Chartered Bank (Vietnam) Limited
A11: Tên Quỹ: | B11: =TONGQUAN!D9 -> Quỹ Đầu tư Chứng khoán Việt Nam
A12: Fund name: | B12: =TONGQUAN!D10 -> Vietnam Securities Investment Fund(VFMVF1)
A13: Ngày lập báo cáo: | B13: =TONGQUAN!D11 -> Ngày 06 tháng 04 năm 2021
A14: Reporting Date: | B14: =TONGQUAN!D12 -> 06 Apr 2021
A17: Chỉ tiêu Indicator | B17: Mã số Code | C17: Thuyết minh Note | D17: =BCKetQuaHoatDong_06028!D18 -> Quý I năm 2021 Quarter I 2021 | E17: =BCKetQuaHoatDong_06028!E18 -> Quý IV năm 2020 Quarter IV 2020
A18: I. Lưu chuyển tiền từ hoạt động đầu tư Cash flow from investing activities | B18: I
A19: 1. Lợi nhuận trước Thuế thu nhập doanh nghiệp Profit before income tax | B19: 01 | D19: 51099476926 | E19: 105496617758
A20: 2. Điều chỉnh cho các khoản tăng giá trị tài sản ròng từ các hoạt động đầu tư Adjustment for NAV increase from investing activities | B20: 02 | D20: -40145417656 | E20: -91650711613
A21: (- Lãi) hoặc (+ lỗ) chênh lệch tỷ giá hối đoái/ đánh giá lại các khoản đầu tư chưa thực hiện Unreliased (Gain) or Loss from FX valuation/Investment revaluation | B21: 03 | D21: -40120221081 | E21: -91783584564
A22: (+) Chi phí trích trước Increase of Accrued Expenses | B22: 04 | D22: -25196575 | E22: 132872951
A23: 3. Lợi nhuận từ hoạt động đầu tư trước thay đổi vốn lưu động Profit from investing activities before changes in working capital | B23: 05 | D23: 10954059270 | E23: 13845906145
A24: (-) Tăng, (+) giảm đầu tư (Increase), Decrease Investments | B24: 20 | D24: -74120544469 | E24: 13091328814
A25: (-) Tăng, (+) giảm phải thu bán chứng khoán đầu tư (Increase), Decrease in Receivables from investments sold but not yet settled | B25: 06 | D25: -5131890 | E25: -154710
A26: (-) Tăng, (+) giảm dự thu phải thu tiền lãi các khoản đầu tư (Increase), Decrease in Dividend and interest receivables | B26: 07 | D26: 879425051 | E26: 1076265850
A27: (-) Tăng, (+) giảm các khoản phải thu khác (Increase), Decrease in other receivables | B27: 08 | D27: 0 | E27: 0
A28: (+) Tăng, (-) giảm vay ngắn hạn Increase, (Decrease) in Short-term Loans | B28: 09 | D28: 0 | E28: 0
A29: (+) Tăng, (-) giảm phải trả cho người bán (Decrease), Increase in payables for securities purchased but not yet settled | B29: 10 | D29: 0 | E29: 0
A30: (+) Tăng, (-) giảm phải trả các Đại lý phân phối Chứng chỉ quỹ, Công ty Quản lý Quỹ (Decrease)/increase in subscription and redemption fee payable to distributors and Fund Management Company | B30: 11 | D30: 90452463 | E30: 25401432
... A38: Lưu chuyển tiền thuần từ hoạt động đầu tư (1+2+3) Net Cash flow from Investing activities | B38: 19 | D38: -62537032952 | E38: 30381356521
A39: II. Lưu chuyển tiền từ hoạt động tài chính Cash flow from financing activities | B39: II
A40: 1. Tiền thu từ phát hành Chứng chỉ quỹ mở Receipts from subscriptions | B40: 31 | D40: 80184192529 | E40: 34023099739
A41: 2. Tiền chi mua lại Chứng chỉ quỹ mở Payments for redemptions | B41: 32 | D41: -50544009204 | E41: -23948774545
A42: 3. Tiền vay gốc Principal of borrowings | B42: 33 | D42: 0 | E42: 0
A43: 4. Tiền chi trả nợ gốc vay Payment of Principal borrowings | B43: 34 | D43: 0 | E43: 0
A44: 5. Tiền chi trả cổ tức, tiền lãi cho nhà đầu tư Dividend, profit distribution paid to investors | B44: 35 | D44: 0 | E44: 0
A45: Lưu chuyển tiền thuần từ hoạt động tài chính (1-2+3-4-5) Net cash outflows from financing activities | B45: 30 | D45: 29640183325 | E45: 10074325194
A46: III. Tăng/giảm tiền thuần trong kỳ Net Increase/Decrease in cash and cash equivalent for the period | B46: 40 | D46: -32896849627 | E46: 40455681715
A47: IV. Tiền và các khoản tương đương tiền đầu kỳ Cash and cash equivalents at the beginning of period | B47: 50 | D47: 46497927740 | E47: 6042246025
A48: Tiền gửi ngân hàng đầu kỳ: Cash at bank of the beginning of period: | B48: 51 | D48: 46497927740 | E48: 6042246025
A49: -Tiền gửi ngân hàng và tương đương tiền cho hoạt động của Quỹ Cash at bank and cash equivalent for Fund's operation | B49: 52 | D49: 46271226925 | E49: 5913952195
A50: Tiền gửi không kỳ hạn Demand deposit | B50: 52.1 | D50: 41972659771 | E50: 5913837097
A51: Tiền gửi có kỳ hạn dưới ba (03) tháng Deposits with term under three (03) months | B51: 52.2 | D51: 0 | E51: 0
...

Sheet BCTaiSan_06027
A1: Phụ lục XXVI. Mẫu báo cáo về hoạt động của Quỹ Appendix XXVI. Report on Fund's Operation
A2: (Ban hành kèm theo Thông tư số 98/2020/TT-BTC ngày 16 tháng 11 năm 2020 của Bộ trưởng Bộ Tài Chính về hướng dẫn hoạt động và quản lý quỹ đầu tư chứng khoán) (Issued in association with Circular 98/2020/TT-BTC dated 16 November 2020 of the Minister of Finance on guiding the operation and management of the securities investment funds)
A3: BÁO CÁO VỀ HOẠT ĐỘNG ĐẦU TƯ REPORT ON INVESTMENT ACTIVITIES
A5: Tại ngày 31 tháng 03 năm 2021 / As at 31 Mar 2021
A7: Tên Công ty quản lý quỹ: | C7: Công ty Cổ phần Quản lý Quỹ Đầu tư Dragon Capital Việt Nam
A8: Fund Management Company: | C8: Dragon Capital Vietfund Management Joint Stock Company
A9: Tên ngân hàng giám sát: | C9: Ngân hàng TNHH Một thành viên Standard Chartered (Việt Nam)
A10: Supervising bank: | C10: Standard Chartered Bank (Vietnam) Limited
A11: Tên Quỹ: | C11: Quỹ Đầu tư Chứng khoán Việt Nam
A12: Fund name: | C12: Vietnam Securities Investment Fund(VFMVF1)
A13: Ngày lập báo cáo: | C13: Ngày 06 tháng 04 năm 2021
A14: Reporting Date: | C14: 06 Apr 2021
A16: A. | B16: BÁO CÁO CHUNG VỀ HOẠT ĐỘNG ĐẦU TƯ CỦA QUỸ/GENERAL INFORMATION ON FUND'S INVESTMENT ACTIVITIES
A17: I | B17: BÁO CÁO VỀ TÀI SẢN / ASSET REPORT
A18: STT No | B18: Nội dung Indicator | C18: Mã chỉ tiêu Code | D18: Ngày 31 tháng 03 năm 2021 As at 31 Mar 2021 | E18: Ngày 31 tháng 12 năm 2020 As at 31 Dec 2020 | F18: %/cùng kỳ năm trước %/against last year
A19: I | B19: TÀI SẢN ASSETS
A20: I.1 | B20: Tiền và các khoản tương đương tiền Cash and Cash Equivalents | D20: 13601078113 | E20: 46497927740 | F20: 0.27671132
B21: Tiền gửi ngân hàng Cash at bank | D21: 13601078113 | E21: 46497927740 | F21: 0.27671132
B22: Tiền gửi của nhà đầu tư cho hoạt động mua chứng chỉ quỹ Cash at bank for Fund's subscription | D22: 0 | E22: 0 | F22: 0
B23: Tiền phải trả cho Nhà đầu tư về mua lại chứng chỉ quỹ Cash at bank for Fund's redemption | D23: 125123389 | E23: 226700815 | F23: 1.0328178
B24: Tiền gửi ngân hàng cho hoạt động của Quỹ Cash at bank for Fund's operation | D24: 13475839515 | E24: 41972659771 | F24: 1.1854925
B25: Tiền gửi ký quỹ cho hoạt động đầu tư chứng khoán phái sinh Margin account for trading derivatives | D25: 115209 | E25: 4298567154 | F25: 3.0593377e-06
B26: Tiền, tương đương tiền Cash, cash equivalents | D26: 0 | E26: 0
A27: I.2 | B27: Các khoản đầu tư (kê chi tiết) Investments | D27: 607539056450 | E27: 493298290900 | F27: 1.1950766
B28: Cổ phiếu niêm yết Listed shares | D28: 542545631850 | E28: 448298290900 | F28: 1.3972894
B29: Cổ phiếu chưa niêm yết Unlisted shares | D29: 0 | E29: 0
B30: Trái phiếu Bonds | D30: 19993424600 | E30: 0 | F30: 0.33275844
B31: Chứng chỉ tiền gửi Certificates of Deposit | D31: 45000000000 | E31: 45000000000 | F31: 0.75
B32: Hợp đồng tiền gửi có kỳ hạn trên ba (03) tháng Deposits with term over three (03) months | D32: 0 | E32: 0
B33: Quyền mua chứng khoán Investment - Rights | D33: 0 | E33: 0
B34: Hợp đồng tương lai chỉ số Index future contracts | D34: 0 | E34: 0
B35: Đầu tư khác Other investments | D35: 0 | E35: 0
B36: Hợp đồng mua lại đảo ngược Reverse repo contracts | D36: 0 | E36: 0
A37: I.3 | B37: Thu từ cho thuê bất động sản đầu tư (không áp dụng) Receivables from rental of investment property (not applicable)
A38: I.4 | B38: Cổ tức, trái tức được nhận Dividend, Coupon receivables | D38: 1074601195 | E38: 2609492000 | F38: 0.30411377
B39: Phải thu cổ tức Dividend receivables | D39: 982546400 | E39: 2609492000 | F39: 0.81098296
B40: Phải thu trái tức Coupon receivables | D40: 92054795 | E40: 0 | F40: 0.039644615
A41: I.5 | B41: Lãi được nhận Interest receivables | D41: 1146630137 | E41: 491164383 | F41: 0.97053742
B42: Phải thu lãi tiền gửi Interest receivable from bank deposits | D42: 0 | E42: 0
B43: Phải thu lãi chứng chỉ tiền gửi Interest receivable from Certificates of Deposit | D43: 1146630137 | E43: 491164383 | F43: 0.97053742
...

Sheet BCKetQuaHoatDong_06028
A1: Phụ lục XXVI. Mẫu báo cáo về hoạt động của Quỹ Appendix XXVI. Report on Fund's Operation
A2: (Ban hành kèm theo Thông tư số 98/2020/TT-BTC ngày 16 tháng 11 năm 2020 của Bộ trưởng Bộ Tài Chính về hướng dẫn hoạt động và quản lý quỹ đầu tư chứng khoán) (Issued in association with Circular 98/2020/TT-BTC dated 16 November 2020 of the Minister of Finance on guiding the operation and management of the securities investment funds)
A3: BÁO CÁO VỀ HOẠT ĐỘNG ĐẦU TƯ REPORT ON INVESTMENT ACTIVITIES
A5: Quý I năm 2021 / Quarter I 2021
A7: Tên Công ty quản lý quỹ: | C7: Công ty Cổ phần Quản lý Quỹ Đầu tư Dragon Capital Việt Nam
A8: Fund Management Company: | C8: Dragon Capital Vietfund Management Joint Stock Company
A9: Tên ngân hàng giám sát: | C9: Ngân hàng TNHH Một thành viên Standard Chartered (Việt Nam)
A10: Supervising bank: | C10: Standard Chartered Bank (Vietnam) Limited
A11: Tên Quỹ: | C11: Quỹ Đầu tư Chứng khoán Việt Nam
A12: Fund name: | C12: Vietnam Securities Investment Fund(VFMVF1)
A13: Ngày lập báo cáo: | C13: Ngày 06 tháng 04 năm 2021
A14: Reporting Date: | C14: 06 Apr 2021
A16: A. | B16: BÁO CÁO CHUNG VỀ HOẠT ĐỘNG ĐẦU TƯ CỦA QUỸ/GENERAL INFORMATION ON FUND'S INVESTMENT ACTIVITIES
A17: II | B17: BÁO CÁO KẾT QUẢ HOẠT ĐỘNG / PROFIT AND LOSS REPORT
A18: STT No | B18: Nội dung Indicator | C18: Mã chỉ tiêu Code | D18: Quý I năm 2021 Quarter I 2021 | E18: Quý IV năm 2020 Quarter IV 2020 | F18: Lũy kế từ đầu năm Accumulated from beginning of year
A19: I | B19: Thu nhập từ hoạt động đầu tư Income from Investment Activities | D19: 1705899512 | E19: 4597693474 | F19: 1705899512
A20: 1 | B20: Thu từ bất động sản cho thuê (không áp dụng) Income from rental property (not applicable)
A21: 2 | B21: Cổ tức, trái tức được nhận Dividend income, interest income from bonds | D21: 622900853 | E21: 3507772455 | F21: 622900853
B22: Cổ tức được nhận Dividends income | D22: 537421400 | E22: 3269073834 | F22: 537421400
B23: Trái tức được nhận Interest income from bonds | D23: 85479453 | E23: 238698621 | F23: 85479453
A24: 3 | B24: Lãi được nhận Interest income | D24: 1082998659 | E24: 1089921019 | F24: 1082998659
B25: Lãi tiền gửi ngân hàng Interest income from bank deposits | D25: 15943864 | E25: 6208691 | F25: 15943864
B26: Lãi chứng chỉ tiền gửi Interest income from Certificates of Deposit | D26: 1067054795 | E26: 1083712328 | F26: 1067054795
B27: Lãi hợp đồng mua lại đảo ngược Interest income from reverse repo contracts | D27: 0 | E27: 0 | F27: 0
A28: 4 | B28: Các khoản thu nhập khác Other incomes | D28: 0 | E28: 0 | F28: 0
B29: Thu nhập khác về đầu tư Other investment incomes | D29: 0 | E29: 0 | F29: 0
B30: Thu nhập khác Other incomes | D30: 0 | E30: 0 | F30: 0
B31: Chi phí dự phòng nợ phải thu khó đòi về cổ tức, tiền lãi và xử lý tổn thất nợ phải thu khó đòi về cổ tức, tiền lãi Provision expense for bad debts from dividends, interest income and written off bad debts from dividends, interest income | D31: 0 | E31: 0 | F31: 0
A32: II | B32: Chi phí Expenses | D32: 3406874403 | E32: 2945744176 | F32: 3406874403
A33: 1 | B33: Chi phí quản lý trả cho Công ty quản lý quỹ Management Fee paid to Fund Management Company | D33: 2795129033 | E33: 2304253594 | F33: 2795129033
A34: 2 | B34: Chi phí lưu ký, giám sát trả cho Ngân hàng Giám sát/VSD Custody fee, Supervising fee paid to Supervising Bank/VSD | D34: 175762183 | E34: 168146038 | F34: 175762183
B35: Chi phí dịch vụ lưu ký - bảo quản tài sản Custodian service - Safe Custody Fee | D35: 80779680 | E35: 71150162 | F35: 80779680
B36: Chi phí dịch vụ lưu ký - giao dịch chứng khoán Custodian service - Transaction fee | D36: 9900000 | E36: 11100000 | F36: 9900000
B37: Chi phí dịch vụ lưu ký cho chứng khoán cơ sở, phí quản lý vị thế và tài sản phái sinh trả cho VSD Custodian service - Depository fee, Position and Margin management fee paid to VSD | D37: 9182503 | E37: 9995876 | F37: 9182503
B38: Chi phí giám sát Supervisory fee | D38: 75900000 | E38: 75900000 | F38: 75900000
A39: 3 | B39: Chi phí quản trị quỹ và các chi phí khác mà công ty quản lý quỹ trả cho tổ chức cung cấp dịch vụ có liên quan Fund Administration Fee, and other fees paid to relevant Fund's service providers | D39: 72418485 | E39: 65499930 | F39: 72418485
B40: Chi phí quản trị Quỹ Fund Administration Fee | D40: 39418485 | E40: 32499930 | F40: 39418485
B41: Chi phí dịch vụ Đại lý Chuyển nhượng Transfer Agency Fee | D41: 33000000 | E41: 33000000 | F41: 33000000
A42: 4 | B42: Chi phí dịch vụ quản lý bất động sản (không áp dụng) Real Estate Management Service fee (not applicable)
A43: 5 | B43: Chi phí dịch vụ định giá bất động sản (không áp dụng) Real estate valuation service fees (not applicable)
...

Sheet BCDanhMucDauTu_06029
A1: Phụ lục XXVI. Mẫu báo cáo về hoạt động của Quỹ Appendix XXVI. Report on Fund's Operation
A2: (Ban hành kèm theo Thông tư số 98/2020/TT-BTC ngày 16 tháng 11 năm 2020 của Bộ trưởng Bộ Tài Chính về hướng dẫn hoạt động và quản lý quỹ đầu tư chứng khoán) (Issued in association with Circular 98/2020/TT-BTC dated 16 November 2020 of the Minister of Finance on guiding the operation and management of the securities investment funds)
A3: BÁO CÁO VỀ HOẠT ĐỘNG ĐẦU TƯ REPORT ON INVESTMENT ACTIVITIES
A5: Tại ngày 31 tháng 03 năm 2021 / As at 31 Mar 2021
A7: Tên Công ty quản lý quỹ: | C7: Công ty Cổ phần Quản lý Quỹ Đầu tư Dragon Capital Việt Nam
A8: Fund Management Company: | C8: Dragon Capital Vietfund Management Joint Stock Company
A9: Tên ngân hàng giám sát: | C9: Ngân hàng TNHH Một thành viên Standard Chartered (Việt Nam)
A10: Supervising bank: | C10: Standard Chartered Bank (Vietnam) Limited
A11: Tên Quỹ: | C11: Quỹ Đầu tư Chứng khoán Việt Nam
A12: Fund name: | C12: Vietnam Securities Investment Fund(VFMVF1)
A13: Ngày lập báo cáo: | C13: Ngày 06 tháng 04 năm 2021
A14: Reporting Date: | C14: 06 Apr 2021
A16: A. | B16: BÁO CÁO CHUNG VỀ HOẠT ĐỘNG ĐẦU TƯ CỦA QUỸ/GENERAL INFORMATION ON FUND'S INVESTMENT ACTIVITIES
A17: III | B17: BÁO CÁO DANH MỤC ĐẦU TƯ / INVESTMENT PORTFOLIO REPORT
A18: STT No. | B18: Loại Category | C18: Mã chỉ tiêu Code | D18: Số Lượng Quantity | E18: Giá thị trường hoặc giá trị hợp lý tại ngày báo cáo Market price | F18: Tổng giá trị (Đồng) Value (VND) | G18: Tỷ lệ % Tổng giá trị tài sản của Quỹ % of total asset
A19: I | B19: BẤT ĐỘNG SẢN ĐẦU TƯ (KHÔNG ÁP DỤNG) REAL ESTATE INVESTMENT (NOT APPLICABLE)
A20: II | B20: CỔ PHIẾU NIÊM YẾT, ĐĂNG KÝ GIAO DỊCH, CHỨNG CHỈ QUỸ NIÊM YẾT LISTED SHARES, TRADING REGISTRATION SHARED, LISTED FUND CERTIFICATES
A21: 1 | B21: ACB | D21: 375314 | E21: 33300 | F21: 12497956200 | G21: 0.02007703
A22: 2 | B22: ASM | D22: 413100 | E22: 15150 | F22: 6258465000 | G22: 0.010053755
A23: 3 | B23: BID | D23: 191820 | E23: 42950 | F23: 8238669000 | G23: 0.013234804
A24: 4 | B24: CTG | D24: 266290 | E24: 40150 | F24: 10691543500 | G24: 0.017175163
A25: 5 | B25: CTR | D25: 86500 | E25: 93800 | F25: 8113700000 | G25: 0.013034051
A26: 6 | B26: DHC | D26: 171410 | E26: 83500 | F26: 14312735000 | G26: 0.022992336
A27: 7 | B27: DPM | D27: 300000 | E27: 19850 | F27: 5955000000 | G27: 0.0095662612
A28: 8 | B28: DRC | D28: 164810 | E28: 28800 | F28: 4746528000 | G28: 0.0076249415
A29: 9 | B29: DXG | D29: 246993 | E29: 24000 | F29: 5927832000 | G29: 0.0095226178
A30: 10 | B30: FPT | D30: 520305 | E30: 77700 | F30: 40427698500 | G30: 0.064944068
A31: 11 | B31: GAS | D31: 62360 | E31: 89700 | F31: 5593692000 | G31: 0.008985847
A32: 12 | B32: GIL | D32: 92300 | E32: 71800 | F32: 6627140000 | G32: 0.010646004
... A60: 40 | B60: VRE | D60: 164070 | E60: 32700 | F60: 5365089000 | G60: 0.0086186134
B61: TỔNG TOTAL | F61: 542545631850 | G61: 0.87155889
A62: III | B62: CỔ PHIẾU CHƯA NIÊM YẾT, ĐĂNG KÝ GIAO DỊCH, CHỨNG CHỈ QUỸ KHÔNG NIÊM YẾT UNLISTED SHARES, TRADING REGISTRATION, UNLISTED FUND CERTIFICATES
B63: TỔNG TOTAL | F63: 0 | G63: 0
B64: TỔNG CÁC LOẠI CỔ PHIẾU TOTAL SHARES | F64: 542545631850 | G64: 0.87155889
A65: IV | B65: TRÁI PHIẾU BONDS
A66: 1 | B66: Trái phiếu niêm yết Listed bonds | F66: 0 | G66: 0
A67: 2 | B67: Trái phiếu chưa niêm yết Unlisted Bonds | F67: 19993424600 | G67: 0.032117938
A68: 2.1 | B68: DAT XANH GROUP JSC 12% 18 Mar 2023 | D68: 200 | E68: 99967123 | F68: 19993424600 | G68: 0.032117938
B69: TỔNG TOTAL | F69: 19993424600 | G69: 0.032117938
A70: V | B70: CÁC LOẠI CHỨNG KHOÁN KHÁC OTHER SECURITIES
...

Sheet Khac_06030
A1: Phụ lục XXVI. Mẫu báo cáo về hoạt động của Quỹ Appendix XXVI. Report on Fund's Operation
A2: (Ban hành kèm theo Thông tư số 98/2020/TT-BTC ngày 16 tháng 11 năm 2020 của Bộ trưởng Bộ Tài Chính về hướng dẫn hoạt động và quản lý quỹ đầu tư chứng khoán) (Issued in association with Circular 98/2020/TT-BTC dated 16 November 2020 of the Minister of Finance on guiding the operation and management of the securities investment funds)
A3: BÁO CÁO VỀ HOẠT ĐỘNG ĐẦU TƯ REPORT ON INVESTMENT ACTIVITIES
A5: =TONGQUAN!C2 -> Quý I năm 2021 / Quarter I 2021
A7: Tên Công ty quản lý quỹ: | C7: =TONGQUAN!D5 -> Công ty Cổ phần Quản lý Quỹ Đầu tư Dragon Capital Việt Nam
A8: Fund Management Company: | C8: =TONGQUAN!D6 -> Dragon Capital Vietfund Management Joint Stock Company
A9: Tên ngân hàng giám sát: | C9: =TONGQUAN!D7 -> Ngân hàng TNHH Một thành viên Standard Chartered (Việt Nam)
A10: Supervising bank: | C10: =TONGQUAN!D8 -> Standard Chartered Bank (Vietnam) Limited
A11: Tên Quỹ: | C11: =TONGQUAN!D9 -> Quỹ Đầu tư Chứng khoán Việt Nam
A12: Fund name: | C12: =TONGQUAN!D10 -> Vietnam Securities Investment Fund(VFMVF1)
A13: Ngày lập báo cáo: | C13: =TONGQUAN!D11 -> Ngày 06 tháng 04 năm 2021
A14: Reporting Date: | C14: =TONGQUAN!D12 -> 06 Apr 2021
A16: A. | B16: BÁO CÁO CHUNG VỀ HOẠT ĐỘNG ĐẦU TƯ CỦA QUỸ/GENERAL INFORMATION ON FUND'S INVESTMENT ACTIVITIES
A17: V | B17: MỘT SỐ CHỈ TIÊU KHÁC / OTHER INDICATORS
A18: STT No | B18: Chỉ tiêu Indicators | C18: Mã chỉ tiêu Code | D18: =BCKetQuaHoatDong_06028!D18 -> Quý I năm 2021 Quarter I 2021 | E18: =BCKetQuaHoatDong_06028!E18 -> Quý IV năm 2020 Quarter IV 2020
A19: I | B19: CÁC CHỈ TIÊU VỀ HIỆU QUẢ HOẠT ĐỘNG INVESTMENT PERFORMANCE INDICATORS
A20: 1 | B20: Tỷ lệ giá dịch vụ quản lý quỹ trả cho công ty quản lý quỹ/Giá trị tài sản ròng trung bình trong kỳ (%) Management fee paid to the fund management company/Average NAV (%) | D20: 0.019235165 | E20: 0.019606145
A21: 2 | B21: Tỷ lệ giá dịch vụ lưu ký, giám sát trả cho Ngân hàng Giám sát/Giá trị tài sản ròng trung bình trong kỳ (%) Custody and supervising fees paid to the Supervisory Bank/Average NAV (%) | D21: 0.0011463469 | E21: 0.0013456484
A22: 3 | B22: Tỷ lệ chi phí dịch vụ quản trị quỹ, và các chi phí khác mà công ty quản lý quỹ trả cho tổ chức cung cấp dịch vụ có liên quan/Giá trị tài sản ròng của quỹ trung bình trong kỳ (%) Fund admin fee, and other fees paid to relating services providers by the fund management company/Average NAV (%) | D22: 0.00056155134 | E22: 0.00064236929
A23: 4 | B23: Chi phí kiểm toán trả cho tổ chức kiểm toán (nếu phát sinh)/Giá trị tài sản ròng trung bình trong kỳ (%) Auditing fee paid to auditing organizations (if any)/Average NAV (%) | D23: 0.00030797845 | E23: 0.00038819087
A24: 5 | B24: Chi phí trả cho tổ chức quản lý bất động sản/ Giá trị tài sản ròng trung bình trong kỳ (%) (không áp dụng) Fee paid to Real Estate management organisation/ Average NAV (%) (not applicable)
A25: 6 | B25: Chi phí trả cho doanh nghiệp thẩm định giá bất động sản/Giá trị tài sản ròng trung bình trong kỳ (%) (không áp dụng) Fee paid to Real Estate valuation service provider/ Average NAV (%) (not applicable)
A26: 7 | B26: Chi phí dịch vụ tư vấn pháp lý, dịch vụ báo giá và các dịch vụ hợp lý khác, thù lao trả cho ban đại diện quỹ/Giá trị tài sản ròng trung bình trong kỳ (%) Legal consultancy, price quotation and other appropriate service fees; remunerations paid to the Board of Representatives/Average NAV (%) | D26: 0.00049886475 | E26: 0.0014900666
A27: 8 | B27: Tỷ lệ chi phí /Giá trị tài sản ròng trung bình trong kỳ (%) Expense/Average NAV (%) | D27: 0.023444997 | E27: 0.02506438
A28: 9 | B28: Tốc độ vòng quay danh mục trong kỳ (%) = (Tổng giá trị mua vào + tổng giá trị bán ra) x 100%/ (2 x Giá trị tài sản ròng trung bình trong kỳ) Portfolio turnover rate (%) = (Total value of purchase transactions + total value of sales transactions) x 100%/ (2 x Average NAV) (**) | D28: 0.80284592 | E28: 0.62106722
A29: 10 | B29: Tỷ lệ thu nhập (tính cả thu nhập từ lãi, cổ tức, trái tức, chênh lệch giá)/ Giá trị tài sản ròng (không áp dụng) Income (including interest income, dividend, coupon income and unrealised gain)/ Average NAV (%) (not applicable)
A30: II | B30: CÁC CHỈ TIÊU KHÁC OTHER INDICATORS
A31: 1 | B31: Quy mô quỹ đầu kỳ (tính theo mệnh giá chứng chỉ quỹ) Fund scale at the beginning of the period (based on par value of fund certificate) | D31: 105292552100 | E31: 103117010400
B32: Tổng giá trị chứng chỉ quỹ đang lưu hành đầu kỳ Total value of outstanding Fund Certificate at the beginning of period | D32: 105292552100 | E32: 103117010400
B33: Tổng số lượng chứng chỉ quỹ đang lưu hành đầu kỳ Total number of outstanding Fund Certificate at the beginning of period | D33: 10529255 | E33: 10311701
A34: 2 | B34: Thay đổi quy mô quỹ trong kỳ (tính theo mệnh giá chứng chỉ quỹ) Change of Fund scale during the period (based on par value of fund certificate) | D34: 5358375000 | E34: 2175541700
B35: Thay đổi số lượng chứng chỉ quỹ trong kỳ Change of Number of Fund Certificates during the period | D35: 535837.5 | E35: 217554.17
B36: Thay đổi giá trị vốn trong kỳ (theo mệnh giá) Change in capital amount during the period (based on par value) | D36: 5358375000 | E36: 2175541700
B37: Số lượng chứng chỉ quỹ phát hành thêm trong kỳ Number of Fund Certificates subscribed during the period | D37: 1470523.2 | E37: 728312.03
B38: Giá trị vốn huy động thêm trong kỳ (theo mệnh giá) Net subscription amount during the period (based on par value) | D38: 14705232400 | E38: 7283120300
B39: Số lượng chứng chỉ quỹ mua lại trong kỳ (theo mệnh giá) Number of Fund Certificates redeemed during the period | D39: -934685.74 | E39: -510757.86
B40: Giá trị vốn phải thanh toán trong kỳ khi đáp ứng lệnh của nhà đầu tư (theo mệnh giá) Net redemption amount during the period (based on par value) | D40: -9346857400 | E40: -5107578600
A41: 3 | B41: Quy mô quỹ cuối kỳ (tính theo mệnh giá chứng chỉ quỹ) Fund scale at the end of the period (based on par value) | D41: 110650927100 | E41: 105292552100
B42: Tổng giá trị thị trường của quỹ đang lưu hành cuối kỳ (theo mệnh giá) Total value of outstanding Fund Certificate at the end of the period (based on par value) | D42: 110650927100 | E42: 105292552100
B43: Tổng số lượng chứng chỉ quỹ đang lưu hành cuối kỳ Total number of outstanding Fund Certificate at the end of the period | D43: 11065093 | E43: 10529255
...

Sheet BCHoatDongVay_06026
A1: Phụ lục XXVI. Mẫu báo cáo về hoạt động của Quỹ Appendix XXVI. Report on Fund's Operation
A2: (Ban hành kèm theo Thông tư số 98/2020/TT-BTC ngày 16 tháng 11 năm 2020 của Bộ trưởng Bộ Tài Chính về hướng dẫn hoạt động và quản lý quỹ đầu tư chứng khoán) (Issued in association with Circular 98/2020/TT-BTC dated 16 November 2020 of the Minister of Finance on guiding the operation and management of the securities investment funds)
A3: BÁO CÁO VỀ HOẠT ĐỘNG ĐẦU TƯ REPORT ON INVESTMENT ACTIVITIES
A5: Quý I năm 2021 / Quarter I 2021
A7: Tên Công ty quản lý quỹ: | G7: Công ty Cổ phần Quản lý Quỹ Đầu tư Dragon Capital Việt Nam
A8: Fund Management Company: | G8: Dragon Capital Vietfund Management Joint Stock Company
A9: Tên ngân hàng giám sát: | G9: Ngân hàng TNHH Một thành viên Standard Chartered (Việt Nam)
A10: Supervising bank: | G10: Standard Chartered Bank (Vietnam) Limited
A11: Tên Quỹ: | G11: Quỹ Đầu tư Chứng khoán Việt Nam
A12: Fund name: | G12: Vietnam Securities Investment Fund(VFMVF1)
A13: Ngày lập báo cáo: | G13: Ngày 06 tháng 04 năm 2021
A14: Reporting Date: | G14: 06 Apr 2021
A16: A. | B16: BÁO CÁO CHUNG VỀ HOẠT ĐỘNG ĐẦU TƯ CỦA QUỸ/GENERAL INFORMATION ON FUND'S INVESTMENT ACTIVITIES
A17: IV | B17: BÁO CÁO HOẠT ĐỘNG VAY, GIAO DỊCH MUA BÁN LẠI / REPORT ON BORROWING OPERATION, REPO/REVERSE REPO TRANSACTIONS
A18: STT No. | B18: Nội dung hoạt động (nêu chi tiết theo mục tiêu và đối tác) Description | C18: Mã chỉ tiêu Code | D18: Đối tác Counterparty | E18: Mục tiêu/Tài sản đảm bảo Collateral | F18: Kỳ hạn Term | G18: Giá trị khoản vay hoặc khoản cho vay Amount | H18: Thời điểm giao dịch As at transaction date | J18: Thời điểm báo cáo As at reporting date
H19: Ngày tháng năm Date | I19: Tỷ lệ giá trị hợp đồng/giá trị tài sản ròng của quỹ Balance/NAV | J19: Ngày tháng năm Date | K19: Tỷ lệ giá trị hợp đồng/giá trị tài sản ròng của quỹ Balance/NAV
A20: 1 | B20: Các khoản vay tiền (nêu chi tiết từng hợp đồng) Borrowings (detail by each contract)
A21: I | B21: Tổng giá trị các khoản vay tiền/giá trị tài sản ròng Borrowings/NAV
A22: 2 | B22: Hợp đồng Repo (nêu chi tiết từng hợp đồng) Repo contract (detail by each contract)
A23: II | B23: Tổng giá trị các hợp đồng Repo/giá trị tài sản ròng Total value of Repo contracts/NAV
A24: A | B24: Tổng giá trị các khoản vay/giá trị tài sản ròng (=I+II) Total Borrowings, Repo/NAV (=I+II)
A25: 3 | B25: Cho vay chứng khoán (nêu chi tiết từng hợp đồng) Securities lending (detail by each contract)
A26: III | B26: Tổng giá trị các hợp đồng/giá trị tài sản ròng Total contract value/NAV
A27: 4 | B27: Hợp đồng Reverse Repo (nêu chi tiết từng hợp đồng) Reverse Repo contract (Detail by each contract)
A28: IV | B28: Tổng giá trị các hợp đồng/giá trị tài sản ròng Total contract value/NAV
A29: B | B29: Tổng giá trị các khoản cho vay/giá trị tài sản ròng (=III + IV) Total Loans/NAV (=III + IV)
A34: Đại diện có thẩm quyền của Ngân hàng giám sát | I34: Đại diện có thẩm quyền của Công ty quản lý Quỹ
A35: Authorised Representative of Supervisory Bank | I35: Authorised Representative of Fund Management Company
A45: Ngân hàng TNHH MTV Standard Chartered (Việt Nam) | I45: Công ty Cổ phần Quản lý Quỹ Đầu tư Dragon Capital Việt Nam
A46: Vũ Hương Giang | I46: Nguyễn Minh Đăng Khánh
A47: Trưởng phòng Dịch vụ Quản trị và Giám sát Quỹ | I47: Giám đốc điều hành Nghiệp vụ hỗ trợ đầu tư
