Workbook
Name addlogo: INDEX(#REF!,MATCH(#REF!,#REF!,0))

Sheet TONGQUAN
A1: Kỳ báo cáo: | C1: Tại ngày 30 tháng 09 năm 2022 / As at 30 Sep 2022
C2: Quý III năm 2022 / Quarter III 2022
A4: Thông tin chung:
C5: Tên Công ty quản lý quỹ: | D5: Công ty Cổ phần Quản lý Quỹ Đầu tư Dragon Capital Việt Nam
C6: Fund Management Company: | D6: Dragon Capital Vietfund Management Joint Stock Company
C7: Tên ngân hàng giám sát: | D7: Ngân hàng TNHH Một thành viên Standard Chartered (Việt Nam)
C8: Supervising bank: | D8: Standard Chartered Bank (Vietnam) Limited
C9: Tên Quỹ: | D9: Quỹ Đầu tư Trái phiếu Gia tăng Thu nhập Cố định DC
C10: Fund name: | D10: DC Income Plus Bond Fund(VFMVFC)
C11: Ngày lập báo cáo: | D11: Ngày 05 tháng 10 năm 2022
C12: Reporting Date: | D12: 05 Oct 2022
A14: Người ký báo cáo:
C16: Đại diện có thẩm quyền của Ngân hàng giám sát | F16: Đại diện có thẩm quyền của Công ty quản lý Quỹ
C17: Authorised Representative of Supervisory Bank | F17: Authorised Representative of Fund Management Company
C19: Ngân hàng TNHH MTV Standard Chartered (Việt Nam) | F19: =D5 -> Công ty Cổ phần Quản lý Quỹ Đầu tư Dragon Capital Việt Nam
C20: Trịnh Hoài Nam | F20: Nguyễn Minh Đăng Khánh
C21: Phó phòng Dịch vụ Quản trị và Giám sát Quỹ | F21: Giám đốc điều hành Nghiệp vụ hỗ trợ đầu tư
B34: STT | C34: Nội dung | D34: Tên sheet
B35: A | C35: BÁO CÁO CHUNG VỀ HOẠT ĐỘNG ĐẦU TƯ CỦA QUỸ
B36: A.I | C36: Báo cáo về tài sản | D36: 06027
B37: A.II | C37: Báo cáo kết quả hoạt động | D37: 06028
B38: A.III | C38: Báo cáo danh mục đầu tư | D38: 06029
B39: A.IV | C39: Báo cáo hoạt động vay, giao dịch mua bán lại | D39: 06026
B40: A.V | C40: Một số chỉ tiêu khác | D40: 06030
B41: A.VI | C41: Thống kê phí giao dịch | D41: 06031
B42: 5 | C42: Báo cáo thay đổi giá trị tài sản ròng, giao dịch chứng chỉ quỹ | D42: 06129
B43: 6 | C43: Báo cáo thu nhập giữa niên độ | D43: 06203
B44: 7 | C44: Báo cáo tình hình tài chính giữa niên độ | D44: 06105
B45: 8 | C45: Báo cáo thay đổi giá trị tài sản ròng, giao dịch chứng chỉ quỹ giữa niên độ | D45: 06107
B46: 9 | C46: Báo cáo danh mục đầu tư | D46: 06108
B47: 10 | C47: Báo cáo lưu chuyển tiền tệ | D47: 06262
B48: 11 | C48: Báo cáo thu nhập | D48: 06104
B49: 12 | C49: Báo cáo về tài sản của quỹ | D49: 06126
B50: A.VII | C50: Thống kê giao dịch của Quỹ đầu tư bất động sản với người có liên quan | D50: không có
B51: A.VIII | C51: Thống kê giao dịch bất động sản của Quỹ đầu tư bất động sản | D51: không có
B52: B | C52: BÁO CÁO TÌNH HÌNH TỰ DOANH ĐẦU TƯ GIÁN TIẾP RA NƯỚC NGOÀI CỦA QUỸ | D52: Không có

Sheet BCthunhap
A1: Mẫu số B01g - QM. Báo cáo thu nhập Template B01g - QM. Statement of Comprehensive Income
A2: (Ban hành kèm theo Thông tư 198/2012/TT-BTC ngày 15 tháng 11 năm 2012 về chế độ kế toán áp dụng đối với quỹ mở) (Issued in association with Circular 198/2012/TT-BTC dated 15 Nov 2012 on the Accounting Policies for Open-Ended Fund)
A3: BÁO CÁO THU NHẬP STATEMENT OF COMPREHENSIVE INCOME
A5: =TONGQUAN!C2 -> Quý III năm 2022 / Quarter III 2022
A7: Tên Công ty quản lý quỹ: | D7: =TONGQUAN!D5 -> Công ty Cổ phần Quản lý Quỹ Đầu tư Dragon Capital Việt Nam
A8: Fund Management Company: | D8: =TONGQUAN!D6 -> Dragon Capital Vietfund Management Joint Stock Company
A9: Tên ngân hàng giám sát: | D9: =TONGQUAN!D7 -> Ngân hàng TNHH Một thành viên Standard Chartered (Việt Nam)
A10: Supervising bank: | D10: =TONGQUAN!D8 -> Standard Chartered Bank (Vietnam) Limited
A11: Tên Quỹ: | D11: =TONGQUAN!D9 -> Quỹ Đầu tư Trái phiếu Gia tăng Thu nhập Cố định DC
A12: Fund name: | D12: =TONGQUAN!D10 -> DC Income Plus Bond Fund(VFMVFC)
A13: Ngày lập báo cáo: | D13: =TONGQUAN!D11 -> Ngày 05 tháng 10 năm 2022
A14: Reporting Date: | D14: =TONGQUAN!D12 -> 05 Oct 2022
A16: Chỉ tiêu Indicator | B16: Mã số Code | C16: Thuyết minh Note | D16: Năm 2022 Year 2022 | F16: Năm 2021 Year 2021
D17: =BCKetQuaHoatDong_06028!D18 -> Quý III năm 2022 Quarter III 2022 | E17: Số lũy kế Year-to-date | F17: Quý III năm 2021 Quarter III 2021 | G17: Số lũy kế Year-to-date
A18: I. THU NHẬP, DOANH THU HOẠT ĐỘNG ĐẦU TƯ Investment income | B18: 01 | D18: 12115899732 | E18: 23528831260 | F18: 4156664698 | G18: 5750628763
A19: 1.1. Cổ tức được chia Dividend income | B19: 02 | D19: 0 | E19: 0 | F19: 17000 | G19: 212000
A20: 1.2. Tiền lãi được nhận Interest income | B20: 03 | D20: 12859723014 | E20: 24194718123 | F20: 4195213657 | G20: 5772572637
A21: Lãi tiền gửi ngân hàng Interest income from bank deposits | B21: 03.1 | D21: 1372469591 | E21: 2683328986 | F21: 642653249 | G21: 1153190312
A22: Lãi chứng chỉ tiền gửi Interest income from Certificates of Deposit | B22: 03.2 | D22: 1395767124 | E22: 3846643836 | F22: 1643397260 | G22: 2082547945
A23: Lãi trái phiếu Interest income from bonds | B23: 03.3 | D23: 10091486299 | E23: 17664745301 | F23: 1909163148 | G23: 2536834380
A24: Tiền lãi hợp đồng mua lại đảo ngược được nhận Reverse repo contract interest received | B24: 03.4 | D24: 0 | E24: 0 | F24: 0 | G24: 0
A25: 1.3. Lãi (lỗ) bán các khoản đầu tư Realized gain (losses) from disposal investments | B25: 04 | D25: 128662233 | E25: 484419112 | F25: -38705479 | G25: -11222836
A26: 1.4. Chênh lệch tăng, giảm đánh giá lại các khoản đầu tư chưa thực hiện Unrealized gain (losses) from investment revaluation | B26: 05 | D26: -872485515 | E26: -1150305975 | F26: 139520 | G26: -10933038
A27: 1.5. Doanh thu khác Other income | B27: 06 | D27: 0 | E27: 0 | F27: 0 | G27: 0
A28: 1.6. Chênh lệch lãi, lỗ tỷ giá hối đoái đã và chưa thực hiện Realized and unrealized gain (losses) from foreign exchange | B28: 07 | D28: 0 | E28: 0 | F28: 0 | G28: 0
A29: 1.7. Doanh thu khác về đầu tư Other investment income | B29: 08 | D29: 0 | E29: 0 | F29: 0 | G29: 0
... A77: VIII. LỢI NHUẬN KẾ TOÁN SAU THUẾ TNDN PROFIT AFTER TAX (41=30-40) | B77: 41 | D77: 9608133266 | E77: 18568973122 | F77: 3151009049 | G77: 3798671370
A80: Người lập: | B80: Người duyệt:
A93: _______________________________________________ | B93: _____________________________________ | F93: _________________________________________________
A94: Nguyễn Kiều Trúc Ly | B94: Ninh Thị Tuệ Minh | F94: Nguyễn Minh Đăng Khánh
A95: Kế toán Quỹ | B95: Trưởng phòng Kế toán Quỹ | F95: Giám đốc điều hành Nghiệp vụ hỗ trợ đầu tư

Sheet BCtinhhinhtaichinh
A1: Mẫu số B02g - QM. Báo cáo tình hình tài chính Template B02g - QM. Statement of Financial Position
A2: (Ban hành kèm theo Thông tư 198/2012/TT-BTC ngày 15 tháng 11 năm 2012 về chế độ kế toán áp dụng đối với quỹ mở) (Issued in association with Circular 198/2012/TT-BTC dated 15 Nov 2012 on the Accounting Policies for Open-Ended Fund)
A3: BÁO CÁO TÌNH HÌNH TÀI CHÍNH STATEMENT OF FINANCIAL POSITION
A5: =TONGQUAN!C1 -> Tại ngày 30 tháng 09 năm 2022 / As at 30 Sep 2022
A7: Tên Công ty quản lý quỹ: | C7: =TONGQUAN!D5 -> Công ty Cổ phần Quản lý Quỹ Đầu tư Dragon Capital Việt Nam
A8: Fund Management Company: | C8: =TONGQUAN!D6 -> Dragon Capital Vietfund Management Joint Stock Company
A9: Tên ngân hàng giám sát: | C9: =TONGQUAN!D7 -> Ngân hàng TNHH Một thành viên Standard Chartered (Việt Nam)
A10: Supervising bank: | C10: =TONGQUAN!D8 -> Standard Chartered Bank (Vietnam) Limited
A11: Tên Quỹ: | C11: =TONGQUAN!D9 -> Quỹ Đầu tư Trái phiếu Gia tăng Thu nhập Cố định DC
A12: Fund name: | C12: =TONGQUAN!D10 -> DC Income Plus Bond Fund(VFMVFC)
A13: Ngày lập báo cáo: | C13: =TONGQUAN!D11 -> Ngày 05 tháng 10 năm 2022
A14: Reporting Date: | C14: =TONGQUAN!D12 -> 05 Oct 2022
A16: STT No. | B16: Chỉ tiêu Indicator | C16: Mã số Code | D16: Thuyết minh Note | E16: =BCTaiSan_06027!D18 -> Ngày 30 tháng 09 năm 2022 As at 30 Sep 2022 | F16: =BCTaiSan_06027!E18 -> Ngày 30 tháng 06 năm 2022 As at 30 Jun 2022
A17: I | B17: I. TÀI SẢN ASSETS | C17: I
A18: 1 | B18: 1.Tiền gửi ngân hàng và tương đương tiền Cash at bank and cash equivalent | C18: 110 | E18: 147951287500 | F18: 69607440580
A19: 1.1 | B19: 1.1. Tiền gửi ngân hàng Cash at bank | C19: 111 | E19: 78951287500 | F19: 8607440580
B20: Tiền gửi của nhà đầu tư cho hoạt động mua chứng chỉ quỹ Cash at bank for Fund's subscription | C20: 111.1 | E20: 0 | F20: 0
B21: Tiền phải trả cho Nhà đầu tư về mua lại Chứng chỉ quỹ Cash at bank for Fund's redemption | C21: 111.2 | E21: 50120632 | F21: 11385290
B22: Tiền gửi ngân hàng cho hoạt động của Quỹ Cash at bank for Fund's operation | C22: 111.3 | E22: 78901166868 | F22: 8596055290
B23: Tiền gửi ký quỹ cho hoạt động đầu tư chứng khoán phái sinh Margin account for trading derivatives | C23: 111.4 | E23: 0 | F23: 0
A24: 1.2 | B24: 1.2. Tiền gửi có kỳ hạn dưới ba (03) tháng Deposit with term less than three (03) months | C24: 112 | E24: 69000000000 | F24: 61000000000
A25: 2 | B25: 2. Các khoản đầu tư thuần Net Investments | C25: 120 | E25: 895944472888 | F25: 294518928855
A26: 2.1 | B26: 2.1. Các khoản đầu tư Investments | C26: 121 | E26: 895944472888 | F26: 294518928855
B27: Cổ phiếu niêm yết Listed Shares | C27: 121.1 | E27: 0 | F27: 0
B28: Cổ phiếu chưa niêm yết Unlisted Shares | C28: 121.2 | E28: 0 | F28: 0
B29: Trái phiếu niêm yết Listed Bonds | C29: 121.3 | E29: 576115043700 | F29: 203377325500
B30: Trái phiếu chưa niêm yết Unlisted Bonds | C30: 121.4 | E30: 99082914650 | F30: 31003554040
B31: Chứng chỉ tiền gửi Certificates of Deposit | C31: 121.5 | E31: 190146514538 | F31: 50538049315
B32: Hợp đồng tiền gửi có kỳ hạn trên ba (03) tháng Deposits with term over three (03) months | C32: 121.6 | E32: 30600000000 | F32: 9600000000
B33: Quyền mua chứng khoán Investment - Rights | C33: 121.7 | E33: 0 | F33: 0
B34: Hợp đồng tương lai chỉ số Index future contracts | C34: 121.8 | E34: 0 | F34: 0
B35: Đầu tư khác Other Investments | C35: 121.9 | E35: 0 | F35: 0
B36: Hợp đồng mua lại đảo ngược Reverse repo contracts | C36: 121.10 | E36: 0 | F36: 0
A37: 2.2 | B37: 2.2. Dự phòng giảm giá tài sản nhận thế chấp Impairment of devaluation of pledged assets | C37: 122 | E37: 0 | F37: 0
A38: 3 | B38: 3. Các khoản phải thu Receivables | C38: 130 | E38: 26686447536 | F38: 6275483056
A39: 3.1 | B39: 3.1 Phải thu về bán các khoản đầu tư Receivables from investments sold but not yet settled | C39: 131 | E39: 0 | F39: 0
B40: Trong đó: Phải thu khó đòi về bán các khoản đầu tư In which: Overdue receivables from selling investments | C40: 132 | E40: 0 | F40: 0
A41: 3.2 | B41: 3.2. Phải thu và dự thu cổ tức, tiền lãi các khoản đầu tư Dividend and interest receivables | C41: 133 | E41: 26686337536 | F41: 6275470956
A42: 3.2.1 | B42: 3.2.1. Phải thu cổ tức, tiền lãi đến ngày nhận Dividend and interest receivables on or after payment date | C42: 134 | E42: 0 | F42: 0
B43: Phải thu cổ tức Dividend receivables | C43: 134.1 | E43: 0 | F43: 0
...

Sheet BCLCTT_06262
A1: Mẫu số B05g - QM. Báo cáo lưu chuyển tiền tệ Template B05g - QM. Cash flow statement
A2: (Ban hành kèm theo Thông tư 198/2012/TT-BTC ngày 15 tháng 11 năm 2012 về chế độ kế toán áp dụng đối với quỹ mở) (Issued in association with Circular 198/2012/TT-BTC dated 15 Nov 2012 on the Accounting Policies for Open-Ended Fund)
A3: BÁO CÁO LƯU CHUYỂN TIỀN TỆ CASH FLOW STATEMENT
A4: =TONGQUAN!C2 -> Quý III năm 2022 / Quarter III 2022
A7: Tên Công ty quản lý quỹ: | B7: =TONGQUAN!D5 -> Công ty Cổ phần Quản lý Quỹ Đầu tư Dragon Capital Việt Nam
A8: Fund Management Company: | B8: =TONGQUAN!D6 -> Dragon Capital Vietfund Management Joint Stock Company
A9: Tên ngân hàng giám sát: | B9: =TONGQUAN!D7 -> Ngân hàng TNHH Một thành viên Standard Chartered (Việt Nam)
A10: Supervising bank: | B10: =TONGQUAN!D8 -> Standard Chartered Bank (Vietnam) Limited
A11: Tên Quỹ: | B11: =TONGQUAN!D9 -> Quỹ Đầu tư Trái phiếu Gia tăng Thu nhập Cố định DC
A12: Fund name: | B12: =TONGQUAN!D10 -> DC Income Plus Bond Fund(VFMVFC)
A13: Ngày lập báo cáo: | B13: =TONGQUAN!D11 -> Ngày 05 tháng 10 năm 2022
A14: Reporting Date: | B14: =TONGQUAN!D12 -> 05 Oct 2022
A17: Chỉ tiêu Indicator | B17: Mã số Code | C17: Thuyết minh Note | D17: =BCKetQuaHoatDong_06028!D18 -> Quý III năm 2022 Quarter III 2022 | E17: =BCKetQuaHoatDong_06028!E18 -> Quý II năm 2022 Quarter II 2022
A18: I. Lưu chuyển tiền từ hoạt động đầu tư Cash flow from investing activities | B18: I
A19: 1. Lợi nhuận trước Thuế thu nhập doanh nghiệp Profit before income tax | B19: 01 | D19: 9608133266 | E19: 4627253459
A20: 2. Điều chỉnh cho các khoản tăng giá trị tài sản ròng từ các hoạt động đầu tư Adjustment for NAV increase from investing activities | B20: 02 | D20: 848286283 | E20: 66583055
A21: (- Lãi) hoặc (+ lỗ) chênh lệch tỷ giá hối đoái/ đánh giá lại các khoản đầu tư chưa thực hiện Unreliased (Gain) or Loss from FX valuation/Investment revaluation | B21: 03 | D21: 872485515 | E21: 85239386
A22: (+) Chi phí trích trước Increase of Accrued Expenses | B22: 04 | D22: -24199232 | E22: -18656331
A23: 3. Lợi nhuận từ hoạt động đầu tư trước thay đổi vốn lưu động Profit from investing activities before changes in working capital | B23: 05 | D23: 10456419549 | E23: 4693836514
A24: (-) Tăng, (+) giảm đầu tư (Increase), Decrease Investments | B24: 20 | D24: -602298029548 | E24: -34954774026
A25: (-) Tăng, (+) giảm phải thu bán chứng khoán đầu tư (Increase), Decrease in Receivables from investments sold but not yet settled | B25: 06 | D25: 0 | E25: 0
A26: (-) Tăng, (+) giảm dự thu phải thu tiền lãi các khoản đầu tư (Increase), Decrease in Dividend and interest receivables | B26: 07 | D26: -20410866580 | E26: -39370962
A27: (-) Tăng, (+) giảm các khoản phải thu khác (Increase), Decrease in other receivables | B27: 08 | D27: -97900 | E27: -12100
A28: (+) Tăng, (-) giảm vay ngắn hạn Increase, (Decrease) in Short-term Loans | B28: 09 | D28: 0 | E28: 0
A29: (+) Tăng, (-) giảm phải trả cho người bán (Decrease), Increase in payables for securities purchased but not yet settled | B29: 10 | D29: 18794840000 | E29: 0
A30: (+) Tăng, (-) giảm phải trả các Đại lý phân phối Chứng chỉ quỹ, Công ty Quản lý Quỹ (Decrease)/increase in subscription and redemption fee payable to distributors and Fund Management Company | B30: 11 | D30: 175094068 | E30: 13777608
... A38: Lưu chuyển tiền thuần từ hoạt động đầu tư (1+2+3) Net Cash flow from Investing activities | B38: 19 | D38: -572802857842 | E38: -21907816170
A39: II. Lưu chuyển tiền từ hoạt động tài chính Cash flow from financing activities | B39: II
A40: 1. Tiền thu từ phát hành Chứng chỉ quỹ mở Receipts from subscriptions | B40: 31 | D40: 961853905123 | E40: 98241194677
A41: 2. Tiền chi mua lại Chứng chỉ quỹ mở Payments for redemptions | B41: 32 | D41: -310707200361 | E41: -21675506517
A42: 3. Tiền vay gốc Principal of borrowings | B42: 33 | D42: 0 | E42: 0
A43: 4. Tiền chi trả nợ gốc vay Payment of Principal borrowings | B43: 34 | D43: 0 | E43: 0
A44: 5. Tiền chi trả cổ tức, tiền lãi cho nhà đầu tư Dividend, profit distribution paid to investors | B44: 35 | D44: 0 | E44: 0
A45: Lưu chuyển tiền thuần từ hoạt động tài chính (1-2+3-4-5) Net cash outflows from financing activities | B45: 30 | D45: 651146704762 | E45: 76565688160
A46: III. Tăng/giảm tiền thuần trong kỳ Net Increase/Decrease in cash and cash equivalent for the period | B46: 40 | D46: 78343846920 | E46: 54657871990
A47: IV. Tiền và các khoản tương đương tiền đầu kỳ Cash and cash equivalents at the beginning of period | B47: 50 | D47: 69607440580 | E47: 14949568590
A48: Tiền gửi ngân hàng đầu kỳ: Cash at bank of the beginning of period: | B48: 51 | D48: 69607440580 | E48: 14949568590
A49: -Tiền gửi ngân hàng và tương đương tiền cho hoạt động của Quỹ Cash at bank and cash equivalent for Fund's operation | B49: 52 | D49: 69596055290 | E49: 14949468680
A50: Tiền gửi không kỳ hạn Demand deposit | B50: 52.1 | D50: 8596055290 | E50: 449468680
A51: Tiền gửi có kỳ hạn dưới ba (03) tháng Deposits with term under three (03) months | B51: 52.2 | D51: 61000000000 | E51: 14500000000
...

Sheet BCTaiSan_06027
A1: Phụ lục XXVI. Mẫu báo cáo về hoạt động của Quỹ Appendix XXVI. Report on Fund's Operation
A2: (Ban hành kèm theo Thông tư số 98/2020/TT-BTC ngày 16 tháng 11 năm 2020 của Bộ trưởng Bộ Tài Chính về hướng dẫn hoạt động và quản lý quỹ đầu tư chứng khoán) (Issued in association with Circular 98/2020/TT-BTC dated 16 November 2020 of the Minister of Finance on guiding the operation and management of the securities investment funds)
A3: BÁO CÁO VỀ HOẠT ĐỘNG ĐẦU TƯ REPORT ON INVESTMENT ACTIVITIES
A5: =TONGQUAN!C1 -> Tại ngày 30 tháng 09 năm 2022 / As at 30 Sep 2022
A7: Tên Công ty quản lý quỹ: | C7: =TONGQUAN!D5 -> Công ty Cổ phần Quản lý Quỹ Đầu tư Dragon Capital Việt Nam
A8: Fund Management Company: | C8: =TONGQUAN!D6 -> Dragon Capital Vietfund Management Joint Stock Company
A9: Tên ngân hàng giám sát: | C9: =TONGQUAN!D7 -> Ngân hàng TNHH Một thành viên Standard Chartered (Việt Nam)
A10: Supervising bank: | C10: =TONGQUAN!D8 -> Standard Chartered Bank (Vietnam) Limited
A11: Tên Quỹ: | C11: =TONGQUAN!D9 -> Quỹ Đầu tư Trái phiếu Gia tăng Thu nhập Cố định DC
A12: Fund name: | C12: =TONGQUAN!D10 -> DC Income Plus Bond Fund(VFMVFC)
A13: Ngày lập báo cáo: | C13: =TONGQUAN!D11 -> Ngày 05 tháng 10 năm 2022
A14: Reporting Date: | C14: =TONGQUAN!D12 -> 05 Oct 2022
A16: A. | B16: BÁO CÁO CHUNG VỀ HOẠT ĐỘNG ĐẦU TƯ CỦA QUỸ/GENERAL INFORMATION ON FUND'S INVESTMENT ACTIVITIES
A17: I | B17: BÁO CÁO VỀ TÀI SẢN / ASSET REPORT
A18: STT No | B18: Nội dung Indicator | C18: Mã chỉ tiêu Code | D18: Ngày 30 tháng 09 năm 2022 As at 30 Sep 2022 | E18: Ngày 30 tháng 06 năm 2022 As at 30 Jun 2022 | F18: %/cùng kỳ năm trước %/against last year
A19: I | B19: TÀI SẢN ASSETS
A20: I.1 | B20: Tiền và các khoản tương đương tiền Cash and Cash Equivalents | D20: 147951287500 | E20: 69607440580 | F20: 6.8331915
B21: Tiền gửi ngân hàng Cash at bank | D21: 78951287500 | E21: 8607440580 | F21: 224.38438
B22: Tiền gửi của nhà đầu tư cho hoạt động mua chứng chỉ quỹ Cash at bank for Fund's subscription | D22: 0 | E22: 0
B23: Tiền phải trả cho Nhà đầu tư về mua lại chứng chỉ quỹ Cash at bank for Fund's redemption | D23: 50120632 | E23: 11385290
B24: Tiền gửi ngân hàng cho hoạt động của Quỹ Cash at bank for Fund's operation | D24: 78901166868 | E24: 8596055290 | F24: 224.24194
B25: Tiền gửi ký quỹ cho hoạt động đầu tư chứng khoán phái sinh Margin account for trading derivatives | D25: 0 | E25: 0
B26: Tiền, tương đương tiền Cash, cash equivalents | D26: 69000000000 | E26: 61000000000 | F26: 3.2394366
A27: I.2 | B27: Các khoản đầu tư (kê chi tiết) Investments | D27: 895944472888 | E27: 294518928855 | F27: 4.5095859
B28: Cổ phiếu niêm yết Listed shares | D28: 0 | E28: 0 | F28: 0
B29: Cổ phiếu chưa niêm yết Unlisted shares | D29: 0 | E29: 0
B30: Trái phiếu Bonds | D30: 675197958350 | E30: 234380879540 | F30: 8.6391257
B31: Chứng chỉ tiền gửi Certificates of Deposit | D31: 190146514538 | E31: 50538049315 | F31: 2.361536
B32: Hợp đồng tiền gửi có kỳ hạn trên ba (03) tháng Deposits with term over three (03) months | D32: 30600000000 | E32: 9600000000 | F32: 0.765
B33: Quyền mua chứng khoán Investment - Rights | D33: 0 | E33: 0
B34: Hợp đồng tương lai chỉ số Index future contracts | D34: 0 | E34: 0
B35: Đầu tư khác Other investments | D35: 0 | E35: 0
B36: Hợp đồng mua lại đảo ngược Reverse repo contracts | D36: 0 | E36: 0
A37: I.3 | B37: Thu từ cho thuê bất động sản đầu tư (không áp dụng) Receivables from rental of investment property (not applicable)
A38: I.4 | B38: Cổ tức, trái tức được nhận Dividend, Coupon receivables | D38: 19742010958 | E38: 5447342740 | F38: 14.664087
B39: Phải thu cổ tức Dividend receivables | D39: 0 | E39: 0
B40: Phải thu trái tức Coupon receivables | D40: 19742010958 | E40: 5447342740 | F40: 14.664087
A41: I.5 | B41: Lãi được nhận Interest receivables | D41: 6944326578 | E41: 828128216 | F41: 1.5203021
B42: Phải thu lãi tiền gửi Interest receivable from bank deposits | D42: 449011508 | E42: 117689860 | F42: 0.58034276
B43: Phải thu lãi chứng chỉ tiền gửi Interest receivable from Certificates of Deposit | D43: 6495315070 | E43: 710438356 | F43: 1.7119842
...

Sheet BCKetQuaHoatDong_06028
A1: Phụ lục XXVI. Mẫu báo cáo về hoạt động của Quỹ Appendix XXVI. Report on Fund's Operation
A2: (Ban hành kèm theo Thông tư số 98/2020/TT-BTC ngày 16 tháng 11 năm 2020 của Bộ trưởng Bộ Tài Chính về hướng dẫn hoạt động và quản lý quỹ đầu tư chứng khoán) (Issued in association with Circular 98/2020/TT-BTC dated 16 November 2020 of the Minister of Finance on guiding the operation and management of the securities investment funds)
A3: BÁO CÁO VỀ HOẠT ĐỘNG ĐẦU TƯ REPORT ON INVESTMENT ACTIVITIES
A5: =TONGQUAN!C2 -> Quý III năm 2022 / Quarter III 2022
A7: Tên Công ty quản lý quỹ: | C7: =TONGQUAN!D5 -> Công ty Cổ phần Quản lý Quỹ Đầu tư Dragon Capital Việt Nam
A8: Fund Management Company: | C8: =TONGQUAN!D6 -> Dragon Capital Vietfund Management Joint Stock Company
A9: Tên ngân hàng giám sát: | C9: =TONGQUAN!D7 -> Ngân hàng TNHH Một thành viên Standard Chartered (Việt Nam)
A10: Supervising bank: | C10: =TONGQUAN!D8 -> Standard Chartered Bank (Vietnam) Limited
A11: Tên Quỹ: | C11: =TONGQUAN!D9 -> Quỹ Đầu tư Trái phiếu Gia tăng Thu nhập Cố định DC
A12: Fund name: | C12: =TONGQUAN!D10 -> DC Income Plus Bond Fund(VFMVFC)
A13: Ngày lập báo cáo: | C13: =TONGQUAN!D11 -> Ngày 05 tháng 10 năm 2022
A14: Reporting Date: | C14: =TONGQUAN!D12 -> 05 Oct 2022
A16: A. | B16: BÁO CÁO CHUNG VỀ HOẠT ĐỘNG ĐẦU TƯ CỦA QUỸ/GENERAL INFORMATION ON FUND'S INVESTMENT ACTIVITIES
A17: II | B17: BÁO CÁO KẾT QUẢ HOẠT ĐỘNG / PROFIT AND LOSS REPORT
A18: STT No | B18: Nội dung Indicator | C18: Mã chỉ tiêu Code | D18: Quý III năm 2022 Quarter III 2022 | E18: Quý II năm 2022 Quarter II 2022 | F18: Lũy kế từ đầu năm Accumulated from beginning of year
A19: I | B19: Thu nhập từ hoạt động đầu tư Income from Investment Activities | D19: 12859723014 | E19: 6148459931 | F19: 24194718123
A20: 1 | B20: Thu từ bất động sản cho thuê (không áp dụng) Income from rental property (not applicable)
A21: 2 | B21: Cổ tức, trái tức được nhận Dividend income, interest income from bonds | D21: 10091486299 | E21: 4489323424 | F21: 17664745301
B22: Cổ tức được nhận Dividends income | D22: 0 | E22: 0 | F22: 0
B23: Trái tức được nhận Interest income from bonds | D23: 10091486299 | E23: 4489323424 | F23: 17664745301
A24: 3 | B24: Lãi được nhận Interest income | D24: 2768236715 | E24: 1659136507 | F24: 6529972822
B25: Lãi tiền gửi ngân hàng Interest income from bank deposits | D25: 1372469591 | E25: 669355686 | F25: 2683328986
B26: Lãi chứng chỉ tiền gửi Interest income from Certificates of Deposit | D26: 1395767124 | E26: 989780821 | F26: 3846643836
B27: Lãi hợp đồng mua lại đảo ngược Interest income from reverse repo contracts | D27: 0 | E27: 0 | F27: 0
A28: 4 | B28: Các khoản thu nhập khác Other incomes | D28: 0 | E28: 0 | F28: 0
B29: Thu nhập khác về đầu tư Other investment incomes | D29: 0 | E29: 0 | F29: 0
B30: Thu nhập khác Other incomes | D30: 0 | E30: 0 | F30: 0
B31: Chi phí dự phòng nợ phải thu khó đòi về cổ tức, tiền lãi và xử lý tổn thất nợ phải thu khó đòi về cổ tức, tiền lãi Provision expense for bad debts from dividends, interest income and written off bad debts from dividends, interest income | D31: 0 | E31: 0 | F31: 0
A32: II | B32: Chi phí Expenses | D32: 2507766466 | E32: 1315919034 | F32: 4959858138
A33: 1 | B33: Chi phí quản lý trả cho Công ty quản lý quỹ Management Fee paid to Fund Management Company | D33: 1978054608 | E33: 921012824 | F33: 3713556681
A34: 2 | B34: Chi phí lưu ký, giám sát trả cho Ngân hàng Giám sát/VSD Custody fee, Supervising fee paid to Supervising Bank/VSD | D34: 149497260 | E34: 95106858 | F34: 337622865
B35: Chi phí dịch vụ lưu ký - bảo quản tài sản Custodian service - Safe Custody Fee | D35: 82418938 | E35: 38375536 | F35: 155651573
B36: Chi phí dịch vụ lưu ký - giao dịch chứng khoán Custodian service - Transaction fee | D36: 3300000 | E36: 1650000 | F36: 8200000
B37: Chi phí dịch vụ lưu ký cho chứng khoán cơ sở, phí quản lý vị thế và tài sản phái sinh trả cho VSD Custodian service - Depository fee, Position and Margin management fee paid to VSD | D37: 944348 | E37: 631322 | F37: 2037318
B38: Chi phí giám sát Supervisory fee | D38: 62833974 | E38: 54450000 | F38: 171733974
A39: 3 | B39: Chi phí quản trị quỹ và các chi phí khác mà công ty quản lý quỹ trả cho tổ chức cung cấp dịch vụ có liên quan Fund Administration Fee, and other fees paid to relevant Fund's service providers | D39: 154190599 | E39: 144787500 | F39: 443765599
B40: Chi phí quản trị Quỹ Fund Administration Fee | D40: 114590599 | E40: 111787500 | F40: 338165599
B41: Chi phí dịch vụ Đại lý Chuyển nhượng Transfer Agency Fee | D41: 39600000 | E41: 33000000 | F41: 105600000
A42: 4 | B42: Chi phí dịch vụ quản lý bất động sản (không áp dụng) Real Estate Management Service fee (not applicable)
A43: 5 | B43: Chi phí dịch vụ định giá bất động sản (không áp dụng) Real estate valuation service fees (not applicable)
...

Sheet BCDanhMucDauTu_06029
A1: Phụ lục số 03. Mẫu báo cáo hoạt động đầu tư của quỹ mở Appendix 03. Report on Open ended Fund's Investment Activities
A2: (Ban hành kèm theo Thông tư số 91/2019/TT-BTC ngày 31 tháng 12 năm 2019 của Bộ trưởng Bộ Tài chính sửa đổi, bổ sung một số Thông tư quy định về chế độ báo cáo và thủ tục hành chính áp dụng với công ty quản lý quỹ, quỹ đầu tư chứng khoán và công ty đầu tư chứng khoán) (Issued in association with Circular 91/2019/TT-BTC dated 31 December 2019 of the Minister of Finance on amending and supplementing several Circulars on the reporting regime and administrative procedures applicable to fund management company, investment fund and investment company)
A3: BÁO CÁO HOẠT ĐỘNG ĐẦU TƯ CỦA QUỸ MỞ REPORT ON OPEN ENDED FUND'S INVESTMENT ACTIVITIES
A5: =TONGQUAN!C1 -> Tại ngày 30 tháng 09 năm 2022 / As at 30 Sep 2022
A7: Tên Công ty quản lý quỹ: | C7: =TONGQUAN!D5 -> Công ty Cổ phần Quản lý Quỹ Đầu tư Dragon Capital Việt Nam
A8: Fund Management Company: | C8: =TONGQUAN!D6 -> Dragon Capital Vietfund Management Joint Stock Company
A9: Tên ngân hàng giám sát: | C9: =TONGQUAN!D7 -> Ngân hàng TNHH Một thành viên Standard Chartered (Việt Nam)
A10: Supervising bank: | C10: =TONGQUAN!D8 -> Standard Chartered Bank (Vietnam) Limited
A11: Tên Quỹ: | C11: =TONGQUAN!D9 -> Quỹ Đầu tư Trái phiếu Gia tăng Thu nhập Cố định DC
A12: Fund name: | C12: =TONGQUAN!D10 -> DC Income Plus Bond Fund(VFMVFC)
A13: Ngày lập báo cáo: | C13: =TONGQUAN!D11 -> Ngày 05 tháng 10 năm 2022
A14: Reporting Date: | C14: =TONGQUAN!D12 -> 05 Oct 2022
A17: III | B17: BÁO CÁO DANH MỤC ĐẦU TƯ / INVESTMENT PORTFOLIO REPORT
A18: STT No. | B18: Loại Category | C18: Mã chỉ tiêu Code | D18: Số Lượng Quantity | E18: Giá thị trường hoặc giá trị hợp lý tại ngày báo cáo Market price | F18: Tổng giá trị (Đồng) Value (VND) | G18: Tỷ lệ % Tổng giá trị tài sản của Quỹ % of total asset
A19: I | B19: BẤT ĐỘNG SẢN ĐẦU TƯ (KHÔNG ÁP DỤNG) REAL ESTATE INVESTMENT (NOT APPLICABLE)
A20: II | B20: CỔ PHIẾU NIÊM YẾT, ĐĂNG KÝ GIAO DỊCH, CHỨNG CHỈ QUỸ NIÊM YẾT SHARES LISTED, SHARES REGISTERED FOR TRADING, LISTED FUND CERTIFICATES
B21: TỔNG TOTAL
A22: III | B22: CỔ PHIẾU CHƯA NIÊM YẾT, ĐĂNG KÝ GIAO DỊCH, CHỨNG CHỈ QUỸ KHÔNG NIÊM YẾT SHARES UNLISTED, UNREGISTERED FOR TRADING, UNLISTED FUND CERTIFICATES
B23: TỔNG TOTAL | D23: 0 | F23: 0 | G23: 0
B24: TỔNG CÁC LOẠI CỔ PHIẾU TOTAL SHARES
A25: IV | B25: TRÁI PHIẾU BONDS
A26: 1 | B26: Trái phiếu niêm yết Listed bonds | F26: 576115043700 | G26: 0.53813247
A27: 1.1 | B27: BCG122006 | D27: 200000 | E27: 99924 | F27: 19984800000 | G27: 0.018667226
A28: 1.2 | B28: CII121029 | D28: 1070000 | E28: 99785 | F28: 106769950000 | G28: 0.099730735
A29: 1.3 | B29: KBC121020 | D29: 1170000 | E29: 101073 | F29: 118255410000 | G29: 0.11045897
A30: 1.4 | B30: MSN12003 | D30: 1300000 | E30: 100129 | F30: 130167700000 | G30: 0.1215859
A31: 1.5 | B31: MSN121015 | D31: 100000 | E31: 100199 | F31: 10019900000 | G31: 0.0093592999
A32: 1.6 | B32: TNG119007 | D32: 15 | E32: 1001464780 | F32: 15021971700 | G32: 0.014031591
A33: 1.7 | B33: TNG122017 | D33: 159200 | E33: 100360 | F33: 15977312000 | G33: 0.014923947
A34: 1.8 | B34: VND122013 | D34: 1400000 | E34: 99932 | F34: 139904800000 | G34: 0.13068104
A35: 1.9 | B35: VND122014 | D35: 200000 | E35: 100066 | F35: 20013200000 | G35: 0.018693754
A36: 2 | B36: Trái phiếu chưa niêm yết Unlisted Bonds | F36: 99082914650 | G36: 0.092550496
A37: 2.1 | B37: DAT XANH GROUP JSC 12% 18 Mar 2023 | D37: 280 | E37: 100285698 | F37: 28079995440 | G37: 0.026228715
A38: 2.2 | B38: KDH TRADING & INV JSC 12% 14/06/2025 | D38: 10 | E38: 1000000000 | F38: 10000000000 | G38: 0.0093407119
A39: 2.3 | B39: KDH TRADING & INV JSC 12% 23/08/2025 | D39: 40 | E39: 1000000000 | F39: 40000000000 | G39: 0.037362848
A40: 2.4 | B40: PDR BOND 12 PCT 02 DEC 2023 | D40: 210 | E40: 100013901 | F40: 21002919210 | G40: 0.019618222
B41: TỔNG TOTAL | F41: 675197958350 | G41: 0.63068296
A42: V | B42: CÁC LOẠI CHỨNG KHOÁN KHÁC OTHER SECURITIES
A43: 1 | B43: Quyền mua chứng khoán Investment - Rights | D43: 0 | F43: 0 | G43: 0
A44: 2 | B44: Chi tiết loại hợp đồng phái sinh(*) Index future contracts | D44: 0 | F44: 0 | G44: 0
...

Sheet BCHoatDongVay_06026
A1: Phụ lục XXVI. Mẫu báo cáo về hoạt động của Quỹ Appendix XXVI. Report on Fund's Operation
A2: (Ban hành kèm theo Thông tư số 98/2020/TT-BTC ngày 16 tháng 11 năm 2020 của Bộ trưởng Bộ Tài Chính về hướng dẫn hoạt động và quản lý quỹ đầu tư chứng khoán) (Issued in association with Circular 98/2020/TT-BTC dated 16 November 2020 of the Minister of Finance on guiding the operation and management of the securities investment funds)
A3: BÁO CÁO VỀ HOẠT ĐỘNG ĐẦU TƯ REPORT ON INVESTMENT ACTIVITIES
A5: =TONGQUAN!C2 -> Quý III năm 2022 / Quarter III 2022
A7: Tên Công ty quản lý quỹ: | G7: =TONGQUAN!D5 -> Công ty Cổ phần Quản lý Quỹ Đầu tư Dragon Capital Việt Nam
A8: Fund Management Company: | G8: =TONGQUAN!D6 -> Dragon Capital Vietfund Management Joint Stock Company
A9: Tên ngân hàng giám sát: | G9: =TONGQUAN!D7 -> Ngân hàng TNHH Một thành viên Standard Chartered (Việt Nam)
A10: Supervising bank: | G10: =TONGQUAN!D8 -> Standard Chartered Bank (Vietnam) Limited
A11: Tên Quỹ: | G11: =TONGQUAN!D9 -> Quỹ Đầu tư Trái phiếu Gia tăng Thu nhập Cố định DC
A12: Fund name: | G12: =TONGQUAN!D10 -> DC Income Plus Bond Fund(VFMVFC)
A13: Ngày lập báo cáo: | G13: =TONGQUAN!D11 -> Ngày 05 tháng 10 năm 2022
A14: Reporting Date: | G14: =TONGQUAN!D12 -> 05 Oct 2022
A15: A. | B15: BÁO CÁO CHUNG VỀ HOẠT ĐỘNG ĐẦU TƯ CỦA QUỸ/GENERAL INFORMATION ON FUND'S INVESTMENT ACTIVITIES
A16: IV | B16: BÁO CÁO HOẠT ĐỘNG VAY, GIAO DỊCH MUA BÁN LẠI / REPORT ON BORROWING OPERATION, REPO/REVERSE REPO TRANSACTIONS
A17: STT No. | B17: Nội dung hoạt động (nêu chi tiết theo mục tiêu và đối tác) Description | C17: Mã chỉ tiêu Code | D17: Đối tác Counterparty | E17: Mục tiêu/Tài sản đảm bảo Collateral | F17: Kỳ hạn Term | G17: Giá trị khoản vay hoặc khoản cho vay Amount | H17: Thời điểm giao dịch As at transaction date | J17: Thời điểm báo cáo As at reporting date
H18: Ngày tháng năm Date | I18: Tỷ lệ giá trị hợp đồng/giá trị tài sản ròng của quỹ Balance/NAV | J18: Ngày tháng năm Date | K18: Tỷ lệ giá trị hợp đồng/giá trị tài sản ròng của quỹ Balance/NAV
A19: 1 | B19: Các khoản vay tiền (nêu chi tiết từng hợp đồng) Borrowings (detail by each contract)
A20: I | B20: Tổng giá trị các khoản vay tiền/giá trị tài sản ròng Borrowings/NAV
A21: 2 | B21: Hợp đồng Repo (nêu chi tiết từng hợp đồng) Repo contract (detail by each contract)
A22: II | B22: Tổng giá trị các hợp đồng Repo/giá trị tài sản ròng Total value of Repo contracts/NAV
A23: A | B23: Tổng giá trị các khoản vay/giá trị tài sản ròng (=I+II) Total Borrowings, Repo/NAV (=I+II)
A24: 3 | B24: Cho vay chứng khoán (nêu chi tiết từng hợp đồng) Securities lending (detail by each contract)
A25: III | B25: Tổng giá trị các hợp đồng/giá trị tài sản ròng Total contract value/NAV
A26: 4 | B26: Hợp đồng Reverse Repo (nêu chi tiết từng hợp đồng) Reverse Repo contract (Detail by each contract)
A27: IV | B27: Tổng giá trị các hợp đồng/giá trị tài sản ròng Total contract value/NAV
A28: B | B28: Tổng giá trị các khoản cho vay/giá trị tài sản ròng (=III + IV) Total Loans/NAV (=III + IV)
A33: Đại diện có thẩm quyền của Ngân hàng giám sát | I33: Đại diện có thẩm quyền của Công ty quản lý Quỹ
A34: Authorised Representative of Supervisory Bank | I34: Authorised Representative of Fund Management Company
A44: Ngân hàng TNHH MTV Standard Chartered (Việt Nam) | I44: =TONGQUAN!F19 -> Công ty Cổ phần Quản lý Quỹ Đầu tư Dragon Capital Việt Nam
A45: =TONGQUAN!C20 -> Trịnh Hoài Nam | I45: =TONGQUAN!F20 -> Nguyễn Minh Đăng Khánh
A46: =TONGQUAN!C21 -> Phó phòng Dịch vụ Quản trị và Giám sát Quỹ | I46: =TONGQUAN!F21 -> Giám đốc điều hành Nghiệp vụ hỗ trợ đầu tư

Sheet Khac_06030
A1: Phụ lục XXVI. Mẫu báo cáo về hoạt động của Quỹ Appendix XXVI. Report on Fund's Operation
A2: (Ban hành kèm theo Thông tư số 98/2020/TT-BTC ngày 16 tháng 11 năm 2020 của Bộ trưởng Bộ Tài chính về hướng dẫn hoạt động và quản lý quỹ đầu tư chứng khoán) (Issued in association with Circular 98/2020/TT-BTC dated 16 November 2020 of the Minister of Finance on guiding the operation and management of the securities investment funds)
A3: BÁO CÁO VỀ HOẠT ĐỘNG ĐẦU TƯ REPORT ON INVESTMENT ACTIVITIES
A5: =TONGQUAN!C2 -> Quý III năm 2022 / Quarter III 2022
A7: Tên Công ty quản lý quỹ: | C7: =TONGQUAN!D5 -> Công ty Cổ phần Quản lý Quỹ Đầu tư Dragon Capital Việt Nam
A8: Fund Management Company: | C8: =TONGQUAN!D6 -> Dragon Capital Vietfund Management Joint Stock Company
A9: Tên ngân hàng giám sát: | C9: =TONGQUAN!D7 -> Ngân hàng TNHH Một thành viên Standard Chartered (Việt Nam)
A10: Supervising bank: | C10: =TONGQUAN!D8 -> Standard Chartered Bank (Vietnam) Limited
A11: Tên Quỹ: | C11: =TONGQUAN!D9 -> Quỹ Đầu tư Trái phiếu Gia tăng Thu nhập Cố định DC
A12: Fund name: | C12: =TONGQUAN!D10 -> DC Income Plus Bond Fund(VFMVFC)
A13: Ngày lập báo cáo: | C13: =TONGQUAN!D11 -> Ngày 05 tháng 10 năm 2022
A14: Reporting Date: | C14: =TONGQUAN!D12 -> 05 Oct 2022
A16: A. | B16: BÁO CÁO CHUNG VỀ HOẠT ĐỘNG ĐẦU TƯ CỦA QUỸ/GENERAL INFORMATION ON FUND'S INVESTMENT ACTIVITIES
A17: V | B17: MỘT SỐ CHỈ TIÊU KHÁC / OTHER INDICATORS
A18: STT No | B18: Chỉ tiêu Indicators | C18: Mã chỉ tiêu Code | D18: =BCKetQuaHoatDong_06028!D18 -> Quý III năm 2022 Quarter III 2022 | E18: =BCKetQuaHoatDong_06028!E18 -> Quý II năm 2022 Quarter II 2022
A19: I | B19: CÁC CHỈ TIÊU VỀ HIỆU QUẢ HOẠT ĐỘNG INVESTMENT PERFORMANCE INDICATORS
A20: 1 | B20: Tỷ lệ giá dịch vụ quản lý quỹ trả cho công ty quản lý quỹ/Giá trị tài sản ròng trung bình trong kỳ (%) Management fee paid to the fund management company/Average NAV (%) | D20: 0.012099482 | E20: 0.011968038
A21: 2 | B21: Tỷ lệ giá dịch vụ lưu ký, giám sát trả cho Ngân hàng Giám sát/Giá trị tài sản ròng trung bình trong kỳ (%) Custody and supervising fees paid to the Supervisory Bank/Average NAV (%) | D21: 0.00090867726 | E21: 0.0012276559
A22: 3 | B22: Tỷ lệ chi phí dịch vụ quản trị quỹ, và các chi phí khác mà công ty quản lý quỹ trả cho tổ chức cung cấp dịch vụ có liên quan/Giá trị tài sản ròng của quỹ trung bình trong kỳ (%) Fund admin fee, and other fees paid to relating services providers by the fund management company/Average NAV (%) | D22: 0.00094893864 | E22: 0.0018896349
A23: 4 | B23: Chi phí kiểm toán trả cho tổ chức kiểm toán (nếu phát sinh)/Giá trị tài sản ròng trung bình trong kỳ (%) Auditing fee paid to auditing organizations (if any)/Average NAV (%) | D23: 0.0001822871 | E23: 0.00035552602
A24: 5 | B24: Chi phí trả cho tổ chức quản lý bất động sản/ Giá trị tài sản ròng trung bình trong kỳ (%) (không áp dụng) Fee paid to Real Estate management organisation/ Average NAV (%) (not applicable)
A25: 6 | B25: Chi phí trả cho doanh nghiệp thẩm định giá bất động sản/Giá trị tài sản ròng trung bình trong kỳ (%) (không áp dụng) Fee paid to Real Estate valuation service provider/ Average NAV (%) (not applicable)
A26: 7 | B26: Chi phí dịch vụ tư vấn pháp lý, dịch vụ báo giá và các dịch vụ hợp lý khác, thù lao trả cho ban đại diện quỹ/Giá trị tài sản ròng trung bình trong kỳ (%) Legal consultancy, price quotation and other appropriate service fees; remunerations paid to the Board of Representatives/Average NAV (%) | D26: 0.00039377475 | E26: 0.00066873981
A27: 8 | B27: Tỷ lệ chi phí /Giá trị tài sản ròng trung bình trong kỳ (%) Expense/Average NAV (%) | D27: 0.015339655 | E27: 0.01709962
A28: 9 | B28: Tốc độ vòng quay danh mục trong kỳ (%) = (Tổng giá trị mua vào + tổng giá trị bán ra) x 100%/ (2 x Giá trị tài sản ròng trung bình trong kỳ) Portfolio turnover rate (%) = (Total value of purchase transactions + total value of sales transactions) x 100%/ (2 x Average NAV) (**) | D28: 2.0773447 | E28: 1.3649621
A29: 10 | B29: Tỷ lệ thu nhập (tính cả thu nhập từ lãi, cổ tức, trái tức, chênh lệch giá)/ Giá trị tài sản ròng (không áp dụng) Income (including interest income, dividend, coupon income and unrealised gain)/ Average NAV (%) (not applicable)
A30: II | B30: CÁC CHỈ TIÊU KHÁC OTHER INDICATORS
A31: 1 | B31: Quy mô quỹ đầu kỳ (tính theo mệnh giá chứng chỉ quỹ) Fund scale at the beginning of the period (based on par value of fund certificate) | D31: 362616543400 | E31: 285398566800
B32: Tổng giá trị chứng chỉ quỹ đang lưu hành đầu kỳ Total value of outstanding Fund Certificate at the beginning of period | D32: 362616543400 | E32: 285398566800
B33: Tổng số lượng chứng chỉ quỹ đang lưu hành đầu kỳ Total number of outstanding Fund Certificate at the beginning of period | D33: 36261654 | E33: 28539857
A34: 2 | B34: Thay đổi quy mô quỹ trong kỳ (tính theo mệnh giá chứng chỉ quỹ) Change of Fund scale during the period (based on par value of fund certificate) | D34: 647643049800 | E34: 77217976600
B35: Thay đổi số lượng chứng chỉ quỹ trong kỳ Change of Number of Fund Certificates during the period | D35: 64764305 | E35: 7721797.7
B36: Thay đổi giá trị vốn trong kỳ (theo mệnh giá) Change in capital amount during the period (based on par value) | D36: 647643049800 | E36: 77217976600
B37: Số lượng chứng chỉ quỹ phát hành thêm trong kỳ Number of Fund Certificates subscribed during the period | D37: 95583679 | E37: 9909715.7
B38: Giá trị vốn huy động thêm trong kỳ (theo mệnh giá) Net subscription amount during the period (based on par value) | D38: 955836791500 | E38: 99097156700
B39: Số lượng chứng chỉ quỹ mua lại trong kỳ (theo mệnh giá) Number of Fund Certificates redeemed during the period | D39: -30819374 | E39: -2187918
B40: Giá trị vốn phải thanh toán trong kỳ khi đáp ứng lệnh của nhà đầu tư (theo mệnh giá) Net redemption amount during the period (based on par value) | D40: -308193741700 | E40: -21879180100
A41: 3 | B41: Quy mô quỹ cuối kỳ (tính theo mệnh giá chứng chỉ quỹ) Fund scale at the end of the period (based on par value) | D41: 1010259593200 | E41: 362616543400
B42: Tổng giá trị thị trường của quỹ đang lưu hành cuối kỳ (theo mệnh giá) Total value of outstanding Fund Certificate at the end of the period (based on par value) | D42: 1010259593200 | E42: 362616543400
B43: Tổng số lượng chứng chỉ quỹ đang lưu hành cuối kỳ Total number of outstanding Fund Certificate at the end of the period | D43: 1.0102596e+08 | E43: 36261654
...
