Workbook
Name addlogo: INDEX(LogoFMS!$C$3:$C$39,MATCH(LogoFMS!$D$1,LogoFMS!$A$3:$A$39,0))

Sheet Tong quat
A1: Kỳ báo cáo: | C1: Tại ngày 31 tháng 10 năm 2019 / As at 31 Oct 2019
C2: Tháng 10 năm 2019 / Oct 2019
A4: Thông tin chung:
C5: Tên Công ty quản lý quỹ: | D5: Công ty Cổ phần Quản lý Quỹ Đầu tư Việt Nam
C6: Fund Management Company: | D6: Vietnam Investment Fund Management Joint Stock Company
C7: Tên ngân hàng giám sát: | D7: Ngân hàng TNHH Một thành viên Standard Chartered (Việt Nam)
C8: Supervising bank: | D8: Standard Chartered Bank (Vietnam) Limited
C9: Tên Quỹ: | D9: Quỹ Đầu tư Chứng khoán Việt Nam
C10: Fund name: | D10: Vietnam Securities Investment Fund(VFMVF1)
C11: Ngày lập báo cáo: | D11: Ngày 04 tháng 11 năm 2019
C12: Reporting Date: | D12: 04 Nov 2019
A14: Người ký báo cáo:
C16: Đại diện có thẩm quyền của Ngân hàng giám sát | F16: Đại diện có thẩm quyền của Công ty quản lý Quỹ
C17: Authorised Representative of Supervisory Bank | F17: Authorised Representative of Fund Management Company
C19: Ngân hàng TNHH MTV Standard Chartered (Việt Nam) | F19: =D5 -> Công ty Cổ phần Quản lý Quỹ Đầu tư Việt Nam
C20: Vũ Hương Giang | F20: Trần Thanh Tân
C21: Phó phòng Nghiệp vụ Dịch vụ Chứng khoán | F21: Tổng Giám đốc
B34: STT | C34: Nội dung | D34: Tên sheet
B35: 1 | C35: Báo cáo về tài sản của quỹ | D35: 06027
B36: 2 | C36: Báo cáo kết quả hoạt động | D36: 06028
B37: 3 | C37: Báo cáo danh mục đầu tư của quỹ | D37: 06029
B38: 4 | C38: Một số chỉ tiêu khác | D38: 06030
B39: 5 | C39: Báo cáo thay đổi giá trị tài sản ròng, giao dịch chứng chỉ quỹ | D39: 06129
B40: 6 | C40: Báo cáo thu nhập giữa niên độ | D40: 06203
B41: 7 | C41: Báo cáo tình hình tài chính giữa niên độ | D41: 06105
B42: 8 | C42: Báo cáo thay đổi giá trị tài sản ròng, giao dịch chứng chỉ quỹ giữa niên độ | D42: 06107
B43: 9 | C43: Báo cáo danh mục đầu tư | D43: 06108
B44: 10 | C44: Báo cáo lưu chuyển tiền tệ | D44: 06262
B45: 11 | C45: Báo cáo thu nhập | D45: 06104
B46: 12 | C46: Báo cáo về tài sản của quỹ | D46: 06126
B48: Thống kê các Thuyết minh BCTC
D50: Có trình bày Y/N/O | E50: Nguyên nhân không trình bày
B51: 1/ | C51: Tiền gửi Ngân hàng | D51: Y
B52: 2/ | C52: Các khoản đầu tư | D52: Y
B53: 3/ | C53: Các khoản dự phòng | D53: O | E53: Chỉ có VF1 trình bày, các Quỹ khác không có khoản mục này không phải trình bày
B54: 4/ | C54: Vay ngắn hạn | D54: N | E54: Không có số dư không trình bày
B55: 5/ | C55: Phải trả mua các khoản đầu tư | D55: N | E55: Không có số dư không trình bày
B56: 6/ | C56: Phải trả các Đại lý phân phối, Công ty Quản lý quỹ về phí phát hành và mua lại Chứng chỉ quỹ | D56: N | E56: Trên báo cáo chính đã chi tiết theo từng khoản mục
B57: 7/ | C57: Thuế và các khoản phải nộp Nhà nước | D57: N | E57: Không bắt buộc, Quỹ chỉ có khoản mục thuế từ hoạt động mua bán CCQ và Thù lao BDD
B58: 8/ | C58: Phải trả thu nhập cho Nhà đầu tư | D58: N | E58: Quỹ nào có chia cổ tức mới trình bày
...

Sheet BCthunhap
A1: Mẫu số B01g - QM. Báo cáo thu nhập Template B01g - QM. Statement of Comprehensive Income
A2: (Ban hành kèm theo Thông tư 198/2012/TT-BTC ngày 15 tháng 11 năm 2012 về chế độ kế toán áp dụng đối với quỹ mở) (Issued in association with Circular 198/2012/TT-BTC dated 15 Nov 2012 on the Accounting Policies for Open-Ended Fund)
A3: BÁO CÁO THU NHẬP STATEMENT OF COMPREHENSIVE INCOME
A5: ='Tong quat'!C2 -> Tháng 10 năm 2019 / Oct 2019
A7: Tên Công ty quản lý quỹ: | D7: ='Tong quat'!D5 -> Công ty Cổ phần Quản lý Quỹ Đầu tư Việt Nam
A8: Fund Management Company: | D8: ='Tong quat'!D6 -> Vietnam Investment Fund Management Joint Stock Company
A9: Tên ngân hàng giám sát: | D9: ='Tong quat'!D7 -> Ngân hàng TNHH Một thành viên Standard Chartered (Việt Nam)
A10: Supervising bank: | D10: ='Tong quat'!D8 -> Standard Chartered Bank (Vietnam) Limited
A11: Tên Quỹ: | D11: ='Tong quat'!D9 -> Quỹ Đầu tư Chứng khoán Việt Nam
A12: Fund name: | D12: ='Tong quat'!D10 -> Vietnam Securities Investment Fund(VFMVF1)
A13: Ngày lập báo cáo: | D13: ='Tong quat'!D11 -> Ngày 04 tháng 11 năm 2019
A14: Reporting Date: | D14: ='Tong quat'!D12 -> 04 Nov 2019
A16: Chỉ tiêu Indicator | B16: Mã số Code | C16: Thuyết minh Note | D16: Năm 2019 Year 2019 | F16: Năm 2018 Year 2018
D17: =BCKetQuaHoatDong_06028!D18 -> Tháng 10 năm 2019 Oct 2019 | E17: Số lũy kế Year-to-date | F17: Tháng 10 năm 2018 Oct 2018 | G17: Số lũy kế Year-to-date
A18: I. THU NHẬP, DOANH THU HOẠT ĐỘNG ĐẦU TƯ Investment income | B18: 01 | D18: 5814905582 | E18: 139819108198 | F18: -126850262450 | G18: -132972932936
A19: 1.1. Cổ tức được chia Dividend income | B19: 02 | D19: 643830000 | E19: 12039311000 | F19: 1294826000 | G19: 13105518700
A20: 1.2. Tiền lãi được nhận Interest income | B20: 03 | D20: 979821780 | E20: 14568393858 | F20: 1360904100 | G20: 10950463254
A21: Lãi tiền gửi ngân hàng Interest income from bank deposits | B21: 03.1 | D21: 4993012 | E21: 262591347 | F21: 28479156 | G21: 1446833402
A22: Lãi chứng chỉ tiền gửi Interest income from Certificates of Deposit | B22: 03.2 | D22: 278150685 | E22: 6629817922 | F22: 1061174944 | G22: 7981129852
A23: Lãi trái phiếu Interest income from bonds | B23: 03.3 | D23: 696678083 | E23: 7675984589 | F23: 271250000 | G23: 1522500000
A24: Tiền lãi hợp đồng reverse repo Reverse repo contract interest received | B24: 03.4 | D24: 0 | E24: 0 | F24: 0 | G24: 0
A25: 1.3. Lãi (lỗ) bán các khoản đầu tư Realized gain (losses) from disposal investments | B25: 04 | D25: 994411335 | E25: 3783608640 | F25: -13376297276 | G25: 67758632292
A26: 1.4. Chênh lệch tăng, giảm đánh giá lại các khoản đầu tư chưa thực hiện Unrealized gain (losses) from investment revaluation | B26: 05 | D26: 3196842467 | E26: 109427794700 | F26: -116129695274 | G26: -227643547182
A27: 1.5. Doanh thu khác Other income | B27: 06 | D27: 0 | E27: 0 | F27: 0 | G27: 2856000000
A28: 1.6. Chênh lệch lãi, lỗ tỷ giá hối đoái đã và chưa thực hiện Realized and unrealized gain (losses) from foreign exchange | B28: 07 | D28: 0 | E28: 0 | F28: 0 | G28: 0
A29: 1.7. Doanh thu khác về đầu tư Other investment income | B29: 08 | D29: 0 | E29: 0 | F29: 0 | G29: 0
... A77: VIII. LỢI NHUẬN KẾ TOÁN SAU THUẾ TNDN PROFIT AFTER TAX (41=30-40) | B77: 41 | D77: 4194581295 | E77: 120697289535 | F77: -129547781095 | G77: -159977099676
A80: Người lập: | B80: Người duyệt:
A93: ____________________________________________ | B93: ____________________________________________ | F93: _____________________________________
A94: Bà Mai Thùy Sâm | B94: Ông Nguyễn Minh Đăng Khánh | F94: Ông Trần Thanh Tân
A95: Kế toán Quỹ | B95: Phó Tổng Giám đốc kiêm Giám đốc Tài chính | F95: Tổng Giám đốc

Sheet BCtinhhinhtaichinh
A1: Mẫu số B02g - QM. Báo cáo tình hình tài chính Template B02g - QM. Statement of Financial Position
A2: (Ban hành kèm theo Thông tư 198/2012/TT-BTC ngày 15 tháng 11 năm 2012 về chế độ kế toán áp dụng đối với quỹ mở) (Issued in association with Circular 198/2012/TT-BTC dated 15 Nov 2012 on the Accounting Policies for Open-Ended Fund)
A3: BÁO CÁO TÌNH HÌNH TÀI CHÍNH STATEMENT OF FINANCIAL POSITION
A5: ='Tong quat'!C1 -> Tại ngày 31 tháng 10 năm 2019 / As at 31 Oct 2019
A7: Tên Công ty quản lý quỹ: | C7: ='Tong quat'!D5 -> Công ty Cổ phần Quản lý Quỹ Đầu tư Việt Nam
A8: Fund Management Company: | C8: ='Tong quat'!D6 -> Vietnam Investment Fund Management Joint Stock Company
A9: Tên ngân hàng giám sát: | C9: ='Tong quat'!D7 -> Ngân hàng TNHH Một thành viên Standard Chartered (Việt Nam)
A10: Supervising bank: | C10: ='Tong quat'!D8 -> Standard Chartered Bank (Vietnam) Limited
A11: Tên Quỹ: | C11: ='Tong quat'!D9 -> Quỹ Đầu tư Chứng khoán Việt Nam
A12: Fund name: | C12: ='Tong quat'!D10 -> Vietnam Securities Investment Fund(VFMVF1)
A13: Ngày lập báo cáo: | C13: ='Tong quat'!D11 -> Ngày 04 tháng 11 năm 2019
A14: Reporting Date: | C14: ='Tong quat'!D12 -> 04 Nov 2019
A16: STT No. | B16: Chỉ tiêu Indicator | C16: Mã số Code | D16: Thuyết minh Note | E16: =BCTaiSan_06027!D18 -> Ngày 31 tháng 10 năm 2019 As at 31 Oct 2019 | F16: =BCTaiSan_06027!E18 -> Ngày 30 tháng 09 năm 2019 As at 30 Sep 2019
A17: I | B17: I. TÀI SẢN ASSETS | C17: I
A18: 1 | B18: 1.Tiền gửi ngân hàng và tương đương tiền Cash at bank and cash equivalent | C18: 110 | E18: 49227230731 | F18: 4858023375
A19: 1.1 | B19: 1.1. Tiền gửi ngân hàng Cash at bank | C19: 111 | E19: 49227230731 | F19: 4858023375
B20: Tiền gửi của nhà đầu tư cho hoạt động mua chứng chỉ quỹ Cash at bank for Fund's subscription | C20: 111.1 | E20: 59000000 | F20: 41000000
B21: Tiền phải trả cho Nhà đầu tư về mua lại Chứng chỉ quỹ Cash at bank for Fund's redemption | C21: 111.2 | E21: 0 | F21: 0
B22: Tiền gửi ngân hàng cho hoạt động của Quỹ Cash at bank for Fund's operation | C22: 111.3 | E22: 49168230731 | F22: 4817023375
B23: Tiền gửi ký quỹ cho hoạt động đầu tư chứng khoán phái sinh Margin account for trading derivatives | C23: 111.4 | E23: 0 | F23: 0
A24: 1.2 | B24: 1.2. Tiền gửi có kỳ hạn dưới ba (03) tháng Deposits with term less than three (03) months | C24: 112 | E24: 0 | F24: 0
A25: 2 | B25: 2. Các khoản đầu tư thuần Net Investments | C25: 120 | E25: 808973695750 | F25: 864628088050
A26: 2.1 | B26: 2.1. Các khoản đầu tư Investments | C26: 121 | E26: 808973695750 | F26: 864628088050
B27: Cổ phiếu niêm yết Listed Shares | C27: 121.1 | E27: 713837895750 | F27: 739131288050
B28: Cổ phiếu chưa niêm yết Unlisted Shares | C28: 121.2 | E28: 0 | F28: 0
B29: Trái phiếu niêm yết Listed Bonds | C29: 121.3 | E29: 60135800000 | F29: 90496800000
B30: Trái phiếu chưa niêm yết Unlisted Bonds | C30: 121.4 | E30: 0 | F30: 0
B31: Chứng chỉ tiền gửi Certificates of Deposit | C31: 121.5 | E31: 35000000000 | F31: 35000000000
B32: Hợp đồng tiền gửi có kỳ hạn trên ba (03) tháng Deposits with term over three (03) months | C32: 121.6 | E32: 0 | F32: 0
B33: Quyền mua chứng khoán Investment - Rights | C33: 121.7 | E33: 0 | F33: 0
B34: Hợp đồng tương lai chỉ số Index future contracts | C34: 121.8 | E34: 0 | F34: 0
B35: Đầu tư khác Other Investments | C35: 121.9 | E35: 0 | F35: 0
B36: Hợp đồng reverse repo Reverse repo contracts | C36: 121.10 | E36: 0 | F36: 0
A37: 2.2 | B37: 2.2. Dự phòng giảm giá tài sản nhận thế chấp Impairment of devaluation of pledged assets | C37: 122 | E37: 0 | F37: 0
A38: 3 | B38: 3. Các khoản phải thu Receivables | C38: 130 | E38: 3618099315 | F38: 3532149315
A39: 3.1 | B39: 3.1 Phải thu về bán các khoản đầu tư Receivables from investments sold but not yet settled | C39: 131 | E39: 0 | F39: 0
B40: Trong đó: Phải thu khó đòi về bán các khoản đầu tư In which: Overdue receivables from selling investments | C40: 132 | E40: 0 | F40: 0
A41: 3.2 | B41: 3.2. Phải thu và dự thu cổ tức, tiền lãi các khoản đầu tư Dividend and interest receivables | C41: 133 | E41: 4484499315 | F41: 4398549315
A42: 3.2.1 | B42: 3.2.1. Phải thu cổ tức, tiền lãi đến ngày nhận Dividend and interest receivables on or after payment date | C42: 134 | E42: 866400000 | F42: 866400000
B43: Phải thu cổ tức Dividend receivables | C43: 134.1 | E43: 866400000 | F43: 866400000
...

Sheet BCTaiSan_06027
A1: Phụ lục 34. Mẫu báo cáo định kỳ về hoạt động đầu tư của quỹ Appendix 34. Periodical Report on Fund's Investment Activities
A2: (Ban hành kèm theo Thông tư 183/2011/TT-BTC ngày 16 tháng 12 năm 2011 hướng dẫn về việc thành lập và quản lý quỹ mở) (Issued in association with Circular 183/2011/TT-BTC dated 16 December 2011 guiding establishment and management of the Open-Ended Fund)
A3: BÁO CÁO ĐỊNH KỲ VỀ HOẠT ĐỘNG ĐẦU TƯ CỦA QUỸ PERIODICAL REPORT ON FUND'S INVESTMENT ACTIVITIES
A5: ='Tong quat'!C1 -> Tại ngày 31 tháng 10 năm 2019 / As at 31 Oct 2019
A7: Tên Công ty quản lý quỹ: | C7: ='Tong quat'!D5 -> Công ty Cổ phần Quản lý Quỹ Đầu tư Việt Nam
A8: Fund Management Company: | C8: ='Tong quat'!D6 -> Vietnam Investment Fund Management Joint Stock Company
A9: Tên ngân hàng giám sát: | C9: ='Tong quat'!D7 -> Ngân hàng TNHH Một thành viên Standard Chartered (Việt Nam)
A10: Supervising bank: | C10: ='Tong quat'!D8 -> Standard Chartered Bank (Vietnam) Limited
A11: Tên Quỹ: | C11: ='Tong quat'!D9 -> Quỹ Đầu tư Chứng khoán Việt Nam
A12: Fund name: | C12: ='Tong quat'!D10 -> Vietnam Securities Investment Fund(VFMVF1)
A13: Ngày lập báo cáo: | C13: ='Tong quat'!D11 -> Ngày 04 tháng 11 năm 2019
A14: Reporting Date: | C14: ='Tong quat'!D12 -> 04 Nov 2019
A17: I | B17: BÁO CÁO TÀI SẢN CỦA QUỸ / ASSET REPORT
A18: STT No | B18: Nội dung Indicator | C18: Mã chỉ tiêu Code | D18: Ngày 31 tháng 10 năm 2019 As at 31 Oct 2019 | E18: Ngày 30 tháng 09 năm 2019 As at 30 Sep 2019 | F18: %/cùng kỳ năm trước %/against last year
A19: I | B19: TÀI SẢN ASSETS | C19: 2200
A20: I.1 | B20: Tiền và các khoản tương đương tiền Cash and Cash Equivalents | C20: 2201 | D20: 49227230731 | E20: 4858023375 | F20: 0.7580963
B21: Tiền Cash | C21: 2202 | D21: 0 | E21: 0
B22: Tiền gửi ngân hàng Cash at bank | C22: 2203 | D22: 49227230731 | E22: 4858023375 | F22: 0.7580963
B23: Tiền gửi của nhà đầu tư cho hoạt động mua chứng chỉ quỹ Cash at bank for Fund's subscription | C23: 2203.1 | D23: 59000000 | E23: 41000000 | F23: 7.375
B24: Tiền phải trả cho Nhà đầu tư về mua lại chứng chỉ quỹ Cash at bank for Fund's redemption | C24: 2203.2 | D24: 0 | E24: 0 | F24: 0
B25: Tiền gửi ngân hàng cho hoạt động của Quỹ Cash at bank for Fund's operation | C25: 2203.3 | D25: 49168230731 | E25: 4817023375 | F25: 0.80521008
B26: Tiền gửi ký quỹ cho hoạt động đầu tư chứng khoán phái sinh Margin account for trading derivatives | C26: 2203.4 | D26: 0 | E26: 0
B27: Các khoản tương đương tiền Cash Equivalents | C27: 2204 | D27: 0 | E27: 0
A28: I.2 | B28: Các khoản đầu tư (kê chi tiết) Investments | C28: 2205 | D28: 808973695750 | E28: 864628088050 | F28: 0.75480467
B29: Cổ phiếu niêm yết Listed shares | C29: 2205.1 | D29: 713837895750 | E29: 739131288050 | F29: 0.7830447
B30: Cổ phiếu chưa niêm yết Unlisted shares | C30: 2205.2 | D30: 0 | E30: 0
B31: Trái phiếu Bonds | C31: 2205.3 | D31: 60135800000 | E31: 90496800000 | F31: 1.9947325
B32: Chứng chỉ tiền gửi Certificates of Deposit | C32: 2205.4 | D32: 35000000000 | E32: 35000000000 | F32: 0.26923077
B33: Hợp đồng tiền gửi có kỳ hạn trên ba (03) tháng Deposits with term over three (03) months | C33: 2205.5 | D33: 0 | E33: 0
B34: Quyền mua chứng khoán Investment - Rights | C34: 2205.6 | D34: 0 | E34: 0
B35: Hợp đồng tương lai chỉ số Index future contracts | C35: 2205.7 | D35: 0 | E35: 0
B36: Đầu tư khác Other investments | C36: 2205.8 | D36: 0 | E36: 0
B37: Hợp đồng reverse repo Reverse repo contracts | C37: 2205.9 | D37: 0 | E37: 0
A38: I.3 | B38: Phải thu cổ tức, trái tức Dividend, Coupon receivables | C38: 2206 | D38: 4262444521 | E38: 3978343836 | F38: 2.0552797
B39: Phải thu cổ tức Dividend receivables | C39: 2206.1 | D39: 1420150000 | E39: 866700000 | F39: 1.0206626
B40: Phải thu trái tức Coupon receivables | C40: 2206.2 | D40: 2842294521 | E40: 3111643836 | F40: 4.1645341
A41: I.4 | B41: Lãi được nhận Interest receivables | C41: 2207 | D41: 222054794 | E41: 420205479 | F41: 0.074580606
B42: Phải thu lãi tiền gửi Interest receivable from bank deposits | C42: 2207.1 | D42: 0 | E42: 0
B43: Phải thu lãi chứng chỉ tiền gửi Interest receivable from Certificates of Deposit | C43: 2207.2 | D43: 222054794 | E43: 420205479 | F43: 0.074580606
B44: Phải thu lãi hợp đồng reverse repo Interest receivable from reverse repo contracts | C44: 2207.3 | D44: 0 | E44: 0
...

Sheet BCKetQuaHoatDong_06028
A1: Phụ lục 34. Mẫu báo cáo định kỳ về hoạt động đầu tư của quỹ Appendix 34. Periodical Report on Fund's Investment Activities
A2: (Ban hành kèm theo Thông tư 183/2011/TT-BTC ngày 16 tháng 12 năm 2011 hướng dẫn về việc thành lập và quản lý quỹ mở) (Issued in association with Circular 183/2011/TT-BTC dated 16 December 2011 guiding establishment and management of the Open-Ended Fund)
A3: BÁO CÁO ĐỊNH KỲ VỀ HOẠT ĐỘNG ĐẦU TƯ CỦA QUỸ PERIODICAL REPORT ON FUND'S INVESTMENT ACTIVITIES
A5: ='Tong quat'!C2 -> Tháng 10 năm 2019 / Oct 2019
A7: Tên Công ty quản lý quỹ: | C7: ='Tong quat'!D5 -> Công ty Cổ phần Quản lý Quỹ Đầu tư Việt Nam
A8: Fund Management Company: | C8: ='Tong quat'!D6 -> Vietnam Investment Fund Management Joint Stock Company
A9: Tên ngân hàng giám sát: | C9: ='Tong quat'!D7 -> Ngân hàng TNHH Một thành viên Standard Chartered (Việt Nam)
A10: Supervising bank: | C10: ='Tong quat'!D8 -> Standard Chartered Bank (Vietnam) Limited
A11: Tên Quỹ: | C11: ='Tong quat'!D9 -> Quỹ Đầu tư Chứng khoán Việt Nam
A12: Fund name: | C12: ='Tong quat'!D10 -> Vietnam Securities Investment Fund(VFMVF1)
A13: Ngày lập báo cáo: | C13: ='Tong quat'!D11 -> Ngày 04 tháng 11 năm 2019
A14: Reporting Date: | C14: ='Tong quat'!D12 -> 04 Nov 2019
A17: II | B17: BÁO CÁO KẾT QUẢ HOẠT ĐỘNG / PROFIT AND LOSS REPORT
A18: STT No | B18: Nội dung Indicator | C18: Mã chỉ tiêu Code | D18: Tháng 10 năm 2019 Oct 2019 | E18: Tháng 09 năm 2019 Sep 2019 | F18: Lũy kế từ đầu năm Accumulated from beginning of year
A19: I | B19: Thu nhập từ hoạt động đầu tư Income from Investment Activities | C19: 2220 | D19: 1623651780 | E19: 1713413162 | F19: 26607704858
A20: 1 | B20: Cổ tức, trái tức được nhận Dividend income, interest income from bonds | C20: 2221 | D20: 1340508083 | E20: 1447416001 | F20: 19715295589
B21: Cổ tức được nhận Dividends income | C21: 2221.1 | D21: 643830000 | E21: 677216000 | F21: 12039311000
B22: Trái tức được nhận Interest income from bonds | C22: 2221.2 | D22: 696678083 | E22: 770200001 | F22: 7675984589
A23: 2 | B23: Lãi được nhận Interest income | C23: 2222 | D23: 283143697 | E23: 265997161 | F23: 6892409269
B24: Lãi tiền gửi ngân hàng Interest income from bank deposits | C24: 2222.1 | D24: 4993012 | E24: 3024274 | F24: 262591347
B25: Lãi chứng chỉ tiền gửi Interest income from Certificates of Deposit | C25: 2222.2 | D25: 278150685 | E25: 262972887 | F25: 6629817922
B26: Lãi hợp đồng mua reverse repo Interest income from reverse repo contracts | C26: 2222.3 | D26: 0 | E26: 0 | F26: 0
A27: 3 | B27: Các khoản thu nhập khác Other income | C27: 2223 | D27: 0 | E27: 0 | F27: 0
B28: Thu nhập khác về đầu tư Other investment income | C28: 2223.1 | D28: 0 | E28: 0 | F28: 0
B29: Thu nhập khác Other income | C29: 2223.2 | D29: 0 | E29: 0 | F29: 0
B30: Chi phí dự phòng nợ phải thu khó đòi về cổ tức, tiền lãi và xử lý tổn thất nợ phải thu khó đòi về cổ tức, tiền lãi Provision expense for bad debts from dividends, interest income and written off bad debts from dividends, interest income | C30: 2223.3 | D30: 0 | E30: 0 | F30: 0
A31: II | B31: Chi phí Expenses | C31: 2224 | D31: 1620324287 | E31: 1581657071 | F31: 19121818663
A32: 1 | B32: Phí quản lý trả cho Công ty quản lý quỹ Management Fee paid to Fund Management Company | C32: 2225 | D32: 1424409624 | E32: 1398127063 | F32: 16116239884
A33: 2 | B33: Phí lưu ký, giám sát trả cho Ngân hàng Giám sát/VSD Custody fee, Supervising fee paid to Supervising Bank/VSD | C33: 2226 | D33: 78454753 | E33: 76875896 | F33: 858500405
B34: Phí dịch vụ lưu ký - bảo quản tài sản Custodian service - Safe Custody Fee | C34: 2226.1 | D34: 36523323 | E34: 35849411 | F34: 366340048
B35: Phí dịch vụ lưu ký - giao dịch chứng khoán Custodian service - Transaction fee | C35: 2226.2 | D35: 4515000 | E35: 2900000 | F35: 63015000
B36: Phí dịch vụ lưu ký cho chứng khoán cơ sở, phí quản lý vị thế và tài sản phái sinh trả cho VSD Custodian service - Depository fee, Position and Margin management fee paid to VSD | C36: 2226.3 | D36: 5275906 | E36: 6579004 | F36: 65496873
B37: Phí giám sát Supervisory fee | C37: 2226.4 | D37: 32140524 | E37: 31547481 | F37: 363648484
A38: 3 | B38: Chi phí dịch vụ quản trị quỹ, chi phí dịch vụ đại lý chuyển nhượng và các chi phí khác mà công ty quản lý quỹ trả cho tổ chức cung cấp dịch vụ có liên quan Fund Administration Fee, Transfer Agency Fee and other fees paid to relevant Fund's service providers | C38: 2227 | D38: 31087827 | E38: 30717177 | F38: 337280301
B39: Chi phí quản trị Quỹ Fund Administration Fee | C39: 2227.1 | D39: 20087827 | E39: 19717177 | F39: 227280301
B40: Chi phí dịch vụ Đại lý Chuyển nhượng Transfer Agency Fee | C40: 2227.2 | D40: 11000000 | E40: 11000000 | F40: 110000000
A41: 4 | B41: Chi phí kiểm toán trả cho tổ chức kiểm toán Audit fee | C41: 2228 | D41: 15415064 | E41: 14917805 | F41: 154805349
A42: 5 | B42: Chi phí dịch vụ tư vấn pháp lý, dịch vụ báo giá và các dịch vụ hợp lý khác, thù lao trả cho ban đại diện quỹ Legal consultancy expenses, price feed fee, other valid expenses, remuneration paid to Fund's Board of Representatives | C42: 2229 | D42: 18443829 | E42: 18397255 | F42: 196223846
B43: Thù lao Ban đại diện Quỹ Remuneration of Fund's Board of Representatives | C43: 2229.1 | D43: 18443829 | E43: 18397255 | F43: 184158846
B44: Chi phí cung cấp báo giá chứng khoán Price feed fee | C44: 2229.2 | D44: 0 | E44: 0 | F44: 12065000
...

Sheet BCDanhMucDauTu_06029
A1: Phụ lục 34. Mẫu báo cáo định kỳ về hoạt động đầu tư của quỹ Appendix 34. Periodical Report on Fund's Investment Activities
A2: (Ban hành kèm theo Thông tư 183/2011/TT-BTC ngày 16 tháng 12 năm 2011 hướng dẫn về việc thành lập và quản lý quỹ mở) (Issued in association with Circular 183/2011/TT-BTC dated 16 December 2011 guiding establishment and management of the Open-Ended Fund)
A3: BÁO CÁO ĐỊNH KỲ VỀ HOẠT ĐỘNG ĐẦU TƯ CỦA QUỸ PERIODICAL REPORT ON FUND'S INVESTMENT ACTIVITIES
A5: ='Tong quat'!C1 -> Tại ngày 31 tháng 10 năm 2019 / As at 31 Oct 2019
A7: Tên Công ty quản lý quỹ: | C7: ='Tong quat'!D5 -> Công ty Cổ phần Quản lý Quỹ Đầu tư Việt Nam
A8: Fund Management Company: | C8: ='Tong quat'!D6 -> Vietnam Investment Fund Management Joint Stock Company
A9: Tên ngân hàng giám sát: | C9: ='Tong quat'!D7 -> Ngân hàng TNHH Một thành viên Standard Chartered (Việt Nam)
A10: Supervising bank: | C10: ='Tong quat'!D8 -> Standard Chartered Bank (Vietnam) Limited
A11: Tên Quỹ: | C11: ='Tong quat'!D9 -> Quỹ Đầu tư Chứng khoán Việt Nam
A12: Fund name: | C12: ='Tong quat'!D10 -> Vietnam Securities Investment Fund(VFMVF1)
A13: Ngày lập báo cáo: | C13: ='Tong quat'!D11 -> Ngày 04 tháng 11 năm 2019
A14: Reporting Date: | C14: ='Tong quat'!D12 -> 04 Nov 2019
A17: III | B17: BÁO CÁO VỀ TÌNH HÌNH DANH MỤC ĐẦU TƯ CỦA QUỸ / INVESTMENT PORTFOLIO REPORT
A18: STT No. | B18: Loại Category | C18: Mã chỉ tiêu Code | D18: Số Lượng Quantity | E18: Giá thị trường hoặc giá trị hợp lý tại ngày báo cáo Market price | F18: Tổng giá trị (Đồng) Value (VND) | G18: Tỷ lệ % Tổng giá trị tài sản của Quỹ % of total asset
A19: I | B19: CỔ PHIẾU NIÊM YẾT LISTED SHARES | C19: 2246
A20: 1 | B20: ACB | C20: 2246.1 | D20: 764357 | E20: 24100 | F20: 18421003700 | G20: 0.021374561
A21: 2 | B21: ACV | C21: 2246.2 | D21: 136800 | E21: 80000 | F21: 10944000000 | G21: 0.012698722
A22: 3 | B22: BID | C22: 2246.3 | D22: 985890 | E22: 40600 | F22: 40027134000 | G22: 0.046444941
A23: 4 | B23: BVH | C23: 2246.4 | D23: 114600 | E23: 72100 | F23: 8262660000 | G23: 0.0095874653
A24: 5 | B24: CTD | C24: 2246.5 | D24: 100 | E24: 79000 | F24: 7900000 | G24: 9.1666577e-06
A25: 6 | B25: CTG | C25: 2246.6 | D25: 494900 | E25: 22000 | F25: 10887800000 | G25: 0.012633511
A26: 7 | B26: DPM | C26: 2246.7 | D26: 100 | E26: 13650 | F26: 1365000 | G26: 1.5838592e-06
A27: 8 | B27: DXG | C27: 2246.8 | D27: 547153 | E27: 15450 | F27: 8453513850 | G27: 0.00980892
A28: 9 | B28: EIB | C28: 2246.9 | D28: 100 | E28: 16500 | F28: 1650000 | G28: 1.9145551e-06
A29: 10 | B29: FPT | C29: 2246.10 | D29: 1084142 | E29: 57900 | F29: 62771821800 | G29: 0.072836431
A30: 11 | B30: GAS | C30: 2246.11 | D30: 256150 | E30: 103500 | F30: 26511525000 | G30: 0.030762288
A31: 12 | B31: GMD | C31: 2246.12 | D31: 100 | E31: 26700 | F31: 2670000 | G31: 3.0980982e-06
... A63: 44 | B63: VRE | C63: 2246.44 | D63: 285970 | E63: 33200 | F63: 9494204000 | G63: 0.011016471
B64: TỔNG TOTAL | C64: 2247 | D64: 15715365 | F64: 713837895750 | G64: 0.82829211
A65: II | B65: CỔ PHIẾU CHƯA NIÊM YẾT UNLISTED SHARES | C65: 2248
B66: TỔNG TOTAL | C66: 2249 | D66: 0 | F66: 0 | G66: 0
B67: TỔNG CÁC LOẠI CỔ PHIẾU TOTAL | C67: 2250 | D67: 15715365 | F67: 713837895750 | G67: 0.82829211
A68: III | B68: TRÁI PHIẾU BONDS | C68: 2251
A69: 1 | B69: Trái phiếu niêm yết Listed bonds | C69: 2251.1 | D69: 600000 | F69: 60135800000 | G69: 0.069777759
A70: 1.1 | B70: KBC11806 | C70: 2251.1.1 | D70: 500000 | E70: 100000 | F70: 50000000000 | G70: 0.058016821
A71: 1.2 | B71: VIC11814 | C71: 2251.1.2 | D71: 100000 | E71: 101358 | F71: 10135800000 | G71: 0.011760938
A72: 2 | B72: Trái phiếu chưa niêm yết Unlisted Bonds | C72: 2251.2 | D72: 0 | F72: 0 | G72: 0
B73: TỔNG TOTAL | C73: 2252 | D73: 600000 | F73: 60135800000 | G73: 0.069777759
A74: IV | B74: CÁC LOẠI CHỨNG KHOÁN KHÁC OTHER SECURITIES | C74: 2253
A75: 1 | B75: Quyền mua chứng khoán Investment - Rights | C75: 2253.1 | D75: 0 | F75: 0 | G75: 0
...

Sheet Khac_06030
A1: Phụ lục 34. Mẫu báo cáo định kỳ về hoạt động đầu tư của quỹ Appendix 34. Periodical Report on Fund's Investment Activities
A2: (Ban hành kèm theo Thông tư 183/2011/TT-BTC ngày 16 tháng 12 năm 2011 hướng dẫn về việc thành lập và quản lý quỹ mở) (Issued in association with Circular 183/2011/TT-BTC dated 16 December 2011 guiding establishment and management of the Open-Ended Fund)
A3: BÁO CÁO ĐỊNH KỲ VỀ HOẠT ĐỘNG ĐẦU TƯ CỦA QUỸ PERIODICAL REPORT ON FUND'S INVESTMENT ACTIVITIES
A5: ='Tong quat'!C2 -> Tháng 10 năm 2019 / Oct 2019
A7: Tên Công ty quản lý quỹ: | C7: ='Tong quat'!D5 -> Công ty Cổ phần Quản lý Quỹ Đầu tư Việt Nam
A8: Fund Management Company: | C8: ='Tong quat'!D6 -> Vietnam Investment Fund Management Joint Stock Company
A9: Tên ngân hàng giám sát: | C9: ='Tong quat'!D7 -> Ngân hàng TNHH Một thành viên Standard Chartered (Việt Nam)
A10: Supervising bank: | C10: ='Tong quat'!D8 -> Standard Chartered Bank (Vietnam) Limited
A11: Tên Quỹ: | C11: ='Tong quat'!D9 -> Quỹ Đầu tư Chứng khoán Việt Nam
A12: Fund name: | C12: ='Tong quat'!D10 -> Vietnam Securities Investment Fund(VFMVF1)
A13: Ngày lập báo cáo: | C13: ='Tong quat'!D11 -> Ngày 04 tháng 11 năm 2019
A14: Reporting Date: | C14: ='Tong quat'!D12 -> 04 Nov 2019
A17: IV | B17: MỘT SỐ CHỈ TIÊU KHÁC / OTHER INDICATORS
A18: STT No | B18: Chỉ tiêu Indicators | C18: Mã chỉ tiêu Code | D18: =BCKetQuaHoatDong_06028!D18 -> Tháng 10 năm 2019 Oct 2019 | E18: =BCKetQuaHoatDong_06028!E18 -> Tháng 09 năm 2019 Sep 2019
A19: I | B19: CÁC CHỈ TIÊU VỀ HIỆU QUẢ HOẠT ĐỘNG INVESTMENT PERFORMANCE INDICATORS | C19: 2264
A20: 1 | B20: Tỷ lệ phí quản lý trả cho công ty quản lý quỹ/Giá trị tài sản ròng trung bình trong kỳ (%) Management fee paid to the fund management company/Average NAV (%) | C20: 2265 | D20: 0.019875975 | E20: 0.019234916
A21: 2 | B21: Tỷ lệ phí lưu ký, giám sát trả cho Ngân hàng Giám sát/Giá trị tài sản ròng trung bình trong kỳ (%) Custody and supervising fees paid to the Supervisory Bank/Average NAV (%) | C21: 2266 | D21: 0.0010211254 | E21: 0.00096711869
A22: 3 | B22: Tỷ lệ chi phí dịch vụ quản trị quỹ, chi phí dịch vụ đại lý chuyển nhượng và các chi phí khác mà công ty quản lý quỹ trả cho tổ chức cung cấp dịch vụ có liên quan/Giá trị tài sản ròng của quỹ trung bình trong kỳ (%) Fund admin fee, transfer agency fee and other fees paid to relating services providers by the fund management company/Average NAV (%) | C22: 22661 | D22: 0.00050741347 | E22: 0.00051310709
A23: 4 | B23: Chi phí kiểm toán trả cho tổ chức kiểm toán (nếu phát sinh)/Giá trị tài sản ròng trung bình trong kỳ (%) Auditing fee paid to auditing organizations (if any)/Average NAV (%) | C23: 2267 | D23: 0.00021509924 | E23: 0.00020523365
A24: 5 | B24: Chi phí dịch vụ tư vấn pháp lý, dịch vụ báo giá và các dịch vụ hợp lý khác, thù lao trả cho ban đại diện quỹ/Giá trị tài sản ròng trung bình trong kỳ (%) Legal consultancy, price quotation and other appropriate service fees; remunerations paid to the Board of Representatives/Average NAV (%) | C24: 2268 | D24: 0.00025736212 | E24: 0.00025310264
A25: 6 | B25: Tỷ lệ chi phí hoạt động/Giá trị tài sản ròng trung bình trong kỳ (%) Operating expense/Average NAV (%) | C25: 2269 | D25: 0.022609735 | E25: 0.021190653
A26: 7 | B26: Tốc độ vòng quay danh mục trong kỳ (%) = (Tổng giá trị danh mục mua vào + tổng giá trị danh mục bán ra)/2/Giá trị tài sản ròng trung bình trong kỳ Portfolio turnover rate (%) = (Total value of purchase transactions + total value of sales transactions)/2/Average NAV (**) | C26: 2270 | D26: 0.034794841 | E26: 0.053838463
A27: II | B27: CÁC CHỈ TIÊU KHÁC OTHER INDICATORS | C27: 2272
A28: 1 | B28: Quy mô quỹ đầu kỳ (tính theo mệnh giá chứng chỉ quỹ) Fund scale at the beginning of the period (based on par value of fund certificate) | C28: 2273 | D28: 210018339800 | E28: 217450991500
B29: Tổng giá trị chứng chỉ quỹ đang lưu hành đầu kỳ Total value of outstanding Fund Certificate at the beginning of period | C29: 2274 | D29: 210018339800 | E29: 217450991500
B30: Tổng số lượng đơn vị quỹ đang lưu hành đầu kỳ Total number of outstanding Fund Certificate at the beginning of period | C30: 2275 | D30: 21001834 | E30: 21745099
A31: 2 | B31: Thay đổi quy mô quỹ trong kỳ (tính theo mệnh giá chứng chỉ quỹ) Change of Fund scale during the period (based on par value of fund certificate) | C31: 2276 | D31: -4308706200 | E31: -7432651700
B32: Thay đổi số lượng chứng chỉ quỹ trong kỳ Change of Number of Fund Certificates during the period | C32: 2276.1 | D32: -430870.62 | E32: -743265.17
B33: Thay đổi giá trị vốn trong kỳ (theo mệnh giá) Change in capital amount during the period (based on par value) | C33: 2276.2 | D33: -4308706200 | E33: -7432651700
B34: Số lượng đơn vị quỹ phát hành thêm trong kỳ Number of Fund Certificates subscribed during the period | C34: 2277 | D34: 51294.48 | E34: 34291.67
B35: Giá trị vốn huy động thêm trong kỳ (theo mệnh giá) Net subscription amount during the period (based on par value) | C35: 2278 | D35: 512944800 | E35: 342916700
B36: Số lượng đơn vị quỹ mua lại trong kỳ Number of Fund Certificates redeemed during the period | C36: 22781 | D36: -482165.1 | E36: -777556.84
B37: Giá trị vốn phải thanh toán trong kỳ khi đáp ứng lệnh của nhà đầu tư (theo mệnh giá) Net redemption amount during the period (based on par value) | C37: 22782 | D37: -4821651000 | E37: -7775568400
A38: 3 | B38: Quy mô quỹ cuối kỳ (tính theo mệnh giá chứng chỉ quỹ) Fund scale at the end of the period (based on par value) | C38: 2279 | D38: 205709633600 | E38: 210018339800
B39: Tổng giá trị chứng chỉ quỹ đang lưu hành cuối kỳ Total value of outstanding Fund Certificate at the end of the period | C39: 2280 | D39: 205709633600 | E39: 210018339800
B40: Tổng số lượng đơn vị quỹ đang lưu hành cuối kỳ Total number of outstanding Fund Certificate at the end of the period | C40: 2281 | D40: 20570963 | E40: 21001834
A41: 4 | B41: Tỷ lệ nắm giữ chứng chỉ quỹ của công ty quản lý quỹ và người có liên quan cuối kỳ Fund Management Company and related parties' ownership ratio at the end of the period | C41: 2282 | D41: 0.056885501 | E41: 0.055696662
A42: 5 | B42: Tỷ lệ nắm giữ chứng chỉ quỹ của 10 nhà đầu tư lớn nhất cuối kỳ Top 10 investors' ownership ratio at the end of the period | C42: 2283 | D42: 0.696 | E42: 0.6825
A43: 6 | B43: Tỷ lệ nắm giữ chứng chỉ quỹ của nhà đầu tư nước ngoài cuối kỳ Foreign investors' ownership ratio at the end of the period | C43: 2284 | D43: 0.5881 | E43: 0.576
A44: 7 | B44: Số nhà đầu tư tham gia vào quỹ, kể cả giao dịch ký danh Number of investors of the Fund at the end of the period | C44: 22841 | D44: 3170 | E44: 3184
...

Sheet GiaTriTaiSanRong_06129
A1: Phụ lục 26. Mẫu báo cáo thay đổi giá trị tài sản ròng, giao dịch chứng chỉ quỹ Appendix 26. Report on change of Net Asset Value, trading of Fund Certificate
A2: (Ban hành kèm theo Thông tư 183/2011/TT-BTC ngày 16 tháng 12 năm 2011 hướng dẫn về việc thành lập và quản lý quỹ mở) (Issued in association with Circular 183/2011/TT-BTC dated 16 December 2011 guiding establishment and management of the Open-Ended Fund)
A3: BÁO CÁO THAY ĐỔI GIÁ TRỊ TÀI SẢN RÒNG, GIAO DỊCH CHỨNG CHỈ QUỸ REPORT ON CHANGE OF NET ASSET VALUE, TRADING OF FUND CERTIFICATE
A5: ='Tong quat'!C2 -> Tháng 10 năm 2019 / Oct 2019
A7: Tên Công ty quản lý quỹ: | D7: ='Tong quat'!D5 -> Công ty Cổ phần Quản lý Quỹ Đầu tư Việt Nam
A8: Fund Management Company: | D8: ='Tong quat'!D6 -> Vietnam Investment Fund Management Joint Stock Company
A9: Tên ngân hàng giám sát: | D9: ='Tong quat'!D7 -> Ngân hàng TNHH Một thành viên Standard Chartered (Việt Nam)
A10: Supervising bank: | D10: ='Tong quat'!D8 -> Standard Chartered Bank (Vietnam) Limited
A11: Tên Quỹ: | D11: ='Tong quat'!D9 -> Quỹ Đầu tư Chứng khoán Việt Nam
A12: Fund name: | D12: ='Tong quat'!D10 -> Vietnam Securities Investment Fund(VFMVF1)
A13: Ngày lập báo cáo: | D13: ='Tong quat'!D11 -> Ngày 04 tháng 11 năm 2019
A14: Reporting Date: | D14: ='Tong quat'!D12 -> 04 Nov 2019
A18: STT No | C18: Nội dung Item | D18: Mã số Code | E18: =BCKetQuaHoatDong_06028!D18 -> Tháng 10 năm 2019 Oct 2019 | F18: =BCKetQuaHoatDong_06028!E18 -> Tháng 09 năm 2019 Sep 2019
A19: I | C19: I. Giá trị tài sản ròng của Quỹ mở (NAV) đầu kỳ Net Asset Value (NAV) at the beginning of period | D19: 4060 | E19: 870482187950 | F19: 882204395196
A20: II | C20: II. Thay đổi NAV so với kỳ trước (= II.1 + II.2), trong đó: Change of NAV during the period (= II.1 + II.2), of which: | D20: 4061 | E20: 4194581295 | F20: 18755924050
B21: II.1 | C21: II.1 Thay đổi NAV do biến động thị trường và hoạt động giao dịch của Quỹ mở trong kỳ Changes of NAV due to market fluctuation and the fund's investment during the period | D21: 4062 | E21: 4194581295 | F21: 18755924050
B22: II.2 | C22: II.2 Thay đổi NAV do phân chia Lợi nhuận/Tài sản của Quỹ mở cho Nhà đầu tư trong kỳ Change of NAV due to profit/asset distribution to investors during the period | D22: 4063 | E22: 0 | F22: 0
A23: III | C23: III. Thay đổi NAV do mua lại, phát hành thêm Chứng chỉ quỹ (= III.1 + III.2) Change of NAV due to redemption, subscription of Fund Certificate (= III.1 + III.2) | D23: 4064 | E23: -17853610523 | F23: -30478131296
B24: III.1 | C24: III.1 Khoản thu từ việc phát hành bổ sung Chứng chỉ quỹ Increase from Subscription of Fund Certificate | D24: 4065 | E24: 2119427539 | F24: 1397279179
B25: III.2 | C25: III.2 Khoản thanh toán từ việc mua lại Chứng chỉ quỹ Decrease from Redemption of Fund Certificate | D25: 4066 | E25: -19973038062 | F25: -31875410475
A26: IV | C26: IV. Giá trị tài sản ròng của Quỹ mở cuối kỳ (= I + II + III) NAV at the end of period (= I + II + III) | D26: 4067 | E26: 856823158722 | F26: 870482187950
A27: V | C27: V. Giá trị tài sản ròng trên một đơn vị quỹ cuối kỳ NAV per unit at the end of period | D27: 4067.1 | E27: 41652.06 | F27: 41447.91
A30: ='Tong quat'!C16 -> Đại diện có thẩm quyền của Ngân hàng giám sát | E30: ='Tong quat'!F16 -> Đại diện có thẩm quyền của Công ty quản lý Quỹ
A31: ='Tong quat'!C17 -> Authorised Representative of Supervisory Bank | E31: ='Tong quat'!F17 -> Authorised Representative of Fund Management Company
A41: ='Tong quat'!C19 -> Ngân hàng TNHH MTV Standard Chartered (Việt Nam) | E41: ='Tong quat'!F19 -> Công ty Cổ phần Quản lý Quỹ Đầu tư Việt Nam
A42: ='Tong quat'!C20 -> Vũ Hương Giang | E42: ='Tong quat'!F20 -> Trần Thanh Tân
A43: ='Tong quat'!C21 -> Phó phòng Nghiệp vụ Dịch vụ Chứng khoán | E43: ='Tong quat'!F21 -> Tổng Giám đốc

Sheet BCHoatDongVay_06026
A1: Phụ lục 31: Mẫu Báo cáo hoạt động vay, giao dịch mua bán lại của quỹ Appendix 31: Report on borrowing operation, repo/reverse repo transactions of the fund
A2: (Ban hành kèm theo Thông tư 183/2011/TT-BTC ngày 16 tháng 12 năm 2011 hướng dẫn về việc thành lập và quản lý quỹ mở) (Issued in association with Circular 183/2011/TT-BTC dated 16 December 2011 guiding establishment and management of the Open-Ended Fund)
A3: BÁO CÁO HOẠT ĐỘNG VAY, GIAO DỊCH MUA BÁN LẠI CỦA QUỸ REPORT ON BORROWING OPERATION, REPO/REVERSE REPO TRANSACTIONS OF THE FUND
A5: Tháng 10 năm 2019/Oct 2019
A7: Tên Công ty quản lý quỹ: | G7: Công ty Cổ phần Quản lý Quỹ Đầu tư Việt Nam
A8: Fund Management Company: | G8: Vietnam Investment Fund Management Joint Stock Company
A9: Tên ngân hàng giám sát: | G9: Ngân hàng TNHH một thành viên Standard Chartered (Việt Nam)
A10: Supervising bank: | G10: Standard Chartered Bank (Vietnam) Ltd.
A11: Tên Quỹ: | G11: Quỹ đầu tư Chứng khoán Việt Nam
A12: Fund name: | G12: Vietnam Securities Investment Fund (VFMVF1)
A13: Ngày lập báo cáo: | G13: Ngày 04 tháng 11 năm 2019
A14: Reporting Date: | G14: 43773
A16: STT No. | B16: Nội dung hoạt động (nêu chi tiết theo mục tiêu và đối tác) Description | C16: Mã chỉ tiêu Code | D16: Đối tác Counterparty | E16: Mục tiêu/Tài sản đảm bảo Collateral | F16: Kỳ hạn Term | G16: Giá trị khoản vay hoặc khoản cho vay Amount | H16: Thời điểm giao dịch As at transaction date | J16: Thời điểm báo cáo As at reporting date
H17: Ngày tháng năm Date | I17: Tỷ lệ giá trị hợp đồng/giá trị tài sản ròng của quỹ Balance/NAV | J17: Ngày tháng năm Date | K17: Tỷ lệ giá trị hợp đồng/giá trị tài sản ròng của quỹ Balance/NAV
A18: 1.1 | B18: Vay tiền (nêu chi tiết từng hợp đồng) Borrowings (detail by each contract) | C18: 2287
A19: I | B19: Tỷ lệ tiền vay từ các hợp đồng/giá trị tài sản ròng Borrowings/NAV | C19: 2288
A20: 1.2 | B20: Hợp đồng Repo (nêu chi tiết từng hợp đồng) Repo (detail by each contract) | C20: 2289
A21: II | B21: Tổng giá trị các hợp đồng Repo/giá trị tài sản ròng Repo/NAV | C21: 2290
A22: A | B22: Tổng giá trị các khoản vay/giá trị tài sản ròng (=I+II) Total Borrowings, Repo/NAV | C22: 2291
A23: 2.1 | B23: Cho vay chứng khoán (nêu chi tiết từng hợp đồng) Margin (detail by each contract) | C23: 2292
A24: I | B24: Tổng giá trị các hợp đồng/giá trị tài sản ròng của quỹ Total Margin/NAV | C24: 2293
A25: 2.2 | B25: Hợp đồng Reverse Repo (nêu chi tiết từng hợp đồng) Reverse Repo (Detail by each contract) | C25: 2295
A26: II | B26: Tổng giá trị các hợp đồng/giá trị tài sản ròng của quỹ Reverse Repo/NAV | C26: 2296
A27: B | B27: Tổng giá trị các khoản cho vay/giá trị tài sản ròng (=III + IV) Total Loans/NAV | C27: 2297
A32: Đại diện có thẩm quyền của Ngân hàng giám sát | I32: Đại diện có thẩm quyền của Công ty quản lý Quỹ
A33: Authorised Representative of Supervisory Bank | I33: Authorised Representative of Fund Management Company
A43: Ngân hàng TNHH MTV Standard Chartered (Việt Nam) | I43: Công ty Cổ phần Quản lý Quỹ đầu tư Việt Nam
A44: Vũ Hương Giang | I44: Trần Thanh Tân
A45: Phó Phòng Nghiệp vụ Dịch vụ Chứng khoán | I45: Tổng Giám đốc

Sheet LogoFMS
D1: VFMVF1
A2: FUNDCODE | B2: FUNDNAME | C2: LOGO
A3: VFMVEI | B3: Quỹ Đầu tư Cổ phiếu Việt Nam
A4: VFMVF1 | B4: Quỹ Đầu tư Chứng khoán Việt Nam
A5: VFMVF4 | B5: Quỹ Đầu tư Doanh nghiệp hàng đầu Việt Nam
A6: VFMVFA | B6: Quỹ Đầu tư Năng Động Việt Nam
A7: VFMVFB | B7: Quỹ Đầu tư Trái phiếu Việt Nam
A8: VFMVFC | B8: Quỹ đầu tư Định Hướng Bảo Toàn Vốn Việt Nam
A9: TCEF1 | B9: Quỹ Đầu tư Cổ phiếu Techcom
A10: TCBF | B10: Quỹ Đầu tư Cổ phiếu Techcom
A11: MBEF1 | B11: Quỹ Đầu tư JAPAN ASIA MB CAPITAL
A12: MBVF | B12: Quỹ Đầu tư Giá trị MB Capital
A13: SSISCA | B13: Quỹ Đầu tư Lợi thế Cạnh tranh Bền vững SSI
A14: VCBBCF | B14: Quỹ Đầu tư Cổ Phiếu Hàng Đầu VCBF
... A39: MAGEF | B39: Quỹ đầu tư cổ phiếu tăng trưởng Mira asset Việt Nam
